<?xml version="1.0" encoding="UTF-8"?>
<!-- Generated by org.testng.reporters.JUnitXMLReporter -->
<testsuite hostname="EPUAKYIW0675" name="tesNgTask" tests="86" failures="29" timestamp="2 Nov 2016 10:18:25 GMT" time="28.672" errors="0">
  <testcase name="testCos" time="0.0" classname="businessObject.CalculatorTest">
    <failure type="java.lang.AssertionError" message="expected [0.9480811024049992] but found [0.3180286516377352]">
      <![CDATA[java.lang.AssertionError: expected [0.9480811024049992] but found [0.3180286516377352]
	at businessObject.CalculatorTest.testCos(CalculatorTest.java:82)
	at com.intellij.rt.execution.application.AppMain.main(AppMain.java:147)
... Removed 31 stack frames]]>
    </failure>
  </testcase> <!-- testCos -->
  <testcase name="testCos" time="0.0" classname="businessObject.CalculatorTest">
    <failure type="java.lang.AssertionError" message="expected [1.0] but found [0.0]">
      <![CDATA[java.lang.AssertionError: expected [1.0] but found [0.0]
	at businessObject.CalculatorTest.testCos(CalculatorTest.java:82)
	at com.intellij.rt.execution.application.AppMain.main(AppMain.java:147)
... Removed 31 stack frames]]>
    </failure>
  </testcase> <!-- testCos -->
  <testcase name="testCos" time="0.0" classname="businessObject.CalculatorTest">
    <failure type="java.lang.AssertionError" message="expected [-0.13919430405964572] but found [0.9902650886087779]">
      <![CDATA[java.lang.AssertionError: expected [-0.13919430405964572] but found [0.9902650886087779]
	at businessObject.CalculatorTest.testCos(CalculatorTest.java:82)
	at com.intellij.rt.execution.application.AppMain.main(AppMain.java:147)
... Removed 31 stack frames]]>
    </failure>
  </testcase> <!-- testCos -->
  <testcase name="testCos" time="0.0" classname="businessObject.CalculatorTest">
    <failure type="java.lang.AssertionError" message="expected [0.5403023058681398] but found [0.8414709848078965]">
      <![CDATA[java.lang.AssertionError: expected [0.5403023058681398] but found [0.8414709848078965]
	at businessObject.CalculatorTest.testCos(CalculatorTest.java:82)
	at com.intellij.rt.execution.application.AppMain.main(AppMain.java:147)
... Removed 31 stack frames]]>
    </failure>
  </testcase> <!-- testCos -->
  <testcase name="testCtg" time="0.0" classname="businessObject.CalculatorTest">
    <failure type="java.lang.AssertionError" message="expected [2.981118517223813] but found [-1.0]">
      <![CDATA[java.lang.AssertionError: expected [2.981118517223813] but found [-1.0]
	at businessObject.CalculatorTest.testCtg(CalculatorTest.java:77)
	at com.intellij.rt.execution.application.AppMain.main(AppMain.java:147)
... Removed 31 stack frames]]>
    </failure>
  </testcase> <!-- testCtg -->
  <testcase name="testCtg" time="0.0" classname="businessObject.CalculatorTest">
    <failure type="java.lang.AssertionError" message="expected [-0.1405626691891154] but found [1.0]">
      <![CDATA[java.lang.AssertionError: expected [-0.1405626691891154] but found [1.0]
	at businessObject.CalculatorTest.testCtg(CalculatorTest.java:77)
	at com.intellij.rt.execution.application.AppMain.main(AppMain.java:147)
... Removed 31 stack frames]]>
    </failure>
  </testcase> <!-- testCtg -->
  <testcase name="testCtgFromZero" time="0.0" classname="businessObject.CalculatorTest">
    <failure type="org.testng.TestException" message="
Expected exception java.lang.IllegalArgumentException but got org.testng.TestException: 
Method CalculatorTest.testCtgFromZero(double)[pri:0, instance:businessObject.CalculatorTest@50675690] should have thrown an exception of class java.lang.IllegalArgumentException">
      <![CDATA[org.testng.TestException: 
Method CalculatorTest.testCtgFromZero(double)[pri:0, instance:businessObject.CalculatorTest@50675690] should have thrown an exception of class java.lang.IllegalArgumentException
	at com.intellij.rt.execution.application.AppMain.main(AppMain.java:147)
Method CalculatorTest.testCtgFromZero(double)[pri:0, instance:businessObject.CalculatorTest@50675690] should have thrown an exception of class java.lang.IllegalArgumentException
	... 20 more
... Removed 27 stack frames]]>
    </failure>
  </testcase> <!-- testCtgFromZero -->
  <testcase name="testDivDouble" time="0.0" classname="businessObject.CalculatorTest"/>
  <testcase name="testDivDouble" time="0.016" classname="businessObject.CalculatorTest"/>
  <testcase name="testDivDouble" time="0.002" classname="businessObject.CalculatorTest"/>
  <testcase name="testDivDouble" time="0.0" classname="businessObject.CalculatorTest"/>
  <testcase name="testDivDouble" time="0.001" classname="businessObject.CalculatorTest"/>
  <testcase name="testDivLong" time="0.0" classname="businessObject.CalculatorTest"/>
  <testcase name="testDivLong" time="0.0" classname="businessObject.CalculatorTest"/>
  <testcase name="testDivLong" time="0.0" classname="businessObject.CalculatorTest"/>
  <testcase name="testDivLong" time="0.0" classname="businessObject.CalculatorTest"/>
  <testcase name="testDivOnZeroDouble" time="0.0" classname="businessObject.CalculatorTest">
    <failure type="org.testng.TestException" message="
Expected exception java.lang.ArithmeticException but got org.testng.TestException: 
Method CalculatorTest.testDivOnZeroDouble(double, double)[pri:0, instance:businessObject.CalculatorTest@50675690] should have thrown an exception of class java.lang.ArithmeticException">
      <![CDATA[org.testng.TestException: 
Method CalculatorTest.testDivOnZeroDouble(double, double)[pri:0, instance:businessObject.CalculatorTest@50675690] should have thrown an exception of class java.lang.ArithmeticException
	at com.intellij.rt.execution.application.AppMain.main(AppMain.java:147)
Method CalculatorTest.testDivOnZeroDouble(double, double)[pri:0, instance:businessObject.CalculatorTest@50675690] should have thrown an exception of class java.lang.ArithmeticException
	... 20 more
... Removed 27 stack frames]]>
    </failure>
  </testcase> <!-- testDivOnZeroDouble -->
  <testcase name="testDivOnZeroDouble" time="0.0" classname="businessObject.CalculatorTest">
    <failure type="org.testng.TestException" message="
Expected exception java.lang.ArithmeticException but got org.testng.TestException: 
Method CalculatorTest.testDivOnZeroDouble(double, double)[pri:0, instance:businessObject.CalculatorTest@50675690] should have thrown an exception of class java.lang.ArithmeticException">
      <![CDATA[org.testng.TestException: 
Method CalculatorTest.testDivOnZeroDouble(double, double)[pri:0, instance:businessObject.CalculatorTest@50675690] should have thrown an exception of class java.lang.ArithmeticException
	at com.intellij.rt.execution.application.AppMain.main(AppMain.java:147)
Method CalculatorTest.testDivOnZeroDouble(double, double)[pri:0, instance:businessObject.CalculatorTest@50675690] should have thrown an exception of class java.lang.ArithmeticException
	... 20 more
... Removed 27 stack frames]]>
    </failure>
  </testcase> <!-- testDivOnZeroDouble -->
  <testcase name="testDivOnZeroDouble" time="0.0" classname="businessObject.CalculatorTest">
    <failure type="org.testng.TestException" message="
Expected exception java.lang.ArithmeticException but got org.testng.TestException: 
Method CalculatorTest.testDivOnZeroDouble(double, double)[pri:0, instance:businessObject.CalculatorTest@50675690] should have thrown an exception of class java.lang.ArithmeticException">
      <![CDATA[org.testng.TestException: 
Method CalculatorTest.testDivOnZeroDouble(double, double)[pri:0, instance:businessObject.CalculatorTest@50675690] should have thrown an exception of class java.lang.ArithmeticException
	at com.intellij.rt.execution.application.AppMain.main(AppMain.java:147)
Method CalculatorTest.testDivOnZeroDouble(double, double)[pri:0, instance:businessObject.CalculatorTest@50675690] should have thrown an exception of class java.lang.ArithmeticException
	... 20 more
... Removed 27 stack frames]]>
    </failure>
  </testcase> <!-- testDivOnZeroDouble -->
  <testcase name="testDivOnZeroLong" time="0.0" classname="businessObject.CalculatorTest">
    <failure type="org.testng.TestException" message="
Expected exception java.lang.ArithmeticException but got org.testng.TestException: 
Expected exception java.lang.ArithmeticException but got java.lang.NumberFormatException: Attempt to divide by zero">
      <![CDATA[org.testng.TestException: 
Expected exception java.lang.ArithmeticException but got java.lang.NumberFormatException: Attempt to divide by zero
	at com.intellij.rt.execution.application.AppMain.main(AppMain.java:147)
Expected exception java.lang.ArithmeticException but got java.lang.NumberFormatException: Attempt to divide by zero
	... 20 more
Caused by: java.lang.NumberFormatException: Attempt to divide by zero
	at businessObject.Calculator.div(Calculator.java:36)
	at businessObject.CalculatorTest.testDivOnZeroLong(CalculatorTest.java:102)
	... 22 more
... Removed 33 stack frames]]>
    </failure>
  </testcase> <!-- testDivOnZeroLong -->
  <testcase name="testDivOnZeroLong" time="0.0" classname="businessObject.CalculatorTest">
    <failure type="org.testng.TestException" message="
Expected exception java.lang.ArithmeticException but got org.testng.TestException: 
Expected exception java.lang.ArithmeticException but got java.lang.NumberFormatException: Attempt to divide by zero">
      <![CDATA[org.testng.TestException: 
Expected exception java.lang.ArithmeticException but got java.lang.NumberFormatException: Attempt to divide by zero
	at com.intellij.rt.execution.application.AppMain.main(AppMain.java:147)
Expected exception java.lang.ArithmeticException but got java.lang.NumberFormatException: Attempt to divide by zero
	... 20 more
Caused by: java.lang.NumberFormatException: Attempt to divide by zero
	at businessObject.Calculator.div(Calculator.java:36)
	at businessObject.CalculatorTest.testDivOnZeroLong(CalculatorTest.java:102)
	... 22 more
... Removed 33 stack frames]]>
    </failure>
  </testcase> <!-- testDivOnZeroLong -->
  <testcase name="testDivOnZeroLong" time="0.0" classname="businessObject.CalculatorTest">
    <failure type="org.testng.TestException" message="
Expected exception java.lang.ArithmeticException but got org.testng.TestException: 
Expected exception java.lang.ArithmeticException but got java.lang.NumberFormatException: Attempt to divide by zero">
      <![CDATA[org.testng.TestException: 
Expected exception java.lang.ArithmeticException but got java.lang.NumberFormatException: Attempt to divide by zero
	at com.intellij.rt.execution.application.AppMain.main(AppMain.java:147)
Expected exception java.lang.ArithmeticException but got java.lang.NumberFormatException: Attempt to divide by zero
	... 20 more
Caused by: java.lang.NumberFormatException: Attempt to divide by zero
	at businessObject.Calculator.div(Calculator.java:36)
	at businessObject.CalculatorTest.testDivOnZeroLong(CalculatorTest.java:102)
	... 22 more
... Removed 33 stack frames]]>
    </failure>
  </testcase> <!-- testDivOnZeroLong -->
  <testcase name="testIsNegWithPositiveNumber" time="0.0" classname="businessObject.CalculatorTest">
    <failure type="java.lang.IllegalArgumentException" message="argument type mismatch">
      <![CDATA[java.lang.IllegalArgumentException: argument type mismatch
	at com.intellij.rt.execution.application.AppMain.main(AppMain.java:147)
... Removed 27 stack frames]]>
    </failure>
  </testcase> <!-- testIsNegWithPositiveNumber -->
  <testcase name="testIsNegative" time="0.0" classname="businessObject.CalculatorTest"/>
  <testcase name="testIsPosWithNegativeNumber" time="0.0" classname="businessObject.CalculatorTest"/>
  <testcase name="testIsPositive" time="0.0" classname="businessObject.CalculatorTest"/>
  <testcase name="testIsPositive" time="0.0" classname="businessObject.CalculatorTest">
    <failure type="java.lang.AssertionError" message="expected [true] but found [false]">
      <![CDATA[java.lang.AssertionError: expected [true] but found [false]
	at businessObject.CalculatorTest.testIsPositive(CalculatorTest.java:92)
	at com.intellij.rt.execution.application.AppMain.main(AppMain.java:147)
... Removed 31 stack frames]]>
    </failure>
  </testcase> <!-- testIsPositive -->
  <testcase name="testMultDouble" time="0.0" classname="businessObject.CalculatorTest"/>
  <testcase name="testMultDouble" time="0.0" classname="businessObject.CalculatorTest"/>
  <testcase name="testMultDouble" time="0.0" classname="businessObject.CalculatorTest"/>
  <testcase name="testMultDouble" time="0.0" classname="businessObject.CalculatorTest">
    <failure type="java.lang.AssertionError" message="expected [2740734.0] but found [2858587.0]">
      <![CDATA[java.lang.AssertionError: expected [2740734.0] but found [2858587.0]
	at businessObject.CalculatorTest.testMultDouble(CalculatorTest.java:47)
	at com.intellij.rt.execution.application.AppMain.main(AppMain.java:147)
... Removed 31 stack frames]]>
    </failure>
  </testcase> <!-- testMultDouble -->
  <testcase name="testMultDouble" time="0.0" classname="businessObject.CalculatorTest">
    <failure type="java.lang.AssertionError" message="expected [25.0] but found [27.0]">
      <![CDATA[java.lang.AssertionError: expected [25.0] but found [27.0]
	at businessObject.CalculatorTest.testMultDouble(CalculatorTest.java:47)
	at com.intellij.rt.execution.application.AppMain.main(AppMain.java:147)
... Removed 31 stack frames]]>
    </failure>
  </testcase> <!-- testMultDouble -->
  <testcase name="testMultDouble" time="0.0" classname="businessObject.CalculatorTest">
    <failure type="java.lang.AssertionError" message="expected [-150.0] but found [-159.0]">
      <![CDATA[java.lang.AssertionError: expected [-150.0] but found [-159.0]
	at businessObject.CalculatorTest.testMultDouble(CalculatorTest.java:47)
	at com.intellij.rt.execution.application.AppMain.main(AppMain.java:147)
... Removed 31 stack frames]]>
    </failure>
  </testcase> <!-- testMultDouble -->
  <testcase name="testMultDouble" time="0.0" classname="businessObject.CalculatorTest">
    <failure type="java.lang.AssertionError" message="expected [-160.0] but found [-167.0]">
      <![CDATA[java.lang.AssertionError: expected [-160.0] but found [-167.0]
	at businessObject.CalculatorTest.testMultDouble(CalculatorTest.java:47)
	at com.intellij.rt.execution.application.AppMain.main(AppMain.java:147)
... Removed 31 stack frames]]>
    </failure>
  </testcase> <!-- testMultDouble -->
  <testcase name="testMultLong" time="0.0" classname="businessObject.CalculatorTest"/>
  <testcase name="testMultLong" time="0.0" classname="businessObject.CalculatorTest"/>
  <testcase name="testMultLong" time="0.0" classname="businessObject.CalculatorTest"/>
  <testcase name="testMultLong" time="0.0" classname="businessObject.CalculatorTest"/>
  <testcase name="testMultLong" time="0.0" classname="businessObject.CalculatorTest"/>
  <testcase name="testMultLong" time="0.0" classname="businessObject.CalculatorTest"/>
  <testcase name="testMultLong" time="0.016" classname="businessObject.CalculatorTest"/>
  <testcase name="testPow" time="0.0" classname="businessObject.CalculatorTest"/>
  <testcase name="testPow" time="0.0" classname="businessObject.CalculatorTest"/>
  <testcase name="testPow" time="0.0" classname="businessObject.CalculatorTest"/>
  <testcase name="testPow" time="0.0" classname="businessObject.CalculatorTest"/>
  <testcase name="testPow" time="0.0" classname="businessObject.CalculatorTest"/>
  <testcase name="testPowNumZeroAndPowLessZero" time="0.0" classname="businessObject.CalculatorTest">
    <failure type="org.testng.TestException" message="
Expected exception java.lang.IllegalArgumentException but got org.testng.TestException: 
Method CalculatorTest.testPowNumZeroAndPowLessZero(double, double)[pri:0, instance:businessObject.CalculatorTest@50675690] should have thrown an exception of class java.lang.IllegalArgumentException">
      <![CDATA[org.testng.TestException: 
Method CalculatorTest.testPowNumZeroAndPowLessZero(double, double)[pri:0, instance:businessObject.CalculatorTest@50675690] should have thrown an exception of class java.lang.IllegalArgumentException
	at com.intellij.rt.execution.application.AppMain.main(AppMain.java:147)
Method CalculatorTest.testPowNumZeroAndPowLessZero(double, double)[pri:0, instance:businessObject.CalculatorTest@50675690] should have thrown an exception of class java.lang.IllegalArgumentException
	... 20 more
... Removed 27 stack frames]]>
    </failure>
  </testcase> <!-- testPowNumZeroAndPowLessZero -->
  <testcase name="testSin" time="0.0" classname="businessObject.CalculatorTest"/>
  <testcase name="testSin" time="0.0" classname="businessObject.CalculatorTest"/>
  <testcase name="testSin" time="0.016" classname="businessObject.CalculatorTest"/>
  <testcase name="testSin" time="0.0" classname="businessObject.CalculatorTest"/>
  <testcase name="testSqrt" time="0.0" classname="businessObject.CalculatorTest"/>
  <testcase name="testSqrt" time="0.0" classname="businessObject.CalculatorTest"/>
  <testcase name="testSqrt" time="0.0" classname="businessObject.CalculatorTest"/>
  <testcase name="testSqrtWhenNumLessZero" time="0.0" classname="businessObject.CalculatorTest">
    <failure type="org.testng.TestException" message="
Expected exception java.lang.IllegalArgumentException but got org.testng.TestException: 
Method CalculatorTest.testSqrtWhenNumLessZero(double)[pri:0, instance:businessObject.CalculatorTest@50675690] should have thrown an exception of class java.lang.IllegalArgumentException">
      <![CDATA[org.testng.TestException: 
Method CalculatorTest.testSqrtWhenNumLessZero(double)[pri:0, instance:businessObject.CalculatorTest@50675690] should have thrown an exception of class java.lang.IllegalArgumentException
	at com.intellij.rt.execution.application.AppMain.main(AppMain.java:147)
Method CalculatorTest.testSqrtWhenNumLessZero(double)[pri:0, instance:businessObject.CalculatorTest@50675690] should have thrown an exception of class java.lang.IllegalArgumentException
	... 20 more
... Removed 27 stack frames]]>
    </failure>
  </testcase> <!-- testSqrtWhenNumLessZero -->
  <testcase name="testSubDouble" time="0.0" classname="businessObject.CalculatorTest"/>
  <testcase name="testSubDouble" time="0.0" classname="businessObject.CalculatorTest"/>
  <testcase name="testSubDouble" time="0.0" classname="businessObject.CalculatorTest"/>
  <testcase name="testSubDouble" time="0.0" classname="businessObject.CalculatorTest"/>
  <testcase name="testSubDouble" time="0.0" classname="businessObject.CalculatorTest">
    <failure type="java.lang.AssertionError" message="expected [-5.6562979E7] but found [-5.6562067E7]">
      <![CDATA[java.lang.AssertionError: expected [-5.6562979E7] but found [-5.6562067E7]
	at businessObject.CalculatorTest.testSubDouble(CalculatorTest.java:37)
	at com.intellij.rt.execution.application.AppMain.main(AppMain.java:147)
... Removed 31 stack frames]]>
    </failure>
  </testcase> <!-- testSubDouble -->
  <testcase name="testSubDouble" time="0.0" classname="businessObject.CalculatorTest"/>
  <testcase name="testSubDouble" time="0.0" classname="businessObject.CalculatorTest"/>
  <testcase name="testSubLong" time="0.0" classname="businessObject.CalculatorTest"/>
  <testcase name="testSubLong" time="0.0" classname="businessObject.CalculatorTest"/>
  <testcase name="testSubLong" time="0.0" classname="businessObject.CalculatorTest"/>
  <testcase name="testSubLong" time="0.0" classname="businessObject.CalculatorTest">
    <failure type="java.lang.AssertionError" message="expected [9223372036854775807] but found [9223372036854775709]">
      <![CDATA[java.lang.AssertionError: expected [9223372036854775807] but found [9223372036854775709]
	at businessObject.CalculatorTest.testSubLong(CalculatorTest.java:31)
	at com.intellij.rt.execution.application.AppMain.main(AppMain.java:147)
... Removed 32 stack frames]]>
    </failure>
  </testcase> <!-- testSubLong -->
  <testcase name="testSubLong" time="0.0" classname="businessObject.CalculatorTest">
    <failure type="java.lang.AssertionError" message="expected [56562979] but found [-56562067]">
      <![CDATA[java.lang.AssertionError: expected [56562979] but found [-56562067]
	at businessObject.CalculatorTest.testSubLong(CalculatorTest.java:31)
	at com.intellij.rt.execution.application.AppMain.main(AppMain.java:147)
... Removed 32 stack frames]]>
    </failure>
  </testcase> <!-- testSubLong -->
  <testcase name="testSubLong" time="0.0" classname="businessObject.CalculatorTest">
    <failure type="java.lang.AssertionError" message="expected [0] but found [824682468246]">
      <![CDATA[java.lang.AssertionError: expected [0] but found [824682468246]
	at businessObject.CalculatorTest.testSubLong(CalculatorTest.java:31)
	at com.intellij.rt.execution.application.AppMain.main(AppMain.java:147)
... Removed 32 stack frames]]>
    </failure>
  </testcase> <!-- testSubLong -->
  <testcase name="testSubLong" time="0.0" classname="businessObject.CalculatorTest">
    <failure type="java.lang.AssertionError" message="expected [555555555555550] but found [-555555555555560]">
      <![CDATA[java.lang.AssertionError: expected [555555555555550] but found [-555555555555560]
	at businessObject.CalculatorTest.testSubLong(CalculatorTest.java:31)
	at com.intellij.rt.execution.application.AppMain.main(AppMain.java:147)
... Removed 32 stack frames]]>
    </failure>
  </testcase> <!-- testSubLong -->
  <testcase name="testSumDouble" time="2.025" classname="businessObject.CalculatorTest"/>
  <testcase name="testSumDouble" time="2.011" classname="businessObject.CalculatorTest"/>
  <testcase name="testSumDouble" time="2.002" classname="businessObject.CalculatorTest"/>
  <testcase name="testSumDouble" time="2.01" classname="businessObject.CalculatorTest"/>
  <testcase name="testSumDouble" time="2.002" classname="businessObject.CalculatorTest"/>
  <testcase name="testSumDouble" time="2.013" classname="businessObject.CalculatorTest"/>
  <testcase name="testSumDouble" time="2.008" classname="businessObject.CalculatorTest"/>
  <testcase name="testSumLong" time="2.0" classname="businessObject.CalculatorTest"/>
  <testcase name="testSumLong" time="2.0" classname="businessObject.CalculatorTest"/>
  <testcase name="testSumLong" time="2.009" classname="businessObject.CalculatorTest"/>
  <testcase name="testSumLong" time="2.001" classname="businessObject.CalculatorTest"/>
  <testcase name="testSumLong" time="2.008" classname="businessObject.CalculatorTest"/>
  <testcase name="testSumLong" time="2.014" classname="businessObject.CalculatorTest"/>
  <testcase name="testSumLong" time="2.001" classname="businessObject.CalculatorTest"/>
  <testcase name="testTg" time="0.0" classname="businessObject.CalculatorTest">
    <failure type="java.lang.AssertionError" message="expected [0.3354445635832207] but found [1.0]">
      <![CDATA[java.lang.AssertionError: expected [0.3354445635832207] but found [1.0]
	at businessObject.CalculatorTest.testTg(CalculatorTest.java:72)
	at com.intellij.rt.execution.application.AppMain.main(AppMain.java:147)
... Removed 31 stack frames]]>
    </failure>
  </testcase> <!-- testTg -->
  <testcase name="testTg" time="0.0" classname="businessObject.CalculatorTest">
    <failure type="java.lang.AssertionError" message="expected [0.0] but found [NaN]">
      <![CDATA[java.lang.AssertionError: expected [0.0] but found [NaN]
	at businessObject.CalculatorTest.testTg(CalculatorTest.java:72)
	at com.intellij.rt.execution.application.AppMain.main(AppMain.java:147)
... Removed 31 stack frames]]>
    </failure>
  </testcase> <!-- testTg -->
  <testcase name="testTg" time="0.0" classname="businessObject.CalculatorTest">
    <failure type="java.lang.AssertionError" message="expected [-7.114264447088601] but found [1.0]">
      <![CDATA[java.lang.AssertionError: expected [-7.114264447088601] but found [1.0]
	at businessObject.CalculatorTest.testTg(CalculatorTest.java:72)
	at com.intellij.rt.execution.application.AppMain.main(AppMain.java:147)
... Removed 31 stack frames]]>
    </failure>
  </testcase> <!-- testTg -->
</testsuite> <!-- tesNgTask -->
