<?xml version="1.0" encoding="UTF-8"?>
<!-- Generated by org.testng.reporters.JUnitReportReporter -->
<testsuite hostname="EPUAKYIW0675" name="businessObject.CalculatorTest" tests="95" failures="19" timestamp="2 Nov 2016 13:40:19 GMT" time="28.116" errors="19">
  <testcase name="testMultDouble" time="0.000" classname="businessObject.CalculatorTest">
    <error type="java.lang.AssertionError" message="expected [2740734.0] but found [2858587.0]">
      <![CDATA[java.lang.AssertionError: expected [2740734.0] but found [2858587.0]
	at org.testng.Assert.fail(Assert.java:94)
	at org.testng.Assert.failNotEquals(Assert.java:494)
	at org.testng.Assert.assertEquals(Assert.java:207)
	at org.testng.Assert.assertEquals(Assert.java:220)
	at businessObject.CalculatorTest.testMultDouble(CalculatorTest.java:47)
	at sun.reflect.NativeMethodAccessorImpl.invoke0(Native Method)
	at sun.reflect.NativeMethodAccessorImpl.invoke(NativeMethodAccessorImpl.java:62)
	at sun.reflect.DelegatingMethodAccessorImpl.invoke(DelegatingMethodAccessorImpl.java:43)
	at java.lang.reflect.Method.invoke(Method.java:498)
	at org.testng.internal.MethodInvocationHelper.invokeMethod(MethodInvocationHelper.java:84)
	at org.testng.internal.Invoker.invokeMethod(Invoker.java:714)
	at org.testng.internal.Invoker.invokeTestMethod(Invoker.java:901)
	at org.testng.internal.Invoker.invokeTestMethods(Invoker.java:1231)
	at org.testng.internal.TestMethodWorker.invokeTestMethods(TestMethodWorker.java:127)
	at org.testng.internal.TestMethodWorker.run(TestMethodWorker.java:111)
	at org.testng.TestRunner.privateRun(TestRunner.java:767)
	at org.testng.TestRunner.run(TestRunner.java:617)
	at org.testng.SuiteRunner.runTest(SuiteRunner.java:348)
	at org.testng.SuiteRunner.runSequentially(SuiteRunner.java:343)
	at org.testng.SuiteRunner.privateRun(SuiteRunner.java:305)
	at org.testng.SuiteRunner.run(SuiteRunner.java:254)
	at org.testng.SuiteRunnerWorker.runSuite(SuiteRunnerWorker.java:52)
	at org.testng.SuiteRunnerWorker.run(SuiteRunnerWorker.java:86)
	at org.testng.TestNG.runSuitesSequentially(TestNG.java:1224)
	at org.testng.TestNG.runSuitesLocally(TestNG.java:1149)
	at org.testng.TestNG.run(TestNG.java:1057)
	at org.testng.IDEARemoteTestNG.run(IDEARemoteTestNG.java:72)
	at org.testng.RemoteTestNGStarter.main(RemoteTestNGStarter.java:124)
	at sun.reflect.NativeMethodAccessorImpl.invoke0(Native Method)
	at sun.reflect.NativeMethodAccessorImpl.invoke(NativeMethodAccessorImpl.java:62)
	at sun.reflect.DelegatingMethodAccessorImpl.invoke(DelegatingMethodAccessorImpl.java:43)
	at java.lang.reflect.Method.invoke(Method.java:498)
	at com.intellij.rt.execution.application.AppMain.main(AppMain.java:147)
]]>
    </error>
  </testcase> <!-- testMultDouble -->
  <testcase name="testSubLong" time="0.000" classname="businessObject.CalculatorTest">
    <error type="java.lang.AssertionError" message="expected [0] but found [824682468246]">
      <![CDATA[java.lang.AssertionError: expected [0] but found [824682468246]
	at org.testng.Assert.fail(Assert.java:94)
	at org.testng.Assert.failNotEquals(Assert.java:494)
	at org.testng.Assert.assertEquals(Assert.java:123)
	at org.testng.Assert.assertEquals(Assert.java:265)
	at org.testng.Assert.assertEquals(Assert.java:275)
	at businessObject.CalculatorTest.testSubLong(CalculatorTest.java:31)
	at sun.reflect.NativeMethodAccessorImpl.invoke0(Native Method)
	at sun.reflect.NativeMethodAccessorImpl.invoke(NativeMethodAccessorImpl.java:62)
	at sun.reflect.DelegatingMethodAccessorImpl.invoke(DelegatingMethodAccessorImpl.java:43)
	at java.lang.reflect.Method.invoke(Method.java:498)
	at org.testng.internal.MethodInvocationHelper.invokeMethod(MethodInvocationHelper.java:84)
	at org.testng.internal.Invoker.invokeMethod(Invoker.java:714)
	at org.testng.internal.Invoker.invokeTestMethod(Invoker.java:901)
	at org.testng.internal.Invoker.invokeTestMethods(Invoker.java:1231)
	at org.testng.internal.TestMethodWorker.invokeTestMethods(TestMethodWorker.java:127)
	at org.testng.internal.TestMethodWorker.run(TestMethodWorker.java:111)
	at org.testng.TestRunner.privateRun(TestRunner.java:767)
	at org.testng.TestRunner.run(TestRunner.java:617)
	at org.testng.SuiteRunner.runTest(SuiteRunner.java:348)
	at org.testng.SuiteRunner.runSequentially(SuiteRunner.java:343)
	at org.testng.SuiteRunner.privateRun(SuiteRunner.java:305)
	at org.testng.SuiteRunner.run(SuiteRunner.java:254)
	at org.testng.SuiteRunnerWorker.runSuite(SuiteRunnerWorker.java:52)
	at org.testng.SuiteRunnerWorker.run(SuiteRunnerWorker.java:86)
	at org.testng.TestNG.runSuitesSequentially(TestNG.java:1224)
	at org.testng.TestNG.runSuitesLocally(TestNG.java:1149)
	at org.testng.TestNG.run(TestNG.java:1057)
	at org.testng.IDEARemoteTestNG.run(IDEARemoteTestNG.java:72)
	at org.testng.RemoteTestNGStarter.main(RemoteTestNGStarter.java:124)
	at sun.reflect.NativeMethodAccessorImpl.invoke0(Native Method)
	at sun.reflect.NativeMethodAccessorImpl.invoke(NativeMethodAccessorImpl.java:62)
	at sun.reflect.DelegatingMethodAccessorImpl.invoke(DelegatingMethodAccessorImpl.java:43)
	at java.lang.reflect.Method.invoke(Method.java:498)
	at com.intellij.rt.execution.application.AppMain.main(AppMain.java:147)
]]>
    </error>
  </testcase> <!-- testSubLong -->
  <testcase name="testSumLong" time="2.007" classname="businessObject.CalculatorTest"/>
  <testcase name="testSqrtWhenNumLessZero" time="0.001" classname="businessObject.CalculatorTest">
    <failure type="org.testng.TestException" message="
Expected exception java.lang.IllegalArgumentException but got org.testng.TestException: 
Method CalculatorTest.testSqrtWhenNumLessZero(double)[pri:0, instance:businessObject.CalculatorTest@47d384ee] should have thrown an exception of class java.lang.IllegalArgumentException">
      <![CDATA[org.testng.TestException: 
Expected exception java.lang.IllegalArgumentException but got org.testng.TestException: 
Method CalculatorTest.testSqrtWhenNumLessZero(double)[pri:0, instance:businessObject.CalculatorTest@47d384ee] should have thrown an exception of class java.lang.IllegalArgumentException
	at org.testng.internal.Invoker.handleInvocationResults(Invoker.java:1497)
	at org.testng.internal.Invoker.invokeTestMethods(Invoker.java:1245)
	at org.testng.internal.TestMethodWorker.invokeTestMethods(TestMethodWorker.java:127)
	at org.testng.internal.TestMethodWorker.run(TestMethodWorker.java:111)
	at org.testng.TestRunner.privateRun(TestRunner.java:767)
	at org.testng.TestRunner.run(TestRunner.java:617)
	at org.testng.SuiteRunner.runTest(SuiteRunner.java:348)
	at org.testng.SuiteRunner.runSequentially(SuiteRunner.java:343)
	at org.testng.SuiteRunner.privateRun(SuiteRunner.java:305)
	at org.testng.SuiteRunner.run(SuiteRunner.java:254)
	at org.testng.SuiteRunnerWorker.runSuite(SuiteRunnerWorker.java:52)
	at org.testng.SuiteRunnerWorker.run(SuiteRunnerWorker.java:86)
	at org.testng.TestNG.runSuitesSequentially(TestNG.java:1224)
	at org.testng.TestNG.runSuitesLocally(TestNG.java:1149)
	at org.testng.TestNG.run(TestNG.java:1057)
	at org.testng.IDEARemoteTestNG.run(IDEARemoteTestNG.java:72)
	at org.testng.RemoteTestNGStarter.main(RemoteTestNGStarter.java:124)
	at sun.reflect.NativeMethodAccessorImpl.invoke0(Native Method)
	at sun.reflect.NativeMethodAccessorImpl.invoke(NativeMethodAccessorImpl.java:62)
	at sun.reflect.DelegatingMethodAccessorImpl.invoke(DelegatingMethodAccessorImpl.java:43)
	at java.lang.reflect.Method.invoke(Method.java:498)
	at com.intellij.rt.execution.application.AppMain.main(AppMain.java:147)
Caused by: org.testng.TestException: 
Method CalculatorTest.testSqrtWhenNumLessZero(double)[pri:0, instance:businessObject.CalculatorTest@47d384ee] should have thrown an exception of class java.lang.IllegalArgumentException
	at org.testng.internal.Invoker.handleInvocationResults(Invoker.java:1512)
	at org.testng.internal.Invoker.invokeMethod(Invoker.java:754)
	at org.testng.internal.Invoker.invokeTestMethod(Invoker.java:901)
	at org.testng.internal.Invoker.invokeTestMethods(Invoker.java:1231)
	... 20 more
]]>
    </failure>
  </testcase> <!-- testSqrtWhenNumLessZero -->
  <testcase name="testSumOverflowLong" time="0.000" classname="businessObject.CalculatorTest">
    <failure type="org.testng.TestException" message="
Expected exception java.lang.StackOverflowError but got org.testng.TestException: 
Method CalculatorTest.testSumOverflowLong(long, long)[pri:0, instance:businessObject.CalculatorTest@47d384ee] should have thrown an exception of class java.lang.StackOverflowError">
      <![CDATA[org.testng.TestException: 
Expected exception java.lang.StackOverflowError but got org.testng.TestException: 
Method CalculatorTest.testSumOverflowLong(long, long)[pri:0, instance:businessObject.CalculatorTest@47d384ee] should have thrown an exception of class java.lang.StackOverflowError
	at org.testng.internal.Invoker.handleInvocationResults(Invoker.java:1497)
	at org.testng.internal.Invoker.invokeTestMethods(Invoker.java:1245)
	at org.testng.internal.TestMethodWorker.invokeTestMethods(TestMethodWorker.java:127)
	at org.testng.internal.TestMethodWorker.run(TestMethodWorker.java:111)
	at org.testng.TestRunner.privateRun(TestRunner.java:767)
	at org.testng.TestRunner.run(TestRunner.java:617)
	at org.testng.SuiteRunner.runTest(SuiteRunner.java:348)
	at org.testng.SuiteRunner.runSequentially(SuiteRunner.java:343)
	at org.testng.SuiteRunner.privateRun(SuiteRunner.java:305)
	at org.testng.SuiteRunner.run(SuiteRunner.java:254)
	at org.testng.SuiteRunnerWorker.runSuite(SuiteRunnerWorker.java:52)
	at org.testng.SuiteRunnerWorker.run(SuiteRunnerWorker.java:86)
	at org.testng.TestNG.runSuitesSequentially(TestNG.java:1224)
	at org.testng.TestNG.runSuitesLocally(TestNG.java:1149)
	at org.testng.TestNG.run(TestNG.java:1057)
	at org.testng.IDEARemoteTestNG.run(IDEARemoteTestNG.java:72)
	at org.testng.RemoteTestNGStarter.main(RemoteTestNGStarter.java:124)
	at sun.reflect.NativeMethodAccessorImpl.invoke0(Native Method)
	at sun.reflect.NativeMethodAccessorImpl.invoke(NativeMethodAccessorImpl.java:62)
	at sun.reflect.DelegatingMethodAccessorImpl.invoke(DelegatingMethodAccessorImpl.java:43)
	at java.lang.reflect.Method.invoke(Method.java:498)
	at com.intellij.rt.execution.application.AppMain.main(AppMain.java:147)
Caused by: org.testng.TestException: 
Method CalculatorTest.testSumOverflowLong(long, long)[pri:0, instance:businessObject.CalculatorTest@47d384ee] should have thrown an exception of class java.lang.StackOverflowError
	at org.testng.internal.Invoker.handleInvocationResults(Invoker.java:1512)
	at org.testng.internal.Invoker.invokeMethod(Invoker.java:754)
	at org.testng.internal.Invoker.invokeTestMethod(Invoker.java:901)
	at org.testng.internal.Invoker.invokeTestMethods(Invoker.java:1231)
	... 20 more
]]>
    </failure>
  </testcase> <!-- testSumOverflowLong -->
  <testcase name="testSumDouble" time="2.004" classname="businessObject.CalculatorTest"/>
  <testcase name="testDivOverflowLong" time="0.000" classname="businessObject.CalculatorTest">
    <failure type="org.testng.TestException" message="
Expected exception java.lang.StackOverflowError but got org.testng.TestException: 
Method CalculatorTest.testDivOverflowLong(long, long)[pri:0, instance:businessObject.CalculatorTest@47d384ee] should have thrown an exception of class java.lang.StackOverflowError">
      <![CDATA[org.testng.TestException: 
Expected exception java.lang.StackOverflowError but got org.testng.TestException: 
Method CalculatorTest.testDivOverflowLong(long, long)[pri:0, instance:businessObject.CalculatorTest@47d384ee] should have thrown an exception of class java.lang.StackOverflowError
	at org.testng.internal.Invoker.handleInvocationResults(Invoker.java:1497)
	at org.testng.internal.Invoker.invokeTestMethods(Invoker.java:1245)
	at org.testng.internal.TestMethodWorker.invokeTestMethods(TestMethodWorker.java:127)
	at org.testng.internal.TestMethodWorker.run(TestMethodWorker.java:111)
	at org.testng.TestRunner.privateRun(TestRunner.java:767)
	at org.testng.TestRunner.run(TestRunner.java:617)
	at org.testng.SuiteRunner.runTest(SuiteRunner.java:348)
	at org.testng.SuiteRunner.runSequentially(SuiteRunner.java:343)
	at org.testng.SuiteRunner.privateRun(SuiteRunner.java:305)
	at org.testng.SuiteRunner.run(SuiteRunner.java:254)
	at org.testng.SuiteRunnerWorker.runSuite(SuiteRunnerWorker.java:52)
	at org.testng.SuiteRunnerWorker.run(SuiteRunnerWorker.java:86)
	at org.testng.TestNG.runSuitesSequentially(TestNG.java:1224)
	at org.testng.TestNG.runSuitesLocally(TestNG.java:1149)
	at org.testng.TestNG.run(TestNG.java:1057)
	at org.testng.IDEARemoteTestNG.run(IDEARemoteTestNG.java:72)
	at org.testng.RemoteTestNGStarter.main(RemoteTestNGStarter.java:124)
	at sun.reflect.NativeMethodAccessorImpl.invoke0(Native Method)
	at sun.reflect.NativeMethodAccessorImpl.invoke(NativeMethodAccessorImpl.java:62)
	at sun.reflect.DelegatingMethodAccessorImpl.invoke(DelegatingMethodAccessorImpl.java:43)
	at java.lang.reflect.Method.invoke(Method.java:498)
	at com.intellij.rt.execution.application.AppMain.main(AppMain.java:147)
Caused by: org.testng.TestException: 
Method CalculatorTest.testDivOverflowLong(long, long)[pri:0, instance:businessObject.CalculatorTest@47d384ee] should have thrown an exception of class java.lang.StackOverflowError
	at org.testng.internal.Invoker.handleInvocationResults(Invoker.java:1512)
	at org.testng.internal.Invoker.invokeMethod(Invoker.java:754)
	at org.testng.internal.Invoker.invokeTestMethod(Invoker.java:901)
	at org.testng.internal.Invoker.invokeTestMethods(Invoker.java:1231)
	... 20 more
]]>
    </failure>
  </testcase> <!-- testDivOverflowLong -->
  <testcase name="testSumDouble" time="2.010" classname="businessObject.CalculatorTest"/>
  <testcase name="testSumLong" time="2.005" classname="businessObject.CalculatorTest"/>
  <testcase name="testDivOverflowLong" time="0.000" classname="businessObject.CalculatorTest">
    <failure type="org.testng.TestException" message="
Expected exception java.lang.StackOverflowError but got org.testng.TestException: 
Method CalculatorTest.testDivOverflowLong(long, long)[pri:0, instance:businessObject.CalculatorTest@47d384ee] should have thrown an exception of class java.lang.StackOverflowError">
      <![CDATA[org.testng.TestException: 
Expected exception java.lang.StackOverflowError but got org.testng.TestException: 
Method CalculatorTest.testDivOverflowLong(long, long)[pri:0, instance:businessObject.CalculatorTest@47d384ee] should have thrown an exception of class java.lang.StackOverflowError
	at org.testng.internal.Invoker.handleInvocationResults(Invoker.java:1497)
	at org.testng.internal.Invoker.invokeTestMethods(Invoker.java:1245)
	at org.testng.internal.TestMethodWorker.invokeTestMethods(TestMethodWorker.java:127)
	at org.testng.internal.TestMethodWorker.run(TestMethodWorker.java:111)
	at org.testng.TestRunner.privateRun(TestRunner.java:767)
	at org.testng.TestRunner.run(TestRunner.java:617)
	at org.testng.SuiteRunner.runTest(SuiteRunner.java:348)
	at org.testng.SuiteRunner.runSequentially(SuiteRunner.java:343)
	at org.testng.SuiteRunner.privateRun(SuiteRunner.java:305)
	at org.testng.SuiteRunner.run(SuiteRunner.java:254)
	at org.testng.SuiteRunnerWorker.runSuite(SuiteRunnerWorker.java:52)
	at org.testng.SuiteRunnerWorker.run(SuiteRunnerWorker.java:86)
	at org.testng.TestNG.runSuitesSequentially(TestNG.java:1224)
	at org.testng.TestNG.runSuitesLocally(TestNG.java:1149)
	at org.testng.TestNG.run(TestNG.java:1057)
	at org.testng.IDEARemoteTestNG.run(IDEARemoteTestNG.java:72)
	at org.testng.RemoteTestNGStarter.main(RemoteTestNGStarter.java:124)
	at sun.reflect.NativeMethodAccessorImpl.invoke0(Native Method)
	at sun.reflect.NativeMethodAccessorImpl.invoke(NativeMethodAccessorImpl.java:62)
	at sun.reflect.DelegatingMethodAccessorImpl.invoke(DelegatingMethodAccessorImpl.java:43)
	at java.lang.reflect.Method.invoke(Method.java:498)
	at com.intellij.rt.execution.application.AppMain.main(AppMain.java:147)
Caused by: org.testng.TestException: 
Method CalculatorTest.testDivOverflowLong(long, long)[pri:0, instance:businessObject.CalculatorTest@47d384ee] should have thrown an exception of class java.lang.StackOverflowError
	at org.testng.internal.Invoker.handleInvocationResults(Invoker.java:1512)
	at org.testng.internal.Invoker.invokeMethod(Invoker.java:754)
	at org.testng.internal.Invoker.invokeTestMethod(Invoker.java:901)
	at org.testng.internal.Invoker.invokeTestMethods(Invoker.java:1231)
	... 20 more
]]>
    </failure>
  </testcase> <!-- testDivOverflowLong -->
  <testcase name="testCos" time="0.001" classname="businessObject.CalculatorTest">
    <error type="java.lang.AssertionError" message="expected [0.5403023058681398] but found [0.8414709848078965]">
      <![CDATA[java.lang.AssertionError: expected [0.5403023058681398] but found [0.8414709848078965]
	at org.testng.Assert.fail(Assert.java:94)
	at org.testng.Assert.failNotEquals(Assert.java:494)
	at org.testng.Assert.assertEquals(Assert.java:123)
	at org.testng.Assert.assertEquals(Assert.java:165)
	at businessObject.CalculatorTest.testCos(CalculatorTest.java:82)
	at sun.reflect.NativeMethodAccessorImpl.invoke0(Native Method)
	at sun.reflect.NativeMethodAccessorImpl.invoke(NativeMethodAccessorImpl.java:62)
	at sun.reflect.DelegatingMethodAccessorImpl.invoke(DelegatingMethodAccessorImpl.java:43)
	at java.lang.reflect.Method.invoke(Method.java:498)
	at org.testng.internal.MethodInvocationHelper.invokeMethod(MethodInvocationHelper.java:84)
	at org.testng.internal.Invoker.invokeMethod(Invoker.java:714)
	at org.testng.internal.Invoker.invokeTestMethod(Invoker.java:901)
	at org.testng.internal.Invoker.invokeTestMethods(Invoker.java:1231)
	at org.testng.internal.TestMethodWorker.invokeTestMethods(TestMethodWorker.java:127)
	at org.testng.internal.TestMethodWorker.run(TestMethodWorker.java:111)
	at org.testng.TestRunner.privateRun(TestRunner.java:767)
	at org.testng.TestRunner.run(TestRunner.java:617)
	at org.testng.SuiteRunner.runTest(SuiteRunner.java:348)
	at org.testng.SuiteRunner.runSequentially(SuiteRunner.java:343)
	at org.testng.SuiteRunner.privateRun(SuiteRunner.java:305)
	at org.testng.SuiteRunner.run(SuiteRunner.java:254)
	at org.testng.SuiteRunnerWorker.runSuite(SuiteRunnerWorker.java:52)
	at org.testng.SuiteRunnerWorker.run(SuiteRunnerWorker.java:86)
	at org.testng.TestNG.runSuitesSequentially(TestNG.java:1224)
	at org.testng.TestNG.runSuitesLocally(TestNG.java:1149)
	at org.testng.TestNG.run(TestNG.java:1057)
	at org.testng.IDEARemoteTestNG.run(IDEARemoteTestNG.java:72)
	at org.testng.RemoteTestNGStarter.main(RemoteTestNGStarter.java:124)
	at sun.reflect.NativeMethodAccessorImpl.invoke0(Native Method)
	at sun.reflect.NativeMethodAccessorImpl.invoke(NativeMethodAccessorImpl.java:62)
	at sun.reflect.DelegatingMethodAccessorImpl.invoke(DelegatingMethodAccessorImpl.java:43)
	at java.lang.reflect.Method.invoke(Method.java:498)
	at com.intellij.rt.execution.application.AppMain.main(AppMain.java:147)
]]>
    </error>
  </testcase> <!-- testCos -->
  <testcase name="testTg" time="0.000" classname="businessObject.CalculatorTest">
    <error type="java.lang.AssertionError" message="expected [0.3354445635832207] but found [1.0]">
      <![CDATA[java.lang.AssertionError: expected [0.3354445635832207] but found [1.0]
	at org.testng.Assert.fail(Assert.java:94)
	at org.testng.Assert.failNotEquals(Assert.java:494)
	at org.testng.Assert.assertEquals(Assert.java:123)
	at org.testng.Assert.assertEquals(Assert.java:165)
	at businessObject.CalculatorTest.testTg(CalculatorTest.java:72)
	at sun.reflect.NativeMethodAccessorImpl.invoke0(Native Method)
	at sun.reflect.NativeMethodAccessorImpl.invoke(NativeMethodAccessorImpl.java:62)
	at sun.reflect.DelegatingMethodAccessorImpl.invoke(DelegatingMethodAccessorImpl.java:43)
	at java.lang.reflect.Method.invoke(Method.java:498)
	at org.testng.internal.MethodInvocationHelper.invokeMethod(MethodInvocationHelper.java:84)
	at org.testng.internal.Invoker.invokeMethod(Invoker.java:714)
	at org.testng.internal.Invoker.invokeTestMethod(Invoker.java:901)
	at org.testng.internal.Invoker.invokeTestMethods(Invoker.java:1231)
	at org.testng.internal.TestMethodWorker.invokeTestMethods(TestMethodWorker.java:127)
	at org.testng.internal.TestMethodWorker.run(TestMethodWorker.java:111)
	at org.testng.TestRunner.privateRun(TestRunner.java:767)
	at org.testng.TestRunner.run(TestRunner.java:617)
	at org.testng.SuiteRunner.runTest(SuiteRunner.java:348)
	at org.testng.SuiteRunner.runSequentially(SuiteRunner.java:343)
	at org.testng.SuiteRunner.privateRun(SuiteRunner.java:305)
	at org.testng.SuiteRunner.run(SuiteRunner.java:254)
	at org.testng.SuiteRunnerWorker.runSuite(SuiteRunnerWorker.java:52)
	at org.testng.SuiteRunnerWorker.run(SuiteRunnerWorker.java:86)
	at org.testng.TestNG.runSuitesSequentially(TestNG.java:1224)
	at org.testng.TestNG.runSuitesLocally(TestNG.java:1149)
	at org.testng.TestNG.run(TestNG.java:1057)
	at org.testng.IDEARemoteTestNG.run(IDEARemoteTestNG.java:72)
	at org.testng.RemoteTestNGStarter.main(RemoteTestNGStarter.java:124)
	at sun.reflect.NativeMethodAccessorImpl.invoke0(Native Method)
	at sun.reflect.NativeMethodAccessorImpl.invoke(NativeMethodAccessorImpl.java:62)
	at sun.reflect.DelegatingMethodAccessorImpl.invoke(DelegatingMethodAccessorImpl.java:43)
	at java.lang.reflect.Method.invoke(Method.java:498)
	at com.intellij.rt.execution.application.AppMain.main(AppMain.java:147)
]]>
    </error>
  </testcase> <!-- testTg -->
  <testcase name="testMultDouble" time="0.000" classname="businessObject.CalculatorTest"/>
  <testcase name="testDivDouble" time="0.001" classname="businessObject.CalculatorTest"/>
  <testcase name="testSubLong" time="0.001" classname="businessObject.CalculatorTest"/>
  <testcase name="testSubDouble" time="0.000" classname="businessObject.CalculatorTest"/>
  <testcase name="testDivLong" time="0.001" classname="businessObject.CalculatorTest"/>
  <testcase name="testSubDouble" time="0.000" classname="businessObject.CalculatorTest"/>
  <testcase name="testSubLong" time="0.007" classname="businessObject.CalculatorTest">
    <error type="java.lang.AssertionError" message="expected [9223372036854775807] but found [9223372036854775709]">
      <![CDATA[java.lang.AssertionError: expected [9223372036854775807] but found [9223372036854775709]
	at org.testng.Assert.fail(Assert.java:94)
	at org.testng.Assert.failNotEquals(Assert.java:494)
	at org.testng.Assert.assertEquals(Assert.java:123)
	at org.testng.Assert.assertEquals(Assert.java:265)
	at org.testng.Assert.assertEquals(Assert.java:275)
	at businessObject.CalculatorTest.testSubLong(CalculatorTest.java:31)
	at sun.reflect.NativeMethodAccessorImpl.invoke0(Native Method)
	at sun.reflect.NativeMethodAccessorImpl.invoke(NativeMethodAccessorImpl.java:62)
	at sun.reflect.DelegatingMethodAccessorImpl.invoke(DelegatingMethodAccessorImpl.java:43)
	at java.lang.reflect.Method.invoke(Method.java:498)
	at org.testng.internal.MethodInvocationHelper.invokeMethod(MethodInvocationHelper.java:84)
	at org.testng.internal.Invoker.invokeMethod(Invoker.java:714)
	at org.testng.internal.Invoker.invokeTestMethod(Invoker.java:901)
	at org.testng.internal.Invoker.invokeTestMethods(Invoker.java:1231)
	at org.testng.internal.TestMethodWorker.invokeTestMethods(TestMethodWorker.java:127)
	at org.testng.internal.TestMethodWorker.run(TestMethodWorker.java:111)
	at org.testng.TestRunner.privateRun(TestRunner.java:767)
	at org.testng.TestRunner.run(TestRunner.java:617)
	at org.testng.SuiteRunner.runTest(SuiteRunner.java:348)
	at org.testng.SuiteRunner.runSequentially(SuiteRunner.java:343)
	at org.testng.SuiteRunner.privateRun(SuiteRunner.java:305)
	at org.testng.SuiteRunner.run(SuiteRunner.java:254)
	at org.testng.SuiteRunnerWorker.runSuite(SuiteRunnerWorker.java:52)
	at org.testng.SuiteRunnerWorker.run(SuiteRunnerWorker.java:86)
	at org.testng.TestNG.runSuitesSequentially(TestNG.java:1224)
	at org.testng.TestNG.runSuitesLocally(TestNG.java:1149)
	at org.testng.TestNG.run(TestNG.java:1057)
	at org.testng.IDEARemoteTestNG.run(IDEARemoteTestNG.java:72)
	at org.testng.RemoteTestNGStarter.main(RemoteTestNGStarter.java:124)
	at sun.reflect.NativeMethodAccessorImpl.invoke0(Native Method)
	at sun.reflect.NativeMethodAccessorImpl.invoke(NativeMethodAccessorImpl.java:62)
	at sun.reflect.DelegatingMethodAccessorImpl.invoke(DelegatingMethodAccessorImpl.java:43)
	at java.lang.reflect.Method.invoke(Method.java:498)
	at com.intellij.rt.execution.application.AppMain.main(AppMain.java:147)
]]>
    </error>
  </testcase> <!-- testSubLong -->
  <testcase name="testSumDouble" time="2.002" classname="businessObject.CalculatorTest"/>
  <testcase name="testDivOnZeroLong" time="0.000" classname="businessObject.CalculatorTest">
    <failure type="org.testng.TestException" message="
Expected exception java.lang.ArithmeticException but got org.testng.TestException: 
Expected exception java.lang.ArithmeticException but got java.lang.NumberFormatException: Attempt to divide by zero">
      <![CDATA[org.testng.TestException: 
Expected exception java.lang.ArithmeticException but got org.testng.TestException: 
Expected exception java.lang.ArithmeticException but got java.lang.NumberFormatException: Attempt to divide by zero
	at org.testng.internal.Invoker.handleInvocationResults(Invoker.java:1497)
	at org.testng.internal.Invoker.invokeTestMethods(Invoker.java:1245)
	at org.testng.internal.TestMethodWorker.invokeTestMethods(TestMethodWorker.java:127)
	at org.testng.internal.TestMethodWorker.run(TestMethodWorker.java:111)
	at org.testng.TestRunner.privateRun(TestRunner.java:767)
	at org.testng.TestRunner.run(TestRunner.java:617)
	at org.testng.SuiteRunner.runTest(SuiteRunner.java:348)
	at org.testng.SuiteRunner.runSequentially(SuiteRunner.java:343)
	at org.testng.SuiteRunner.privateRun(SuiteRunner.java:305)
	at org.testng.SuiteRunner.run(SuiteRunner.java:254)
	at org.testng.SuiteRunnerWorker.runSuite(SuiteRunnerWorker.java:52)
	at org.testng.SuiteRunnerWorker.run(SuiteRunnerWorker.java:86)
	at org.testng.TestNG.runSuitesSequentially(TestNG.java:1224)
	at org.testng.TestNG.runSuitesLocally(TestNG.java:1149)
	at org.testng.TestNG.run(TestNG.java:1057)
	at org.testng.IDEARemoteTestNG.run(IDEARemoteTestNG.java:72)
	at org.testng.RemoteTestNGStarter.main(RemoteTestNGStarter.java:124)
	at sun.reflect.NativeMethodAccessorImpl.invoke0(Native Method)
	at sun.reflect.NativeMethodAccessorImpl.invoke(NativeMethodAccessorImpl.java:62)
	at sun.reflect.DelegatingMethodAccessorImpl.invoke(DelegatingMethodAccessorImpl.java:43)
	at java.lang.reflect.Method.invoke(Method.java:498)
	at com.intellij.rt.execution.application.AppMain.main(AppMain.java:147)
Caused by: org.testng.TestException: 
Expected exception java.lang.ArithmeticException but got java.lang.NumberFormatException: Attempt to divide by zero
	at org.testng.internal.Invoker.handleInvocationResults(Invoker.java:1497)
	at org.testng.internal.Invoker.invokeMethod(Invoker.java:754)
	at org.testng.internal.Invoker.invokeTestMethod(Invoker.java:901)
	at org.testng.internal.Invoker.invokeTestMethods(Invoker.java:1231)
	... 20 more
Caused by: java.lang.NumberFormatException: Attempt to divide by zero
	at businessObject.Calculator.div(Calculator.java:36)
	at businessObject.CalculatorTest.testDivOnZeroLong(CalculatorTest.java:102)
	at sun.reflect.NativeMethodAccessorImpl.invoke0(Native Method)
	at sun.reflect.NativeMethodAccessorImpl.invoke(NativeMethodAccessorImpl.java:62)
	at sun.reflect.DelegatingMethodAccessorImpl.invoke(DelegatingMethodAccessorImpl.java:43)
	at java.lang.reflect.Method.invoke(Method.java:498)
	at org.testng.internal.MethodInvocationHelper.invokeMethod(MethodInvocationHelper.java:84)
	at org.testng.internal.Invoker.invokeMethod(Invoker.java:714)
	... 22 more
]]>
    </failure>
  </testcase> <!-- testDivOnZeroLong -->
  <testcase name="testMultLong" time="0.001" classname="businessObject.CalculatorTest"/>
  <testcase name="testMultDouble" time="0.000" classname="businessObject.CalculatorTest"/>
  <testcase name="testCos" time="0.001" classname="businessObject.CalculatorTest">
    <error type="java.lang.AssertionError" message="expected [-0.13919430405964572] but found [0.9902650886087779]">
      <![CDATA[java.lang.AssertionError: expected [-0.13919430405964572] but found [0.9902650886087779]
	at org.testng.Assert.fail(Assert.java:94)
	at org.testng.Assert.failNotEquals(Assert.java:494)
	at org.testng.Assert.assertEquals(Assert.java:123)
	at org.testng.Assert.assertEquals(Assert.java:165)
	at businessObject.CalculatorTest.testCos(CalculatorTest.java:82)
	at sun.reflect.NativeMethodAccessorImpl.invoke0(Native Method)
	at sun.reflect.NativeMethodAccessorImpl.invoke(NativeMethodAccessorImpl.java:62)
	at sun.reflect.DelegatingMethodAccessorImpl.invoke(DelegatingMethodAccessorImpl.java:43)
	at java.lang.reflect.Method.invoke(Method.java:498)
	at org.testng.internal.MethodInvocationHelper.invokeMethod(MethodInvocationHelper.java:84)
	at org.testng.internal.Invoker.invokeMethod(Invoker.java:714)
	at org.testng.internal.Invoker.invokeTestMethod(Invoker.java:901)
	at org.testng.internal.Invoker.invokeTestMethods(Invoker.java:1231)
	at org.testng.internal.TestMethodWorker.invokeTestMethods(TestMethodWorker.java:127)
	at org.testng.internal.TestMethodWorker.run(TestMethodWorker.java:111)
	at org.testng.TestRunner.privateRun(TestRunner.java:767)
	at org.testng.TestRunner.run(TestRunner.java:617)
	at org.testng.SuiteRunner.runTest(SuiteRunner.java:348)
	at org.testng.SuiteRunner.runSequentially(SuiteRunner.java:343)
	at org.testng.SuiteRunner.privateRun(SuiteRunner.java:305)
	at org.testng.SuiteRunner.run(SuiteRunner.java:254)
	at org.testng.SuiteRunnerWorker.runSuite(SuiteRunnerWorker.java:52)
	at org.testng.SuiteRunnerWorker.run(SuiteRunnerWorker.java:86)
	at org.testng.TestNG.runSuitesSequentially(TestNG.java:1224)
	at org.testng.TestNG.runSuitesLocally(TestNG.java:1149)
	at org.testng.TestNG.run(TestNG.java:1057)
	at org.testng.IDEARemoteTestNG.run(IDEARemoteTestNG.java:72)
	at org.testng.RemoteTestNGStarter.main(RemoteTestNGStarter.java:124)
	at sun.reflect.NativeMethodAccessorImpl.invoke0(Native Method)
	at sun.reflect.NativeMethodAccessorImpl.invoke(NativeMethodAccessorImpl.java:62)
	at sun.reflect.DelegatingMethodAccessorImpl.invoke(DelegatingMethodAccessorImpl.java:43)
	at java.lang.reflect.Method.invoke(Method.java:498)
	at com.intellij.rt.execution.application.AppMain.main(AppMain.java:147)
]]>
    </error>
  </testcase> <!-- testCos -->
  <testcase name="testSin" time="0.000" classname="businessObject.CalculatorTest"/>
  <testcase name="testDivDouble" time="0.000" classname="businessObject.CalculatorTest"/>
  <testcase name="testSubLong" time="0.001" classname="businessObject.CalculatorTest">
    <error type="java.lang.AssertionError" message="expected [555555555555550] but found [-555555555555560]">
      <![CDATA[java.lang.AssertionError: expected [555555555555550] but found [-555555555555560]
	at org.testng.Assert.fail(Assert.java:94)
	at org.testng.Assert.failNotEquals(Assert.java:494)
	at org.testng.Assert.assertEquals(Assert.java:123)
	at org.testng.Assert.assertEquals(Assert.java:265)
	at org.testng.Assert.assertEquals(Assert.java:275)
	at businessObject.CalculatorTest.testSubLong(CalculatorTest.java:31)
	at sun.reflect.NativeMethodAccessorImpl.invoke0(Native Method)
	at sun.reflect.NativeMethodAccessorImpl.invoke(NativeMethodAccessorImpl.java:62)
	at sun.reflect.DelegatingMethodAccessorImpl.invoke(DelegatingMethodAccessorImpl.java:43)
	at java.lang.reflect.Method.invoke(Method.java:498)
	at org.testng.internal.MethodInvocationHelper.invokeMethod(MethodInvocationHelper.java:84)
	at org.testng.internal.Invoker.invokeMethod(Invoker.java:714)
	at org.testng.internal.Invoker.invokeTestMethod(Invoker.java:901)
	at org.testng.internal.Invoker.invokeTestMethods(Invoker.java:1231)
	at org.testng.internal.TestMethodWorker.invokeTestMethods(TestMethodWorker.java:127)
	at org.testng.internal.TestMethodWorker.run(TestMethodWorker.java:111)
	at org.testng.TestRunner.privateRun(TestRunner.java:767)
	at org.testng.TestRunner.run(TestRunner.java:617)
	at org.testng.SuiteRunner.runTest(SuiteRunner.java:348)
	at org.testng.SuiteRunner.runSequentially(SuiteRunner.java:343)
	at org.testng.SuiteRunner.privateRun(SuiteRunner.java:305)
	at org.testng.SuiteRunner.run(SuiteRunner.java:254)
	at org.testng.SuiteRunnerWorker.runSuite(SuiteRunnerWorker.java:52)
	at org.testng.SuiteRunnerWorker.run(SuiteRunnerWorker.java:86)
	at org.testng.TestNG.runSuitesSequentially(TestNG.java:1224)
	at org.testng.TestNG.runSuitesLocally(TestNG.java:1149)
	at org.testng.TestNG.run(TestNG.java:1057)
	at org.testng.IDEARemoteTestNG.run(IDEARemoteTestNG.java:72)
	at org.testng.RemoteTestNGStarter.main(RemoteTestNGStarter.java:124)
	at sun.reflect.NativeMethodAccessorImpl.invoke0(Native Method)
	at sun.reflect.NativeMethodAccessorImpl.invoke(NativeMethodAccessorImpl.java:62)
	at sun.reflect.DelegatingMethodAccessorImpl.invoke(DelegatingMethodAccessorImpl.java:43)
	at java.lang.reflect.Method.invoke(Method.java:498)
	at com.intellij.rt.execution.application.AppMain.main(AppMain.java:147)
]]>
    </error>
  </testcase> <!-- testSubLong -->
  <testcase name="testMultLong" time="0.001" classname="businessObject.CalculatorTest"/>
  <testcase name="testIsNegWithPositiveNumber" time="0.000" classname="businessObject.CalculatorTest">
    <failure type="java.lang.IllegalArgumentException" message="argument type mismatch">
      <![CDATA[java.lang.IllegalArgumentException: argument type mismatch
	at sun.reflect.NativeMethodAccessorImpl.invoke0(Native Method)
	at sun.reflect.NativeMethodAccessorImpl.invoke(NativeMethodAccessorImpl.java:62)
	at sun.reflect.DelegatingMethodAccessorImpl.invoke(DelegatingMethodAccessorImpl.java:43)
	at java.lang.reflect.Method.invoke(Method.java:498)
	at org.testng.internal.MethodInvocationHelper.invokeMethod(MethodInvocationHelper.java:84)
	at org.testng.internal.Invoker.invokeMethod(Invoker.java:714)
	at org.testng.internal.Invoker.invokeTestMethod(Invoker.java:901)
	at org.testng.internal.Invoker.invokeTestMethods(Invoker.java:1231)
	at org.testng.internal.TestMethodWorker.invokeTestMethods(TestMethodWorker.java:127)
	at org.testng.internal.TestMethodWorker.run(TestMethodWorker.java:111)
	at org.testng.TestRunner.privateRun(TestRunner.java:767)
	at org.testng.TestRunner.run(TestRunner.java:617)
	at org.testng.SuiteRunner.runTest(SuiteRunner.java:348)
	at org.testng.SuiteRunner.runSequentially(SuiteRunner.java:343)
	at org.testng.SuiteRunner.privateRun(SuiteRunner.java:305)
	at org.testng.SuiteRunner.run(SuiteRunner.java:254)
	at org.testng.SuiteRunnerWorker.runSuite(SuiteRunnerWorker.java:52)
	at org.testng.SuiteRunnerWorker.run(SuiteRunnerWorker.java:86)
	at org.testng.TestNG.runSuitesSequentially(TestNG.java:1224)
	at org.testng.TestNG.runSuitesLocally(TestNG.java:1149)
	at org.testng.TestNG.run(TestNG.java:1057)
	at org.testng.IDEARemoteTestNG.run(IDEARemoteTestNG.java:72)
	at org.testng.RemoteTestNGStarter.main(RemoteTestNGStarter.java:124)
	at sun.reflect.NativeMethodAccessorImpl.invoke0(Native Method)
	at sun.reflect.NativeMethodAccessorImpl.invoke(NativeMethodAccessorImpl.java:62)
	at sun.reflect.DelegatingMethodAccessorImpl.invoke(DelegatingMethodAccessorImpl.java:43)
	at java.lang.reflect.Method.invoke(Method.java:498)
	at com.intellij.rt.execution.application.AppMain.main(AppMain.java:147)
]]>
    </failure>
  </testcase> <!-- testIsNegWithPositiveNumber -->
  <testcase name="testIsPositive" time="0.001" classname="businessObject.CalculatorTest"/>
  <testcase name="testSin" time="0.000" classname="businessObject.CalculatorTest"/>
  <testcase name="testSin" time="0.000" classname="businessObject.CalculatorTest"/>
  <testcase name="testDivDouble" time="0.001" classname="businessObject.CalculatorTest"/>
  <testcase name="testSumOverflowDouble" time="0.000" classname="businessObject.CalculatorTest">
    <failure type="org.testng.TestException" message="
Expected exception java.lang.StackOverflowError but got java.lang.RuntimeException: java.lang.IllegalStateException: Cannot get a numeric value from a text cell">
      <![CDATA[org.testng.TestException: 
Expected exception java.lang.StackOverflowError but got java.lang.RuntimeException: java.lang.IllegalStateException: Cannot get a numeric value from a text cell
	at org.testng.internal.Invoker.handleInvocationResults(Invoker.java:1497)
	at org.testng.internal.Invoker.invokeTestMethods(Invoker.java:1185)
	at org.testng.internal.TestMethodWorker.invokeTestMethods(TestMethodWorker.java:127)
	at org.testng.internal.TestMethodWorker.run(TestMethodWorker.java:111)
	at org.testng.TestRunner.privateRun(TestRunner.java:767)
	at org.testng.TestRunner.run(TestRunner.java:617)
	at org.testng.SuiteRunner.runTest(SuiteRunner.java:348)
	at org.testng.SuiteRunner.runSequentially(SuiteRunner.java:343)
	at org.testng.SuiteRunner.privateRun(SuiteRunner.java:305)
	at org.testng.SuiteRunner.run(SuiteRunner.java:254)
	at org.testng.SuiteRunnerWorker.runSuite(SuiteRunnerWorker.java:52)
	at org.testng.SuiteRunnerWorker.run(SuiteRunnerWorker.java:86)
	at org.testng.TestNG.runSuitesSequentially(TestNG.java:1224)
	at org.testng.TestNG.runSuitesLocally(TestNG.java:1149)
	at org.testng.TestNG.run(TestNG.java:1057)
	at org.testng.IDEARemoteTestNG.run(IDEARemoteTestNG.java:72)
	at org.testng.RemoteTestNGStarter.main(RemoteTestNGStarter.java:124)
	at sun.reflect.NativeMethodAccessorImpl.invoke0(Native Method)
	at sun.reflect.NativeMethodAccessorImpl.invoke(NativeMethodAccessorImpl.java:62)
	at sun.reflect.DelegatingMethodAccessorImpl.invoke(DelegatingMethodAccessorImpl.java:43)
	at java.lang.reflect.Method.invoke(Method.java:498)
	at com.intellij.rt.execution.application.AppMain.main(AppMain.java:147)
Caused by: java.lang.RuntimeException: java.lang.IllegalStateException: Cannot get a numeric value from a text cell
	at org.testng.internal.MethodInvocationHelper.invokeDataProvider(MethodInvocationHelper.java:161)
	at org.testng.internal.Parameters.handleParameters(Parameters.java:429)
	at org.testng.internal.Invoker.handleParameters(Invoker.java:1383)
	at org.testng.internal.Invoker.createParameters(Invoker.java:1075)
	at org.testng.internal.Invoker.invokeTestMethods(Invoker.java:1180)
	... 20 more
Caused by: java.lang.IllegalStateException: Cannot get a numeric value from a text cell
	at org.apache.poi.hssf.usermodel.HSSFCell.typeMismatch(HSSFCell.java:654)
	at org.apache.poi.hssf.usermodel.HSSFCell.getNumericCellValue(HSSFCell.java:679)
	at dataProvider.ReaderXls.parse(ReaderXls.java:41)
	at dataProvider.DataProviderClass.getDataDouble(DataProviderClass.java:24)
	at sun.reflect.GeneratedMethodAccessor2.invoke(Unknown Source)
	at sun.reflect.DelegatingMethodAccessorImpl.invoke(DelegatingMethodAccessorImpl.java:43)
	at java.lang.reflect.Method.invoke(Method.java:498)
	at org.testng.internal.MethodInvocationHelper.invokeMethod(MethodInvocationHelper.java:84)
	at org.testng.internal.MethodInvocationHelper.invokeDataProvider(MethodInvocationHelper.java:135)
	... 24 more
]]>
    </failure>
  </testcase> <!-- testSumOverflowDouble -->
  <testcase name="testTg" time="0.000" classname="businessObject.CalculatorTest">
    <error type="java.lang.AssertionError" message="expected [-7.114264447088601] but found [1.0]">
      <![CDATA[java.lang.AssertionError: expected [-7.114264447088601] but found [1.0]
	at org.testng.Assert.fail(Assert.java:94)
	at org.testng.Assert.failNotEquals(Assert.java:494)
	at org.testng.Assert.assertEquals(Assert.java:123)
	at org.testng.Assert.assertEquals(Assert.java:165)
	at businessObject.CalculatorTest.testTg(CalculatorTest.java:72)
	at sun.reflect.NativeMethodAccessorImpl.invoke0(Native Method)
	at sun.reflect.NativeMethodAccessorImpl.invoke(NativeMethodAccessorImpl.java:62)
	at sun.reflect.DelegatingMethodAccessorImpl.invoke(DelegatingMethodAccessorImpl.java:43)
	at java.lang.reflect.Method.invoke(Method.java:498)
	at org.testng.internal.MethodInvocationHelper.invokeMethod(MethodInvocationHelper.java:84)
	at org.testng.internal.Invoker.invokeMethod(Invoker.java:714)
	at org.testng.internal.Invoker.invokeTestMethod(Invoker.java:901)
	at org.testng.internal.Invoker.invokeTestMethods(Invoker.java:1231)
	at org.testng.internal.TestMethodWorker.invokeTestMethods(TestMethodWorker.java:127)
	at org.testng.internal.TestMethodWorker.run(TestMethodWorker.java:111)
	at org.testng.TestRunner.privateRun(TestRunner.java:767)
	at org.testng.TestRunner.run(TestRunner.java:617)
	at org.testng.SuiteRunner.runTest(SuiteRunner.java:348)
	at org.testng.SuiteRunner.runSequentially(SuiteRunner.java:343)
	at org.testng.SuiteRunner.privateRun(SuiteRunner.java:305)
	at org.testng.SuiteRunner.run(SuiteRunner.java:254)
	at org.testng.SuiteRunnerWorker.runSuite(SuiteRunnerWorker.java:52)
	at org.testng.SuiteRunnerWorker.run(SuiteRunnerWorker.java:86)
	at org.testng.TestNG.runSuitesSequentially(TestNG.java:1224)
	at org.testng.TestNG.runSuitesLocally(TestNG.java:1149)
	at org.testng.TestNG.run(TestNG.java:1057)
	at org.testng.IDEARemoteTestNG.run(IDEARemoteTestNG.java:72)
	at org.testng.RemoteTestNGStarter.main(RemoteTestNGStarter.java:124)
	at sun.reflect.NativeMethodAccessorImpl.invoke0(Native Method)
	at sun.reflect.NativeMethodAccessorImpl.invoke(NativeMethodAccessorImpl.java:62)
	at sun.reflect.DelegatingMethodAccessorImpl.invoke(DelegatingMethodAccessorImpl.java:43)
	at java.lang.reflect.Method.invoke(Method.java:498)
	at com.intellij.rt.execution.application.AppMain.main(AppMain.java:147)
]]>
    </error>
  </testcase> <!-- testTg -->
  <testcase name="testSumDouble" time="2.002" classname="businessObject.CalculatorTest"/>
  <testcase name="testDivLong" time="0.000" classname="businessObject.CalculatorTest"/>
  <testcase name="testSumLong" time="2.004" classname="businessObject.CalculatorTest"/>
  <testcase name="testSumLong" time="2.004" classname="businessObject.CalculatorTest"/>
  <testcase name="testMultDouble" time="0.001" classname="businessObject.CalculatorTest">
    <error type="java.lang.AssertionError" message="expected [-160.0] but found [-167.0]">
      <![CDATA[java.lang.AssertionError: expected [-160.0] but found [-167.0]
	at org.testng.Assert.fail(Assert.java:94)
	at org.testng.Assert.failNotEquals(Assert.java:494)
	at org.testng.Assert.assertEquals(Assert.java:207)
	at org.testng.Assert.assertEquals(Assert.java:220)
	at businessObject.CalculatorTest.testMultDouble(CalculatorTest.java:47)
	at sun.reflect.NativeMethodAccessorImpl.invoke0(Native Method)
	at sun.reflect.NativeMethodAccessorImpl.invoke(NativeMethodAccessorImpl.java:62)
	at sun.reflect.DelegatingMethodAccessorImpl.invoke(DelegatingMethodAccessorImpl.java:43)
	at java.lang.reflect.Method.invoke(Method.java:498)
	at org.testng.internal.MethodInvocationHelper.invokeMethod(MethodInvocationHelper.java:84)
	at org.testng.internal.Invoker.invokeMethod(Invoker.java:714)
	at org.testng.internal.Invoker.invokeTestMethod(Invoker.java:901)
	at org.testng.internal.Invoker.invokeTestMethods(Invoker.java:1231)
	at org.testng.internal.TestMethodWorker.invokeTestMethods(TestMethodWorker.java:127)
	at org.testng.internal.TestMethodWorker.run(TestMethodWorker.java:111)
	at org.testng.TestRunner.privateRun(TestRunner.java:767)
	at org.testng.TestRunner.run(TestRunner.java:617)
	at org.testng.SuiteRunner.runTest(SuiteRunner.java:348)
	at org.testng.SuiteRunner.runSequentially(SuiteRunner.java:343)
	at org.testng.SuiteRunner.privateRun(SuiteRunner.java:305)
	at org.testng.SuiteRunner.run(SuiteRunner.java:254)
	at org.testng.SuiteRunnerWorker.runSuite(SuiteRunnerWorker.java:52)
	at org.testng.SuiteRunnerWorker.run(SuiteRunnerWorker.java:86)
	at org.testng.TestNG.runSuitesSequentially(TestNG.java:1224)
	at org.testng.TestNG.runSuitesLocally(TestNG.java:1149)
	at org.testng.TestNG.run(TestNG.java:1057)
	at org.testng.IDEARemoteTestNG.run(IDEARemoteTestNG.java:72)
	at org.testng.RemoteTestNGStarter.main(RemoteTestNGStarter.java:124)
	at sun.reflect.NativeMethodAccessorImpl.invoke0(Native Method)
	at sun.reflect.NativeMethodAccessorImpl.invoke(NativeMethodAccessorImpl.java:62)
	at sun.reflect.DelegatingMethodAccessorImpl.invoke(DelegatingMethodAccessorImpl.java:43)
	at java.lang.reflect.Method.invoke(Method.java:498)
	at com.intellij.rt.execution.application.AppMain.main(AppMain.java:147)
]]>
    </error>
  </testcase> <!-- testMultDouble -->
  <testcase name="testCos" time="0.000" classname="businessObject.CalculatorTest">
    <error type="java.lang.AssertionError" message="expected [1.0] but found [0.0]">
      <![CDATA[java.lang.AssertionError: expected [1.0] but found [0.0]
	at org.testng.Assert.fail(Assert.java:94)
	at org.testng.Assert.failNotEquals(Assert.java:494)
	at org.testng.Assert.assertEquals(Assert.java:123)
	at org.testng.Assert.assertEquals(Assert.java:165)
	at businessObject.CalculatorTest.testCos(CalculatorTest.java:82)
	at sun.reflect.NativeMethodAccessorImpl.invoke0(Native Method)
	at sun.reflect.NativeMethodAccessorImpl.invoke(NativeMethodAccessorImpl.java:62)
	at sun.reflect.DelegatingMethodAccessorImpl.invoke(DelegatingMethodAccessorImpl.java:43)
	at java.lang.reflect.Method.invoke(Method.java:498)
	at org.testng.internal.MethodInvocationHelper.invokeMethod(MethodInvocationHelper.java:84)
	at org.testng.internal.Invoker.invokeMethod(Invoker.java:714)
	at org.testng.internal.Invoker.invokeTestMethod(Invoker.java:901)
	at org.testng.internal.Invoker.invokeTestMethods(Invoker.java:1231)
	at org.testng.internal.TestMethodWorker.invokeTestMethods(TestMethodWorker.java:127)
	at org.testng.internal.TestMethodWorker.run(TestMethodWorker.java:111)
	at org.testng.TestRunner.privateRun(TestRunner.java:767)
	at org.testng.TestRunner.run(TestRunner.java:617)
	at org.testng.SuiteRunner.runTest(SuiteRunner.java:348)
	at org.testng.SuiteRunner.runSequentially(SuiteRunner.java:343)
	at org.testng.SuiteRunner.privateRun(SuiteRunner.java:305)
	at org.testng.SuiteRunner.run(SuiteRunner.java:254)
	at org.testng.SuiteRunnerWorker.runSuite(SuiteRunnerWorker.java:52)
	at org.testng.SuiteRunnerWorker.run(SuiteRunnerWorker.java:86)
	at org.testng.TestNG.runSuitesSequentially(TestNG.java:1224)
	at org.testng.TestNG.runSuitesLocally(TestNG.java:1149)
	at org.testng.TestNG.run(TestNG.java:1057)
	at org.testng.IDEARemoteTestNG.run(IDEARemoteTestNG.java:72)
	at org.testng.RemoteTestNGStarter.main(RemoteTestNGStarter.java:124)
	at sun.reflect.NativeMethodAccessorImpl.invoke0(Native Method)
	at sun.reflect.NativeMethodAccessorImpl.invoke(NativeMethodAccessorImpl.java:62)
	at sun.reflect.DelegatingMethodAccessorImpl.invoke(DelegatingMethodAccessorImpl.java:43)
	at java.lang.reflect.Method.invoke(Method.java:498)
	at com.intellij.rt.execution.application.AppMain.main(AppMain.java:147)
]]>
    </error>
  </testcase> <!-- testCos -->
  <testcase name="testMultDouble" time="0.000" classname="businessObject.CalculatorTest">
    <error type="java.lang.AssertionError" message="expected [-150.0] but found [-159.0]">
      <![CDATA[java.lang.AssertionError: expected [-150.0] but found [-159.0]
	at org.testng.Assert.fail(Assert.java:94)
	at org.testng.Assert.failNotEquals(Assert.java:494)
	at org.testng.Assert.assertEquals(Assert.java:207)
	at org.testng.Assert.assertEquals(Assert.java:220)
	at businessObject.CalculatorTest.testMultDouble(CalculatorTest.java:47)
	at sun.reflect.NativeMethodAccessorImpl.invoke0(Native Method)
	at sun.reflect.NativeMethodAccessorImpl.invoke(NativeMethodAccessorImpl.java:62)
	at sun.reflect.DelegatingMethodAccessorImpl.invoke(DelegatingMethodAccessorImpl.java:43)
	at java.lang.reflect.Method.invoke(Method.java:498)
	at org.testng.internal.MethodInvocationHelper.invokeMethod(MethodInvocationHelper.java:84)
	at org.testng.internal.Invoker.invokeMethod(Invoker.java:714)
	at org.testng.internal.Invoker.invokeTestMethod(Invoker.java:901)
	at org.testng.internal.Invoker.invokeTestMethods(Invoker.java:1231)
	at org.testng.internal.TestMethodWorker.invokeTestMethods(TestMethodWorker.java:127)
	at org.testng.internal.TestMethodWorker.run(TestMethodWorker.java:111)
	at org.testng.TestRunner.privateRun(TestRunner.java:767)
	at org.testng.TestRunner.run(TestRunner.java:617)
	at org.testng.SuiteRunner.runTest(SuiteRunner.java:348)
	at org.testng.SuiteRunner.runSequentially(SuiteRunner.java:343)
	at org.testng.SuiteRunner.privateRun(SuiteRunner.java:305)
	at org.testng.SuiteRunner.run(SuiteRunner.java:254)
	at org.testng.SuiteRunnerWorker.runSuite(SuiteRunnerWorker.java:52)
	at org.testng.SuiteRunnerWorker.run(SuiteRunnerWorker.java:86)
	at org.testng.TestNG.runSuitesSequentially(TestNG.java:1224)
	at org.testng.TestNG.runSuitesLocally(TestNG.java:1149)
	at org.testng.TestNG.run(TestNG.java:1057)
	at org.testng.IDEARemoteTestNG.run(IDEARemoteTestNG.java:72)
	at org.testng.RemoteTestNGStarter.main(RemoteTestNGStarter.java:124)
	at sun.reflect.NativeMethodAccessorImpl.invoke0(Native Method)
	at sun.reflect.NativeMethodAccessorImpl.invoke(NativeMethodAccessorImpl.java:62)
	at sun.reflect.DelegatingMethodAccessorImpl.invoke(DelegatingMethodAccessorImpl.java:43)
	at java.lang.reflect.Method.invoke(Method.java:498)
	at com.intellij.rt.execution.application.AppMain.main(AppMain.java:147)
]]>
    </error>
  </testcase> <!-- testMultDouble -->
  <testcase name="testDivOnZeroLong" time="0.000" classname="businessObject.CalculatorTest">
    <failure type="org.testng.TestException" message="
Expected exception java.lang.ArithmeticException but got org.testng.TestException: 
Expected exception java.lang.ArithmeticException but got java.lang.NumberFormatException: Attempt to divide by zero">
      <![CDATA[org.testng.TestException: 
Expected exception java.lang.ArithmeticException but got org.testng.TestException: 
Expected exception java.lang.ArithmeticException but got java.lang.NumberFormatException: Attempt to divide by zero
	at org.testng.internal.Invoker.handleInvocationResults(Invoker.java:1497)
	at org.testng.internal.Invoker.invokeTestMethods(Invoker.java:1245)
	at org.testng.internal.TestMethodWorker.invokeTestMethods(TestMethodWorker.java:127)
	at org.testng.internal.TestMethodWorker.run(TestMethodWorker.java:111)
	at org.testng.TestRunner.privateRun(TestRunner.java:767)
	at org.testng.TestRunner.run(TestRunner.java:617)
	at org.testng.SuiteRunner.runTest(SuiteRunner.java:348)
	at org.testng.SuiteRunner.runSequentially(SuiteRunner.java:343)
	at org.testng.SuiteRunner.privateRun(SuiteRunner.java:305)
	at org.testng.SuiteRunner.run(SuiteRunner.java:254)
	at org.testng.SuiteRunnerWorker.runSuite(SuiteRunnerWorker.java:52)
	at org.testng.SuiteRunnerWorker.run(SuiteRunnerWorker.java:86)
	at org.testng.TestNG.runSuitesSequentially(TestNG.java:1224)
	at org.testng.TestNG.runSuitesLocally(TestNG.java:1149)
	at org.testng.TestNG.run(TestNG.java:1057)
	at org.testng.IDEARemoteTestNG.run(IDEARemoteTestNG.java:72)
	at org.testng.RemoteTestNGStarter.main(RemoteTestNGStarter.java:124)
	at sun.reflect.NativeMethodAccessorImpl.invoke0(Native Method)
	at sun.reflect.NativeMethodAccessorImpl.invoke(NativeMethodAccessorImpl.java:62)
	at sun.reflect.DelegatingMethodAccessorImpl.invoke(DelegatingMethodAccessorImpl.java:43)
	at java.lang.reflect.Method.invoke(Method.java:498)
	at com.intellij.rt.execution.application.AppMain.main(AppMain.java:147)
Caused by: org.testng.TestException: 
Expected exception java.lang.ArithmeticException but got java.lang.NumberFormatException: Attempt to divide by zero
	at org.testng.internal.Invoker.handleInvocationResults(Invoker.java:1497)
	at org.testng.internal.Invoker.invokeMethod(Invoker.java:754)
	at org.testng.internal.Invoker.invokeTestMethod(Invoker.java:901)
	at org.testng.internal.Invoker.invokeTestMethods(Invoker.java:1231)
	... 20 more
Caused by: java.lang.NumberFormatException: Attempt to divide by zero
	at businessObject.Calculator.div(Calculator.java:36)
	at businessObject.CalculatorTest.testDivOnZeroLong(CalculatorTest.java:102)
	at sun.reflect.NativeMethodAccessorImpl.invoke0(Native Method)
	at sun.reflect.NativeMethodAccessorImpl.invoke(NativeMethodAccessorImpl.java:62)
	at sun.reflect.DelegatingMethodAccessorImpl.invoke(DelegatingMethodAccessorImpl.java:43)
	at java.lang.reflect.Method.invoke(Method.java:498)
	at org.testng.internal.MethodInvocationHelper.invokeMethod(MethodInvocationHelper.java:84)
	at org.testng.internal.Invoker.invokeMethod(Invoker.java:714)
	... 22 more
]]>
    </failure>
  </testcase> <!-- testDivOnZeroLong -->
  <testcase name="testSubDouble" time="0.000" classname="businessObject.CalculatorTest">
    <error type="java.lang.AssertionError" message="expected [-5.6562979E7] but found [-5.6562067E7]">
      <![CDATA[java.lang.AssertionError: expected [-5.6562979E7] but found [-5.6562067E7]
	at org.testng.Assert.fail(Assert.java:94)
	at org.testng.Assert.failNotEquals(Assert.java:494)
	at org.testng.Assert.assertEquals(Assert.java:207)
	at org.testng.Assert.assertEquals(Assert.java:220)
	at businessObject.CalculatorTest.testSubDouble(CalculatorTest.java:37)
	at sun.reflect.NativeMethodAccessorImpl.invoke0(Native Method)
	at sun.reflect.NativeMethodAccessorImpl.invoke(NativeMethodAccessorImpl.java:62)
	at sun.reflect.DelegatingMethodAccessorImpl.invoke(DelegatingMethodAccessorImpl.java:43)
	at java.lang.reflect.Method.invoke(Method.java:498)
	at org.testng.internal.MethodInvocationHelper.invokeMethod(MethodInvocationHelper.java:84)
	at org.testng.internal.Invoker.invokeMethod(Invoker.java:714)
	at org.testng.internal.Invoker.invokeTestMethod(Invoker.java:901)
	at org.testng.internal.Invoker.invokeTestMethods(Invoker.java:1231)
	at org.testng.internal.TestMethodWorker.invokeTestMethods(TestMethodWorker.java:127)
	at org.testng.internal.TestMethodWorker.run(TestMethodWorker.java:111)
	at org.testng.TestRunner.privateRun(TestRunner.java:767)
	at org.testng.TestRunner.run(TestRunner.java:617)
	at org.testng.SuiteRunner.runTest(SuiteRunner.java:348)
	at org.testng.SuiteRunner.runSequentially(SuiteRunner.java:343)
	at org.testng.SuiteRunner.privateRun(SuiteRunner.java:305)
	at org.testng.SuiteRunner.run(SuiteRunner.java:254)
	at org.testng.SuiteRunnerWorker.runSuite(SuiteRunnerWorker.java:52)
	at org.testng.SuiteRunnerWorker.run(SuiteRunnerWorker.java:86)
	at org.testng.TestNG.runSuitesSequentially(TestNG.java:1224)
	at org.testng.TestNG.runSuitesLocally(TestNG.java:1149)
	at org.testng.TestNG.run(TestNG.java:1057)
	at org.testng.IDEARemoteTestNG.run(IDEARemoteTestNG.java:72)
	at org.testng.RemoteTestNGStarter.main(RemoteTestNGStarter.java:124)
	at sun.reflect.NativeMethodAccessorImpl.invoke0(Native Method)
	at sun.reflect.NativeMethodAccessorImpl.invoke(NativeMethodAccessorImpl.java:62)
	at sun.reflect.DelegatingMethodAccessorImpl.invoke(DelegatingMethodAccessorImpl.java:43)
	at java.lang.reflect.Method.invoke(Method.java:498)
	at com.intellij.rt.execution.application.AppMain.main(AppMain.java:147)
]]>
    </error>
  </testcase> <!-- testSubDouble -->
  <testcase name="testPow" time="0.001" classname="businessObject.CalculatorTest"/>
  <testcase name="testMultOverflowDouble" time="0.000" classname="businessObject.CalculatorTest">
    <failure type="org.testng.TestException" message="
Expected exception java.lang.StackOverflowError but got java.lang.RuntimeException: java.lang.IllegalStateException: Cannot get a numeric value from a text cell">
      <![CDATA[org.testng.TestException: 
Expected exception java.lang.StackOverflowError but got java.lang.RuntimeException: java.lang.IllegalStateException: Cannot get a numeric value from a text cell
	at org.testng.internal.Invoker.handleInvocationResults(Invoker.java:1497)
	at org.testng.internal.Invoker.invokeTestMethods(Invoker.java:1185)
	at org.testng.internal.TestMethodWorker.invokeTestMethods(TestMethodWorker.java:127)
	at org.testng.internal.TestMethodWorker.run(TestMethodWorker.java:111)
	at org.testng.TestRunner.privateRun(TestRunner.java:767)
	at org.testng.TestRunner.run(TestRunner.java:617)
	at org.testng.SuiteRunner.runTest(SuiteRunner.java:348)
	at org.testng.SuiteRunner.runSequentially(SuiteRunner.java:343)
	at org.testng.SuiteRunner.privateRun(SuiteRunner.java:305)
	at org.testng.SuiteRunner.run(SuiteRunner.java:254)
	at org.testng.SuiteRunnerWorker.runSuite(SuiteRunnerWorker.java:52)
	at org.testng.SuiteRunnerWorker.run(SuiteRunnerWorker.java:86)
	at org.testng.TestNG.runSuitesSequentially(TestNG.java:1224)
	at org.testng.TestNG.runSuitesLocally(TestNG.java:1149)
	at org.testng.TestNG.run(TestNG.java:1057)
	at org.testng.IDEARemoteTestNG.run(IDEARemoteTestNG.java:72)
	at org.testng.RemoteTestNGStarter.main(RemoteTestNGStarter.java:124)
	at sun.reflect.NativeMethodAccessorImpl.invoke0(Native Method)
	at sun.reflect.NativeMethodAccessorImpl.invoke(NativeMethodAccessorImpl.java:62)
	at sun.reflect.DelegatingMethodAccessorImpl.invoke(DelegatingMethodAccessorImpl.java:43)
	at java.lang.reflect.Method.invoke(Method.java:498)
	at com.intellij.rt.execution.application.AppMain.main(AppMain.java:147)
Caused by: java.lang.RuntimeException: java.lang.IllegalStateException: Cannot get a numeric value from a text cell
	at org.testng.internal.MethodInvocationHelper.invokeDataProvider(MethodInvocationHelper.java:161)
	at org.testng.internal.Parameters.handleParameters(Parameters.java:429)
	at org.testng.internal.Invoker.handleParameters(Invoker.java:1383)
	at org.testng.internal.Invoker.createParameters(Invoker.java:1075)
	at org.testng.internal.Invoker.invokeTestMethods(Invoker.java:1180)
	... 20 more
Caused by: java.lang.IllegalStateException: Cannot get a numeric value from a text cell
	at org.apache.poi.hssf.usermodel.HSSFCell.typeMismatch(HSSFCell.java:654)
	at org.apache.poi.hssf.usermodel.HSSFCell.getNumericCellValue(HSSFCell.java:679)
	at dataProvider.ReaderXls.parse(ReaderXls.java:41)
	at dataProvider.DataProviderClass.getDataDouble(DataProviderClass.java:24)
	at sun.reflect.NativeMethodAccessorImpl.invoke0(Native Method)
	at sun.reflect.NativeMethodAccessorImpl.invoke(NativeMethodAccessorImpl.java:62)
	at sun.reflect.DelegatingMethodAccessorImpl.invoke(DelegatingMethodAccessorImpl.java:43)
	at java.lang.reflect.Method.invoke(Method.java:498)
	at org.testng.internal.MethodInvocationHelper.invokeMethod(MethodInvocationHelper.java:84)
	at org.testng.internal.MethodInvocationHelper.invokeDataProvider(MethodInvocationHelper.java:135)
	... 24 more
]]>
    </failure>
  </testcase> <!-- testMultOverflowDouble -->
  <testcase name="testDivDouble" time="0.001" classname="businessObject.CalculatorTest"/>
  <testcase name="testSumDouble" time="2.006" classname="businessObject.CalculatorTest"/>
  <testcase name="testSumLong" time="2.003" classname="businessObject.CalculatorTest"/>
  <testcase name="testSubDouble" time="0.003" classname="businessObject.CalculatorTest"/>
  <testcase name="testDivLong" time="0.000" classname="businessObject.CalculatorTest"/>
  <testcase name="testSumOverflowLong" time="0.000" classname="businessObject.CalculatorTest">
    <failure type="org.testng.TestException" message="
Expected exception java.lang.StackOverflowError but got org.testng.TestException: 
Method CalculatorTest.testSumOverflowLong(long, long)[pri:0, instance:businessObject.CalculatorTest@47d384ee] should have thrown an exception of class java.lang.StackOverflowError">
      <![CDATA[org.testng.TestException: 
Expected exception java.lang.StackOverflowError but got org.testng.TestException: 
Method CalculatorTest.testSumOverflowLong(long, long)[pri:0, instance:businessObject.CalculatorTest@47d384ee] should have thrown an exception of class java.lang.StackOverflowError
	at org.testng.internal.Invoker.handleInvocationResults(Invoker.java:1497)
	at org.testng.internal.Invoker.invokeTestMethods(Invoker.java:1245)
	at org.testng.internal.TestMethodWorker.invokeTestMethods(TestMethodWorker.java:127)
	at org.testng.internal.TestMethodWorker.run(TestMethodWorker.java:111)
	at org.testng.TestRunner.privateRun(TestRunner.java:767)
	at org.testng.TestRunner.run(TestRunner.java:617)
	at org.testng.SuiteRunner.runTest(SuiteRunner.java:348)
	at org.testng.SuiteRunner.runSequentially(SuiteRunner.java:343)
	at org.testng.SuiteRunner.privateRun(SuiteRunner.java:305)
	at org.testng.SuiteRunner.run(SuiteRunner.java:254)
	at org.testng.SuiteRunnerWorker.runSuite(SuiteRunnerWorker.java:52)
	at org.testng.SuiteRunnerWorker.run(SuiteRunnerWorker.java:86)
	at org.testng.TestNG.runSuitesSequentially(TestNG.java:1224)
	at org.testng.TestNG.runSuitesLocally(TestNG.java:1149)
	at org.testng.TestNG.run(TestNG.java:1057)
	at org.testng.IDEARemoteTestNG.run(IDEARemoteTestNG.java:72)
	at org.testng.RemoteTestNGStarter.main(RemoteTestNGStarter.java:124)
	at sun.reflect.NativeMethodAccessorImpl.invoke0(Native Method)
	at sun.reflect.NativeMethodAccessorImpl.invoke(NativeMethodAccessorImpl.java:62)
	at sun.reflect.DelegatingMethodAccessorImpl.invoke(DelegatingMethodAccessorImpl.java:43)
	at java.lang.reflect.Method.invoke(Method.java:498)
	at com.intellij.rt.execution.application.AppMain.main(AppMain.java:147)
Caused by: org.testng.TestException: 
Method CalculatorTest.testSumOverflowLong(long, long)[pri:0, instance:businessObject.CalculatorTest@47d384ee] should have thrown an exception of class java.lang.StackOverflowError
	at org.testng.internal.Invoker.handleInvocationResults(Invoker.java:1512)
	at org.testng.internal.Invoker.invokeMethod(Invoker.java:754)
	at org.testng.internal.Invoker.invokeTestMethod(Invoker.java:901)
	at org.testng.internal.Invoker.invokeTestMethods(Invoker.java:1231)
	... 20 more
]]>
    </failure>
  </testcase> <!-- testSumOverflowLong -->
  <testcase name="testTg" time="0.000" classname="businessObject.CalculatorTest">
    <error type="java.lang.AssertionError" message="expected [0.0] but found [NaN]">
      <![CDATA[java.lang.AssertionError: expected [0.0] but found [NaN]
	at org.testng.Assert.fail(Assert.java:94)
	at org.testng.Assert.failNotEquals(Assert.java:494)
	at org.testng.Assert.assertEquals(Assert.java:123)
	at org.testng.Assert.assertEquals(Assert.java:165)
	at businessObject.CalculatorTest.testTg(CalculatorTest.java:72)
	at sun.reflect.NativeMethodAccessorImpl.invoke0(Native Method)
	at sun.reflect.NativeMethodAccessorImpl.invoke(NativeMethodAccessorImpl.java:62)
	at sun.reflect.DelegatingMethodAccessorImpl.invoke(DelegatingMethodAccessorImpl.java:43)
	at java.lang.reflect.Method.invoke(Method.java:498)
	at org.testng.internal.MethodInvocationHelper.invokeMethod(MethodInvocationHelper.java:84)
	at org.testng.internal.Invoker.invokeMethod(Invoker.java:714)
	at org.testng.internal.Invoker.invokeTestMethod(Invoker.java:901)
	at org.testng.internal.Invoker.invokeTestMethods(Invoker.java:1231)
	at org.testng.internal.TestMethodWorker.invokeTestMethods(TestMethodWorker.java:127)
	at org.testng.internal.TestMethodWorker.run(TestMethodWorker.java:111)
	at org.testng.TestRunner.privateRun(TestRunner.java:767)
	at org.testng.TestRunner.run(TestRunner.java:617)
	at org.testng.SuiteRunner.runTest(SuiteRunner.java:348)
	at org.testng.SuiteRunner.runSequentially(SuiteRunner.java:343)
	at org.testng.SuiteRunner.privateRun(SuiteRunner.java:305)
	at org.testng.SuiteRunner.run(SuiteRunner.java:254)
	at org.testng.SuiteRunnerWorker.runSuite(SuiteRunnerWorker.java:52)
	at org.testng.SuiteRunnerWorker.run(SuiteRunnerWorker.java:86)
	at org.testng.TestNG.runSuitesSequentially(TestNG.java:1224)
	at org.testng.TestNG.runSuitesLocally(TestNG.java:1149)
	at org.testng.TestNG.run(TestNG.java:1057)
	at org.testng.IDEARemoteTestNG.run(IDEARemoteTestNG.java:72)
	at org.testng.RemoteTestNGStarter.main(RemoteTestNGStarter.java:124)
	at sun.reflect.NativeMethodAccessorImpl.invoke0(Native Method)
	at sun.reflect.NativeMethodAccessorImpl.invoke(NativeMethodAccessorImpl.java:62)
	at sun.reflect.DelegatingMethodAccessorImpl.invoke(DelegatingMethodAccessorImpl.java:43)
	at java.lang.reflect.Method.invoke(Method.java:498)
	at com.intellij.rt.execution.application.AppMain.main(AppMain.java:147)
]]>
    </error>
  </testcase> <!-- testTg -->
  <testcase name="testSubDouble" time="0.001" classname="businessObject.CalculatorTest"/>
  <testcase name="testMultLong" time="0.000" classname="businessObject.CalculatorTest"/>
  <testcase name="testCtg" time="0.000" classname="businessObject.CalculatorTest">
    <error type="java.lang.AssertionError" message="expected [-0.1405626691891154] but found [1.0]">
      <![CDATA[java.lang.AssertionError: expected [-0.1405626691891154] but found [1.0]
	at org.testng.Assert.fail(Assert.java:94)
	at org.testng.Assert.failNotEquals(Assert.java:494)
	at org.testng.Assert.assertEquals(Assert.java:123)
	at org.testng.Assert.assertEquals(Assert.java:165)
	at businessObject.CalculatorTest.testCtg(CalculatorTest.java:77)
	at sun.reflect.NativeMethodAccessorImpl.invoke0(Native Method)
	at sun.reflect.NativeMethodAccessorImpl.invoke(NativeMethodAccessorImpl.java:62)
	at sun.reflect.DelegatingMethodAccessorImpl.invoke(DelegatingMethodAccessorImpl.java:43)
	at java.lang.reflect.Method.invoke(Method.java:498)
	at org.testng.internal.MethodInvocationHelper.invokeMethod(MethodInvocationHelper.java:84)
	at org.testng.internal.Invoker.invokeMethod(Invoker.java:714)
	at org.testng.internal.Invoker.invokeTestMethod(Invoker.java:901)
	at org.testng.internal.Invoker.invokeTestMethods(Invoker.java:1231)
	at org.testng.internal.TestMethodWorker.invokeTestMethods(TestMethodWorker.java:127)
	at org.testng.internal.TestMethodWorker.run(TestMethodWorker.java:111)
	at org.testng.TestRunner.privateRun(TestRunner.java:767)
	at org.testng.TestRunner.run(TestRunner.java:617)
	at org.testng.SuiteRunner.runTest(SuiteRunner.java:348)
	at org.testng.SuiteRunner.runSequentially(SuiteRunner.java:343)
	at org.testng.SuiteRunner.privateRun(SuiteRunner.java:305)
	at org.testng.SuiteRunner.run(SuiteRunner.java:254)
	at org.testng.SuiteRunnerWorker.runSuite(SuiteRunnerWorker.java:52)
	at org.testng.SuiteRunnerWorker.run(SuiteRunnerWorker.java:86)
	at org.testng.TestNG.runSuitesSequentially(TestNG.java:1224)
	at org.testng.TestNG.runSuitesLocally(TestNG.java:1149)
	at org.testng.TestNG.run(TestNG.java:1057)
	at org.testng.IDEARemoteTestNG.run(IDEARemoteTestNG.java:72)
	at org.testng.RemoteTestNGStarter.main(RemoteTestNGStarter.java:124)
	at sun.reflect.NativeMethodAccessorImpl.invoke0(Native Method)
	at sun.reflect.NativeMethodAccessorImpl.invoke(NativeMethodAccessorImpl.java:62)
	at sun.reflect.DelegatingMethodAccessorImpl.invoke(DelegatingMethodAccessorImpl.java:43)
	at java.lang.reflect.Method.invoke(Method.java:498)
	at com.intellij.rt.execution.application.AppMain.main(AppMain.java:147)
]]>
    </error>
  </testcase> <!-- testCtg -->
  <testcase name="testDivOnZeroDouble" time="0.001" classname="businessObject.CalculatorTest">
    <failure type="org.testng.TestException" message="
Expected exception java.lang.ArithmeticException but got org.testng.TestException: 
Method CalculatorTest.testDivOnZeroDouble(double, double)[pri:0, instance:businessObject.CalculatorTest@47d384ee] should have thrown an exception of class java.lang.ArithmeticException">
      <![CDATA[org.testng.TestException: 
Expected exception java.lang.ArithmeticException but got org.testng.TestException: 
Method CalculatorTest.testDivOnZeroDouble(double, double)[pri:0, instance:businessObject.CalculatorTest@47d384ee] should have thrown an exception of class java.lang.ArithmeticException
	at org.testng.internal.Invoker.handleInvocationResults(Invoker.java:1497)
	at org.testng.internal.Invoker.invokeTestMethods(Invoker.java:1245)
	at org.testng.internal.TestMethodWorker.invokeTestMethods(TestMethodWorker.java:127)
	at org.testng.internal.TestMethodWorker.run(TestMethodWorker.java:111)
	at org.testng.TestRunner.privateRun(TestRunner.java:767)
	at org.testng.TestRunner.run(TestRunner.java:617)
	at org.testng.SuiteRunner.runTest(SuiteRunner.java:348)
	at org.testng.SuiteRunner.runSequentially(SuiteRunner.java:343)
	at org.testng.SuiteRunner.privateRun(SuiteRunner.java:305)
	at org.testng.SuiteRunner.run(SuiteRunner.java:254)
	at org.testng.SuiteRunnerWorker.runSuite(SuiteRunnerWorker.java:52)
	at org.testng.SuiteRunnerWorker.run(SuiteRunnerWorker.java:86)
	at org.testng.TestNG.runSuitesSequentially(TestNG.java:1224)
	at org.testng.TestNG.runSuitesLocally(TestNG.java:1149)
	at org.testng.TestNG.run(TestNG.java:1057)
	at org.testng.IDEARemoteTestNG.run(IDEARemoteTestNG.java:72)
	at org.testng.RemoteTestNGStarter.main(RemoteTestNGStarter.java:124)
	at sun.reflect.NativeMethodAccessorImpl.invoke0(Native Method)
	at sun.reflect.NativeMethodAccessorImpl.invoke(NativeMethodAccessorImpl.java:62)
	at sun.reflect.DelegatingMethodAccessorImpl.invoke(DelegatingMethodAccessorImpl.java:43)
	at java.lang.reflect.Method.invoke(Method.java:498)
	at com.intellij.rt.execution.application.AppMain.main(AppMain.java:147)
Caused by: org.testng.TestException: 
Method CalculatorTest.testDivOnZeroDouble(double, double)[pri:0, instance:businessObject.CalculatorTest@47d384ee] should have thrown an exception of class java.lang.ArithmeticException
	at org.testng.internal.Invoker.handleInvocationResults(Invoker.java:1512)
	at org.testng.internal.Invoker.invokeMethod(Invoker.java:754)
	at org.testng.internal.Invoker.invokeTestMethod(Invoker.java:901)
	at org.testng.internal.Invoker.invokeTestMethods(Invoker.java:1231)
	... 20 more
]]>
    </failure>
  </testcase> <!-- testDivOnZeroDouble -->
  <testcase name="testSubDouble" time="0.000" classname="businessObject.CalculatorTest"/>
  <testcase name="testPow" time="0.000" classname="businessObject.CalculatorTest"/>
  <testcase name="testDivOverflowDouble" time="0.000" classname="businessObject.CalculatorTest">
    <failure type="org.testng.TestException" message="
Expected exception java.lang.StackOverflowError but got java.lang.RuntimeException: java.lang.IllegalStateException: Cannot get a numeric value from a text cell">
      <![CDATA[org.testng.TestException: 
Expected exception java.lang.StackOverflowError but got java.lang.RuntimeException: java.lang.IllegalStateException: Cannot get a numeric value from a text cell
	at org.testng.internal.Invoker.handleInvocationResults(Invoker.java:1497)
	at org.testng.internal.Invoker.invokeTestMethods(Invoker.java:1185)
	at org.testng.internal.TestMethodWorker.invokeTestMethods(TestMethodWorker.java:127)
	at org.testng.internal.TestMethodWorker.run(TestMethodWorker.java:111)
	at org.testng.TestRunner.privateRun(TestRunner.java:767)
	at org.testng.TestRunner.run(TestRunner.java:617)
	at org.testng.SuiteRunner.runTest(SuiteRunner.java:348)
	at org.testng.SuiteRunner.runSequentially(SuiteRunner.java:343)
	at org.testng.SuiteRunner.privateRun(SuiteRunner.java:305)
	at org.testng.SuiteRunner.run(SuiteRunner.java:254)
	at org.testng.SuiteRunnerWorker.runSuite(SuiteRunnerWorker.java:52)
	at org.testng.SuiteRunnerWorker.run(SuiteRunnerWorker.java:86)
	at org.testng.TestNG.runSuitesSequentially(TestNG.java:1224)
	at org.testng.TestNG.runSuitesLocally(TestNG.java:1149)
	at org.testng.TestNG.run(TestNG.java:1057)
	at org.testng.IDEARemoteTestNG.run(IDEARemoteTestNG.java:72)
	at org.testng.RemoteTestNGStarter.main(RemoteTestNGStarter.java:124)
	at sun.reflect.NativeMethodAccessorImpl.invoke0(Native Method)
	at sun.reflect.NativeMethodAccessorImpl.invoke(NativeMethodAccessorImpl.java:62)
	at sun.reflect.DelegatingMethodAccessorImpl.invoke(DelegatingMethodAccessorImpl.java:43)
	at java.lang.reflect.Method.invoke(Method.java:498)
	at com.intellij.rt.execution.application.AppMain.main(AppMain.java:147)
Caused by: java.lang.RuntimeException: java.lang.IllegalStateException: Cannot get a numeric value from a text cell
	at org.testng.internal.MethodInvocationHelper.invokeDataProvider(MethodInvocationHelper.java:161)
	at org.testng.internal.Parameters.handleParameters(Parameters.java:429)
	at org.testng.internal.Invoker.handleParameters(Invoker.java:1383)
	at org.testng.internal.Invoker.createParameters(Invoker.java:1075)
	at org.testng.internal.Invoker.invokeTestMethods(Invoker.java:1180)
	... 20 more
Caused by: java.lang.IllegalStateException: Cannot get a numeric value from a text cell
	at org.apache.poi.hssf.usermodel.HSSFCell.typeMismatch(HSSFCell.java:654)
	at org.apache.poi.hssf.usermodel.HSSFCell.getNumericCellValue(HSSFCell.java:679)
	at dataProvider.ReaderXls.parse(ReaderXls.java:41)
	at dataProvider.DataProviderClass.getDataDouble(DataProviderClass.java:24)
	at sun.reflect.NativeMethodAccessorImpl.invoke0(Native Method)
	at sun.reflect.NativeMethodAccessorImpl.invoke(NativeMethodAccessorImpl.java:62)
	at sun.reflect.DelegatingMethodAccessorImpl.invoke(DelegatingMethodAccessorImpl.java:43)
	at java.lang.reflect.Method.invoke(Method.java:498)
	at org.testng.internal.MethodInvocationHelper.invokeMethod(MethodInvocationHelper.java:84)
	at org.testng.internal.MethodInvocationHelper.invokeDataProvider(MethodInvocationHelper.java:135)
	... 24 more
]]>
    </failure>
  </testcase> <!-- testDivOverflowDouble -->
  <testcase name="testIsNegative" time="0.001" classname="businessObject.CalculatorTest"/>
  <testcase name="testMultLong" time="0.000" classname="businessObject.CalculatorTest"/>
  <testcase name="testSqrt" time="0.000" classname="businessObject.CalculatorTest"/>
  <testcase name="testSin" time="0.001" classname="businessObject.CalculatorTest"/>
  <testcase name="testSubLong" time="0.000" classname="businessObject.CalculatorTest">
    <error type="java.lang.AssertionError" message="expected [56562979] but found [-56562067]">
      <![CDATA[java.lang.AssertionError: expected [56562979] but found [-56562067]
	at org.testng.Assert.fail(Assert.java:94)
	at org.testng.Assert.failNotEquals(Assert.java:494)
	at org.testng.Assert.assertEquals(Assert.java:123)
	at org.testng.Assert.assertEquals(Assert.java:265)
	at org.testng.Assert.assertEquals(Assert.java:275)
	at businessObject.CalculatorTest.testSubLong(CalculatorTest.java:31)
	at sun.reflect.NativeMethodAccessorImpl.invoke0(Native Method)
	at sun.reflect.NativeMethodAccessorImpl.invoke(NativeMethodAccessorImpl.java:62)
	at sun.reflect.DelegatingMethodAccessorImpl.invoke(DelegatingMethodAccessorImpl.java:43)
	at java.lang.reflect.Method.invoke(Method.java:498)
	at org.testng.internal.MethodInvocationHelper.invokeMethod(MethodInvocationHelper.java:84)
	at org.testng.internal.Invoker.invokeMethod(Invoker.java:714)
	at org.testng.internal.Invoker.invokeTestMethod(Invoker.java:901)
	at org.testng.internal.Invoker.invokeTestMethods(Invoker.java:1231)
	at org.testng.internal.TestMethodWorker.invokeTestMethods(TestMethodWorker.java:127)
	at org.testng.internal.TestMethodWorker.run(TestMethodWorker.java:111)
	at org.testng.TestRunner.privateRun(TestRunner.java:767)
	at org.testng.TestRunner.run(TestRunner.java:617)
	at org.testng.SuiteRunner.runTest(SuiteRunner.java:348)
	at org.testng.SuiteRunner.runSequentially(SuiteRunner.java:343)
	at org.testng.SuiteRunner.privateRun(SuiteRunner.java:305)
	at org.testng.SuiteRunner.run(SuiteRunner.java:254)
	at org.testng.SuiteRunnerWorker.runSuite(SuiteRunnerWorker.java:52)
	at org.testng.SuiteRunnerWorker.run(SuiteRunnerWorker.java:86)
	at org.testng.TestNG.runSuitesSequentially(TestNG.java:1224)
	at org.testng.TestNG.runSuitesLocally(TestNG.java:1149)
	at org.testng.TestNG.run(TestNG.java:1057)
	at org.testng.IDEARemoteTestNG.run(IDEARemoteTestNG.java:72)
	at org.testng.RemoteTestNGStarter.main(RemoteTestNGStarter.java:124)
	at sun.reflect.NativeMethodAccessorImpl.invoke0(Native Method)
	at sun.reflect.NativeMethodAccessorImpl.invoke(NativeMethodAccessorImpl.java:62)
	at sun.reflect.DelegatingMethodAccessorImpl.invoke(DelegatingMethodAccessorImpl.java:43)
	at java.lang.reflect.Method.invoke(Method.java:498)
	at com.intellij.rt.execution.application.AppMain.main(AppMain.java:147)
]]>
    </error>
  </testcase> <!-- testSubLong -->
  <testcase name="testMultDouble" time="0.001" classname="businessObject.CalculatorTest">
    <error type="java.lang.AssertionError" message="expected [25.0] but found [27.0]">
      <![CDATA[java.lang.AssertionError: expected [25.0] but found [27.0]
	at org.testng.Assert.fail(Assert.java:94)
	at org.testng.Assert.failNotEquals(Assert.java:494)
	at org.testng.Assert.assertEquals(Assert.java:207)
	at org.testng.Assert.assertEquals(Assert.java:220)
	at businessObject.CalculatorTest.testMultDouble(CalculatorTest.java:47)
	at sun.reflect.NativeMethodAccessorImpl.invoke0(Native Method)
	at sun.reflect.NativeMethodAccessorImpl.invoke(NativeMethodAccessorImpl.java:62)
	at sun.reflect.DelegatingMethodAccessorImpl.invoke(DelegatingMethodAccessorImpl.java:43)
	at java.lang.reflect.Method.invoke(Method.java:498)
	at org.testng.internal.MethodInvocationHelper.invokeMethod(MethodInvocationHelper.java:84)
	at org.testng.internal.Invoker.invokeMethod(Invoker.java:714)
	at org.testng.internal.Invoker.invokeTestMethod(Invoker.java:901)
	at org.testng.internal.Invoker.invokeTestMethods(Invoker.java:1231)
	at org.testng.internal.TestMethodWorker.invokeTestMethods(TestMethodWorker.java:127)
	at org.testng.internal.TestMethodWorker.run(TestMethodWorker.java:111)
	at org.testng.TestRunner.privateRun(TestRunner.java:767)
	at org.testng.TestRunner.run(TestRunner.java:617)
	at org.testng.SuiteRunner.runTest(SuiteRunner.java:348)
	at org.testng.SuiteRunner.runSequentially(SuiteRunner.java:343)
	at org.testng.SuiteRunner.privateRun(SuiteRunner.java:305)
	at org.testng.SuiteRunner.run(SuiteRunner.java:254)
	at org.testng.SuiteRunnerWorker.runSuite(SuiteRunnerWorker.java:52)
	at org.testng.SuiteRunnerWorker.run(SuiteRunnerWorker.java:86)
	at org.testng.TestNG.runSuitesSequentially(TestNG.java:1224)
	at org.testng.TestNG.runSuitesLocally(TestNG.java:1149)
	at org.testng.TestNG.run(TestNG.java:1057)
	at org.testng.IDEARemoteTestNG.run(IDEARemoteTestNG.java:72)
	at org.testng.RemoteTestNGStarter.main(RemoteTestNGStarter.java:124)
	at sun.reflect.NativeMethodAccessorImpl.invoke0(Native Method)
	at sun.reflect.NativeMethodAccessorImpl.invoke(NativeMethodAccessorImpl.java:62)
	at sun.reflect.DelegatingMethodAccessorImpl.invoke(DelegatingMethodAccessorImpl.java:43)
	at java.lang.reflect.Method.invoke(Method.java:498)
	at com.intellij.rt.execution.application.AppMain.main(AppMain.java:147)
]]>
    </error>
  </testcase> <!-- testMultDouble -->
  <testcase name="testPow" time="0.000" classname="businessObject.CalculatorTest"/>
  <testcase name="testDivLong" time="0.000" classname="businessObject.CalculatorTest"/>
  <testcase name="testSumDouble" time="2.005" classname="businessObject.CalculatorTest"/>
  <testcase name="testSqrt" time="0.001" classname="businessObject.CalculatorTest"/>
  <testcase name="testIsPosWithNegativeNumber" time="0.001" classname="businessObject.CalculatorTest"/>
  <testcase name="testMultLong" time="0.000" classname="businessObject.CalculatorTest"/>
  <testcase name="testSumLong" time="2.001" classname="businessObject.CalculatorTest"/>
  <testcase name="testDivOnZeroLong" time="0.001" classname="businessObject.CalculatorTest">
    <failure type="org.testng.TestException" message="
Expected exception java.lang.ArithmeticException but got org.testng.TestException: 
Expected exception java.lang.ArithmeticException but got java.lang.NumberFormatException: Attempt to divide by zero">
      <![CDATA[org.testng.TestException: 
Expected exception java.lang.ArithmeticException but got org.testng.TestException: 
Expected exception java.lang.ArithmeticException but got java.lang.NumberFormatException: Attempt to divide by zero
	at org.testng.internal.Invoker.handleInvocationResults(Invoker.java:1497)
	at org.testng.internal.Invoker.invokeTestMethods(Invoker.java:1245)
	at org.testng.internal.TestMethodWorker.invokeTestMethods(TestMethodWorker.java:127)
	at org.testng.internal.TestMethodWorker.run(TestMethodWorker.java:111)
	at org.testng.TestRunner.privateRun(TestRunner.java:767)
	at org.testng.TestRunner.run(TestRunner.java:617)
	at org.testng.SuiteRunner.runTest(SuiteRunner.java:348)
	at org.testng.SuiteRunner.runSequentially(SuiteRunner.java:343)
	at org.testng.SuiteRunner.privateRun(SuiteRunner.java:305)
	at org.testng.SuiteRunner.run(SuiteRunner.java:254)
	at org.testng.SuiteRunnerWorker.runSuite(SuiteRunnerWorker.java:52)
	at org.testng.SuiteRunnerWorker.run(SuiteRunnerWorker.java:86)
	at org.testng.TestNG.runSuitesSequentially(TestNG.java:1224)
	at org.testng.TestNG.runSuitesLocally(TestNG.java:1149)
	at org.testng.TestNG.run(TestNG.java:1057)
	at org.testng.IDEARemoteTestNG.run(IDEARemoteTestNG.java:72)
	at org.testng.RemoteTestNGStarter.main(RemoteTestNGStarter.java:124)
	at sun.reflect.NativeMethodAccessorImpl.invoke0(Native Method)
	at sun.reflect.NativeMethodAccessorImpl.invoke(NativeMethodAccessorImpl.java:62)
	at sun.reflect.DelegatingMethodAccessorImpl.invoke(DelegatingMethodAccessorImpl.java:43)
	at java.lang.reflect.Method.invoke(Method.java:498)
	at com.intellij.rt.execution.application.AppMain.main(AppMain.java:147)
Caused by: org.testng.TestException: 
Expected exception java.lang.ArithmeticException but got java.lang.NumberFormatException: Attempt to divide by zero
	at org.testng.internal.Invoker.handleInvocationResults(Invoker.java:1497)
	at org.testng.internal.Invoker.invokeMethod(Invoker.java:754)
	at org.testng.internal.Invoker.invokeTestMethod(Invoker.java:901)
	at org.testng.internal.Invoker.invokeTestMethods(Invoker.java:1231)
	... 20 more
Caused by: java.lang.NumberFormatException: Attempt to divide by zero
	at businessObject.Calculator.div(Calculator.java:36)
	at businessObject.CalculatorTest.testDivOnZeroLong(CalculatorTest.java:102)
	at sun.reflect.NativeMethodAccessorImpl.invoke0(Native Method)
	at sun.reflect.NativeMethodAccessorImpl.invoke(NativeMethodAccessorImpl.java:62)
	at sun.reflect.DelegatingMethodAccessorImpl.invoke(DelegatingMethodAccessorImpl.java:43)
	at java.lang.reflect.Method.invoke(Method.java:498)
	at org.testng.internal.MethodInvocationHelper.invokeMethod(MethodInvocationHelper.java:84)
	at org.testng.internal.Invoker.invokeMethod(Invoker.java:714)
	... 22 more
]]>
    </failure>
  </testcase> <!-- testDivOnZeroLong -->
  <testcase name="testIsPositive" time="0.000" classname="businessObject.CalculatorTest">
    <error type="java.lang.AssertionError" message="expected [true] but found [false]">
      <![CDATA[java.lang.AssertionError: expected [true] but found [false]
	at org.testng.Assert.fail(Assert.java:94)
	at org.testng.Assert.failNotEquals(Assert.java:494)
	at org.testng.Assert.assertTrue(Assert.java:42)
	at org.testng.Assert.assertTrue(Assert.java:52)
	at businessObject.CalculatorTest.testIsPositive(CalculatorTest.java:92)
	at sun.reflect.NativeMethodAccessorImpl.invoke0(Native Method)
	at sun.reflect.NativeMethodAccessorImpl.invoke(NativeMethodAccessorImpl.java:62)
	at sun.reflect.DelegatingMethodAccessorImpl.invoke(DelegatingMethodAccessorImpl.java:43)
	at java.lang.reflect.Method.invoke(Method.java:498)
	at org.testng.internal.MethodInvocationHelper.invokeMethod(MethodInvocationHelper.java:84)
	at org.testng.internal.Invoker.invokeMethod(Invoker.java:714)
	at org.testng.internal.Invoker.invokeTestMethod(Invoker.java:901)
	at org.testng.internal.Invoker.invokeTestMethods(Invoker.java:1231)
	at org.testng.internal.TestMethodWorker.invokeTestMethods(TestMethodWorker.java:127)
	at org.testng.internal.TestMethodWorker.run(TestMethodWorker.java:111)
	at org.testng.TestRunner.privateRun(TestRunner.java:767)
	at org.testng.TestRunner.run(TestRunner.java:617)
	at org.testng.SuiteRunner.runTest(SuiteRunner.java:348)
	at org.testng.SuiteRunner.runSequentially(SuiteRunner.java:343)
	at org.testng.SuiteRunner.privateRun(SuiteRunner.java:305)
	at org.testng.SuiteRunner.run(SuiteRunner.java:254)
	at org.testng.SuiteRunnerWorker.runSuite(SuiteRunnerWorker.java:52)
	at org.testng.SuiteRunnerWorker.run(SuiteRunnerWorker.java:86)
	at org.testng.TestNG.runSuitesSequentially(TestNG.java:1224)
	at org.testng.TestNG.runSuitesLocally(TestNG.java:1149)
	at org.testng.TestNG.run(TestNG.java:1057)
	at org.testng.IDEARemoteTestNG.run(IDEARemoteTestNG.java:72)
	at org.testng.RemoteTestNGStarter.main(RemoteTestNGStarter.java:124)
	at sun.reflect.NativeMethodAccessorImpl.invoke0(Native Method)
	at sun.reflect.NativeMethodAccessorImpl.invoke(NativeMethodAccessorImpl.java:62)
	at sun.reflect.DelegatingMethodAccessorImpl.invoke(DelegatingMethodAccessorImpl.java:43)
	at java.lang.reflect.Method.invoke(Method.java:498)
	at com.intellij.rt.execution.application.AppMain.main(AppMain.java:147)
]]>
    </error>
  </testcase> <!-- testIsPositive -->
  <testcase name="testPow" time="0.000" classname="businessObject.CalculatorTest"/>
  <testcase name="testSubLong" time="0.000" classname="businessObject.CalculatorTest"/>
  <testcase name="testPowNumZeroAndPowLessZero" time="0.000" classname="businessObject.CalculatorTest">
    <failure type="org.testng.TestException" message="
Expected exception java.lang.IllegalArgumentException but got org.testng.TestException: 
Method CalculatorTest.testPowNumZeroAndPowLessZero(double, double)[pri:0, instance:businessObject.CalculatorTest@47d384ee] should have thrown an exception of class java.lang.IllegalArgumentException">
      <![CDATA[org.testng.TestException: 
Expected exception java.lang.IllegalArgumentException but got org.testng.TestException: 
Method CalculatorTest.testPowNumZeroAndPowLessZero(double, double)[pri:0, instance:businessObject.CalculatorTest@47d384ee] should have thrown an exception of class java.lang.IllegalArgumentException
	at org.testng.internal.Invoker.handleInvocationResults(Invoker.java:1497)
	at org.testng.internal.Invoker.invokeTestMethods(Invoker.java:1245)
	at org.testng.internal.TestMethodWorker.invokeTestMethods(TestMethodWorker.java:127)
	at org.testng.internal.TestMethodWorker.run(TestMethodWorker.java:111)
	at org.testng.TestRunner.privateRun(TestRunner.java:767)
	at org.testng.TestRunner.run(TestRunner.java:617)
	at org.testng.SuiteRunner.runTest(SuiteRunner.java:348)
	at org.testng.SuiteRunner.runSequentially(SuiteRunner.java:343)
	at org.testng.SuiteRunner.privateRun(SuiteRunner.java:305)
	at org.testng.SuiteRunner.run(SuiteRunner.java:254)
	at org.testng.SuiteRunnerWorker.runSuite(SuiteRunnerWorker.java:52)
	at org.testng.SuiteRunnerWorker.run(SuiteRunnerWorker.java:86)
	at org.testng.TestNG.runSuitesSequentially(TestNG.java:1224)
	at org.testng.TestNG.runSuitesLocally(TestNG.java:1149)
	at org.testng.TestNG.run(TestNG.java:1057)
	at org.testng.IDEARemoteTestNG.run(IDEARemoteTestNG.java:72)
	at org.testng.RemoteTestNGStarter.main(RemoteTestNGStarter.java:124)
	at sun.reflect.NativeMethodAccessorImpl.invoke0(Native Method)
	at sun.reflect.NativeMethodAccessorImpl.invoke(NativeMethodAccessorImpl.java:62)
	at sun.reflect.DelegatingMethodAccessorImpl.invoke(DelegatingMethodAccessorImpl.java:43)
	at java.lang.reflect.Method.invoke(Method.java:498)
	at com.intellij.rt.execution.application.AppMain.main(AppMain.java:147)
Caused by: org.testng.TestException: 
Method CalculatorTest.testPowNumZeroAndPowLessZero(double, double)[pri:0, instance:businessObject.CalculatorTest@47d384ee] should have thrown an exception of class java.lang.IllegalArgumentException
	at org.testng.internal.Invoker.handleInvocationResults(Invoker.java:1512)
	at org.testng.internal.Invoker.invokeMethod(Invoker.java:754)
	at org.testng.internal.Invoker.invokeTestMethod(Invoker.java:901)
	at org.testng.internal.Invoker.invokeTestMethods(Invoker.java:1231)
	... 20 more
]]>
    </failure>
  </testcase> <!-- testPowNumZeroAndPowLessZero -->
  <testcase name="testMultDouble" time="0.000" classname="businessObject.CalculatorTest"/>
  <testcase name="testSqrt" time="0.000" classname="businessObject.CalculatorTest"/>
  <testcase name="testDivDouble" time="0.009" classname="businessObject.CalculatorTest"/>
  <testcase name="testSumLong" time="2.007" classname="businessObject.CalculatorTest"/>
  <testcase name="testMultLong" time="0.001" classname="businessObject.CalculatorTest"/>
  <testcase name="testCos" time="0.002" classname="businessObject.CalculatorTest">
    <error type="java.lang.AssertionError" message="expected [0.9480811024049992] but found [0.3180286516377352]">
      <![CDATA[java.lang.AssertionError: expected [0.9480811024049992] but found [0.3180286516377352]
	at org.testng.Assert.fail(Assert.java:94)
	at org.testng.Assert.failNotEquals(Assert.java:494)
	at org.testng.Assert.assertEquals(Assert.java:123)
	at org.testng.Assert.assertEquals(Assert.java:165)
	at businessObject.CalculatorTest.testCos(CalculatorTest.java:82)
	at sun.reflect.NativeMethodAccessorImpl.invoke0(Native Method)
	at sun.reflect.NativeMethodAccessorImpl.invoke(NativeMethodAccessorImpl.java:62)
	at sun.reflect.DelegatingMethodAccessorImpl.invoke(DelegatingMethodAccessorImpl.java:43)
	at java.lang.reflect.Method.invoke(Method.java:498)
	at org.testng.internal.MethodInvocationHelper.invokeMethod(MethodInvocationHelper.java:84)
	at org.testng.internal.Invoker.invokeMethod(Invoker.java:714)
	at org.testng.internal.Invoker.invokeTestMethod(Invoker.java:901)
	at org.testng.internal.Invoker.invokeTestMethods(Invoker.java:1231)
	at org.testng.internal.TestMethodWorker.invokeTestMethods(TestMethodWorker.java:127)
	at org.testng.internal.TestMethodWorker.run(TestMethodWorker.java:111)
	at org.testng.TestRunner.privateRun(TestRunner.java:767)
	at org.testng.TestRunner.run(TestRunner.java:617)
	at org.testng.SuiteRunner.runTest(SuiteRunner.java:348)
	at org.testng.SuiteRunner.runSequentially(SuiteRunner.java:343)
	at org.testng.SuiteRunner.privateRun(SuiteRunner.java:305)
	at org.testng.SuiteRunner.run(SuiteRunner.java:254)
	at org.testng.SuiteRunnerWorker.runSuite(SuiteRunnerWorker.java:52)
	at org.testng.SuiteRunnerWorker.run(SuiteRunnerWorker.java:86)
	at org.testng.TestNG.runSuitesSequentially(TestNG.java:1224)
	at org.testng.TestNG.runSuitesLocally(TestNG.java:1149)
	at org.testng.TestNG.run(TestNG.java:1057)
	at org.testng.IDEARemoteTestNG.run(IDEARemoteTestNG.java:72)
	at org.testng.RemoteTestNGStarter.main(RemoteTestNGStarter.java:124)
	at sun.reflect.NativeMethodAccessorImpl.invoke0(Native Method)
	at sun.reflect.NativeMethodAccessorImpl.invoke(NativeMethodAccessorImpl.java:62)
	at sun.reflect.DelegatingMethodAccessorImpl.invoke(DelegatingMethodAccessorImpl.java:43)
	at java.lang.reflect.Method.invoke(Method.java:498)
	at com.intellij.rt.execution.application.AppMain.main(AppMain.java:147)
]]>
    </error>
  </testcase> <!-- testCos -->
  <testcase name="testDivOnZeroDouble" time="0.000" classname="businessObject.CalculatorTest">
    <failure type="org.testng.TestException" message="
Expected exception java.lang.ArithmeticException but got org.testng.TestException: 
Method CalculatorTest.testDivOnZeroDouble(double, double)[pri:0, instance:businessObject.CalculatorTest@47d384ee] should have thrown an exception of class java.lang.ArithmeticException">
      <![CDATA[org.testng.TestException: 
Expected exception java.lang.ArithmeticException but got org.testng.TestException: 
Method CalculatorTest.testDivOnZeroDouble(double, double)[pri:0, instance:businessObject.CalculatorTest@47d384ee] should have thrown an exception of class java.lang.ArithmeticException
	at org.testng.internal.Invoker.handleInvocationResults(Invoker.java:1497)
	at org.testng.internal.Invoker.invokeTestMethods(Invoker.java:1245)
	at org.testng.internal.TestMethodWorker.invokeTestMethods(TestMethodWorker.java:127)
	at org.testng.internal.TestMethodWorker.run(TestMethodWorker.java:111)
	at org.testng.TestRunner.privateRun(TestRunner.java:767)
	at org.testng.TestRunner.run(TestRunner.java:617)
	at org.testng.SuiteRunner.runTest(SuiteRunner.java:348)
	at org.testng.SuiteRunner.runSequentially(SuiteRunner.java:343)
	at org.testng.SuiteRunner.privateRun(SuiteRunner.java:305)
	at org.testng.SuiteRunner.run(SuiteRunner.java:254)
	at org.testng.SuiteRunnerWorker.runSuite(SuiteRunnerWorker.java:52)
	at org.testng.SuiteRunnerWorker.run(SuiteRunnerWorker.java:86)
	at org.testng.TestNG.runSuitesSequentially(TestNG.java:1224)
	at org.testng.TestNG.runSuitesLocally(TestNG.java:1149)
	at org.testng.TestNG.run(TestNG.java:1057)
	at org.testng.IDEARemoteTestNG.run(IDEARemoteTestNG.java:72)
	at org.testng.RemoteTestNGStarter.main(RemoteTestNGStarter.java:124)
	at sun.reflect.NativeMethodAccessorImpl.invoke0(Native Method)
	at sun.reflect.NativeMethodAccessorImpl.invoke(NativeMethodAccessorImpl.java:62)
	at sun.reflect.DelegatingMethodAccessorImpl.invoke(DelegatingMethodAccessorImpl.java:43)
	at java.lang.reflect.Method.invoke(Method.java:498)
	at com.intellij.rt.execution.application.AppMain.main(AppMain.java:147)
Caused by: org.testng.TestException: 
Method CalculatorTest.testDivOnZeroDouble(double, double)[pri:0, instance:businessObject.CalculatorTest@47d384ee] should have thrown an exception of class java.lang.ArithmeticException
	at org.testng.internal.Invoker.handleInvocationResults(Invoker.java:1512)
	at org.testng.internal.Invoker.invokeMethod(Invoker.java:754)
	at org.testng.internal.Invoker.invokeTestMethod(Invoker.java:901)
	at org.testng.internal.Invoker.invokeTestMethods(Invoker.java:1231)
	... 20 more
]]>
    </failure>
  </testcase> <!-- testDivOnZeroDouble -->
  <testcase name="testMultOverflowLong" time="0.000" classname="businessObject.CalculatorTest">
    <failure type="org.testng.TestException" message="
Expected exception java.lang.StackOverflowError but got org.testng.TestException: 
Method CalculatorTest.testMultOverflowLong(long, long)[pri:0, instance:businessObject.CalculatorTest@47d384ee] should have thrown an exception of class java.lang.StackOverflowError">
      <![CDATA[org.testng.TestException: 
Expected exception java.lang.StackOverflowError but got org.testng.TestException: 
Method CalculatorTest.testMultOverflowLong(long, long)[pri:0, instance:businessObject.CalculatorTest@47d384ee] should have thrown an exception of class java.lang.StackOverflowError
	at org.testng.internal.Invoker.handleInvocationResults(Invoker.java:1497)
	at org.testng.internal.Invoker.invokeTestMethods(Invoker.java:1245)
	at org.testng.internal.TestMethodWorker.invokeTestMethods(TestMethodWorker.java:127)
	at org.testng.internal.TestMethodWorker.run(TestMethodWorker.java:111)
	at org.testng.TestRunner.privateRun(TestRunner.java:767)
	at org.testng.TestRunner.run(TestRunner.java:617)
	at org.testng.SuiteRunner.runTest(SuiteRunner.java:348)
	at org.testng.SuiteRunner.runSequentially(SuiteRunner.java:343)
	at org.testng.SuiteRunner.privateRun(SuiteRunner.java:305)
	at org.testng.SuiteRunner.run(SuiteRunner.java:254)
	at org.testng.SuiteRunnerWorker.runSuite(SuiteRunnerWorker.java:52)
	at org.testng.SuiteRunnerWorker.run(SuiteRunnerWorker.java:86)
	at org.testng.TestNG.runSuitesSequentially(TestNG.java:1224)
	at org.testng.TestNG.runSuitesLocally(TestNG.java:1149)
	at org.testng.TestNG.run(TestNG.java:1057)
	at org.testng.IDEARemoteTestNG.run(IDEARemoteTestNG.java:72)
	at org.testng.RemoteTestNGStarter.main(RemoteTestNGStarter.java:124)
	at sun.reflect.NativeMethodAccessorImpl.invoke0(Native Method)
	at sun.reflect.NativeMethodAccessorImpl.invoke(NativeMethodAccessorImpl.java:62)
	at sun.reflect.DelegatingMethodAccessorImpl.invoke(DelegatingMethodAccessorImpl.java:43)
	at java.lang.reflect.Method.invoke(Method.java:498)
	at com.intellij.rt.execution.application.AppMain.main(AppMain.java:147)
Caused by: org.testng.TestException: 
Method CalculatorTest.testMultOverflowLong(long, long)[pri:0, instance:businessObject.CalculatorTest@47d384ee] should have thrown an exception of class java.lang.StackOverflowError
	at org.testng.internal.Invoker.handleInvocationResults(Invoker.java:1512)
	at org.testng.internal.Invoker.invokeMethod(Invoker.java:754)
	at org.testng.internal.Invoker.invokeTestMethod(Invoker.java:901)
	at org.testng.internal.Invoker.invokeTestMethods(Invoker.java:1231)
	... 20 more
]]>
    </failure>
  </testcase> <!-- testMultOverflowLong -->
  <testcase name="testCtgFromZero" time="0.001" classname="businessObject.CalculatorTest">
    <failure type="org.testng.TestException" message="
Expected exception java.lang.IllegalArgumentException but got org.testng.TestException: 
Method CalculatorTest.testCtgFromZero(double)[pri:0, instance:businessObject.CalculatorTest@47d384ee] should have thrown an exception of class java.lang.IllegalArgumentException">
      <![CDATA[org.testng.TestException: 
Expected exception java.lang.IllegalArgumentException but got org.testng.TestException: 
Method CalculatorTest.testCtgFromZero(double)[pri:0, instance:businessObject.CalculatorTest@47d384ee] should have thrown an exception of class java.lang.IllegalArgumentException
	at org.testng.internal.Invoker.handleInvocationResults(Invoker.java:1497)
	at org.testng.internal.Invoker.invokeTestMethods(Invoker.java:1245)
	at org.testng.internal.TestMethodWorker.invokeTestMethods(TestMethodWorker.java:127)
	at org.testng.internal.TestMethodWorker.run(TestMethodWorker.java:111)
	at org.testng.TestRunner.privateRun(TestRunner.java:767)
	at org.testng.TestRunner.run(TestRunner.java:617)
	at org.testng.SuiteRunner.runTest(SuiteRunner.java:348)
	at org.testng.SuiteRunner.runSequentially(SuiteRunner.java:343)
	at org.testng.SuiteRunner.privateRun(SuiteRunner.java:305)
	at org.testng.SuiteRunner.run(SuiteRunner.java:254)
	at org.testng.SuiteRunnerWorker.runSuite(SuiteRunnerWorker.java:52)
	at org.testng.SuiteRunnerWorker.run(SuiteRunnerWorker.java:86)
	at org.testng.TestNG.runSuitesSequentially(TestNG.java:1224)
	at org.testng.TestNG.runSuitesLocally(TestNG.java:1149)
	at org.testng.TestNG.run(TestNG.java:1057)
	at org.testng.IDEARemoteTestNG.run(IDEARemoteTestNG.java:72)
	at org.testng.RemoteTestNGStarter.main(RemoteTestNGStarter.java:124)
	at sun.reflect.NativeMethodAccessorImpl.invoke0(Native Method)
	at sun.reflect.NativeMethodAccessorImpl.invoke(NativeMethodAccessorImpl.java:62)
	at sun.reflect.DelegatingMethodAccessorImpl.invoke(DelegatingMethodAccessorImpl.java:43)
	at java.lang.reflect.Method.invoke(Method.java:498)
	at com.intellij.rt.execution.application.AppMain.main(AppMain.java:147)
Caused by: org.testng.TestException: 
Method CalculatorTest.testCtgFromZero(double)[pri:0, instance:businessObject.CalculatorTest@47d384ee] should have thrown an exception of class java.lang.IllegalArgumentException
	at org.testng.internal.Invoker.handleInvocationResults(Invoker.java:1512)
	at org.testng.internal.Invoker.invokeMethod(Invoker.java:754)
	at org.testng.internal.Invoker.invokeTestMethod(Invoker.java:901)
	at org.testng.internal.Invoker.invokeTestMethods(Invoker.java:1231)
	... 20 more
]]>
    </failure>
  </testcase> <!-- testCtgFromZero -->
  <testcase name="testCtg" time="0.001" classname="businessObject.CalculatorTest">
    <error type="java.lang.AssertionError" message="expected [2.981118517223813] but found [-1.0]">
      <![CDATA[java.lang.AssertionError: expected [2.981118517223813] but found [-1.0]
	at org.testng.Assert.fail(Assert.java:94)
	at org.testng.Assert.failNotEquals(Assert.java:494)
	at org.testng.Assert.assertEquals(Assert.java:123)
	at org.testng.Assert.assertEquals(Assert.java:165)
	at businessObject.CalculatorTest.testCtg(CalculatorTest.java:77)
	at sun.reflect.NativeMethodAccessorImpl.invoke0(Native Method)
	at sun.reflect.NativeMethodAccessorImpl.invoke(NativeMethodAccessorImpl.java:62)
	at sun.reflect.DelegatingMethodAccessorImpl.invoke(DelegatingMethodAccessorImpl.java:43)
	at java.lang.reflect.Method.invoke(Method.java:498)
	at org.testng.internal.MethodInvocationHelper.invokeMethod(MethodInvocationHelper.java:84)
	at org.testng.internal.Invoker.invokeMethod(Invoker.java:714)
	at org.testng.internal.Invoker.invokeTestMethod(Invoker.java:901)
	at org.testng.internal.Invoker.invokeTestMethods(Invoker.java:1231)
	at org.testng.internal.TestMethodWorker.invokeTestMethods(TestMethodWorker.java:127)
	at org.testng.internal.TestMethodWorker.run(TestMethodWorker.java:111)
	at org.testng.TestRunner.privateRun(TestRunner.java:767)
	at org.testng.TestRunner.run(TestRunner.java:617)
	at org.testng.SuiteRunner.runTest(SuiteRunner.java:348)
	at org.testng.SuiteRunner.runSequentially(SuiteRunner.java:343)
	at org.testng.SuiteRunner.privateRun(SuiteRunner.java:305)
	at org.testng.SuiteRunner.run(SuiteRunner.java:254)
	at org.testng.SuiteRunnerWorker.runSuite(SuiteRunnerWorker.java:52)
	at org.testng.SuiteRunnerWorker.run(SuiteRunnerWorker.java:86)
	at org.testng.TestNG.runSuitesSequentially(TestNG.java:1224)
	at org.testng.TestNG.runSuitesLocally(TestNG.java:1149)
	at org.testng.TestNG.run(TestNG.java:1057)
	at org.testng.IDEARemoteTestNG.run(IDEARemoteTestNG.java:72)
	at org.testng.RemoteTestNGStarter.main(RemoteTestNGStarter.java:124)
	at sun.reflect.NativeMethodAccessorImpl.invoke0(Native Method)
	at sun.reflect.NativeMethodAccessorImpl.invoke(NativeMethodAccessorImpl.java:62)
	at sun.reflect.DelegatingMethodAccessorImpl.invoke(DelegatingMethodAccessorImpl.java:43)
	at java.lang.reflect.Method.invoke(Method.java:498)
	at com.intellij.rt.execution.application.AppMain.main(AppMain.java:147)
]]>
    </error>
  </testcase> <!-- testCtg -->
  <testcase name="testMultOverflowLong" time="0.000" classname="businessObject.CalculatorTest">
    <failure type="org.testng.TestException" message="
Expected exception java.lang.StackOverflowError but got org.testng.TestException: 
Method CalculatorTest.testMultOverflowLong(long, long)[pri:0, instance:businessObject.CalculatorTest@47d384ee] should have thrown an exception of class java.lang.StackOverflowError">
      <![CDATA[org.testng.TestException: 
Expected exception java.lang.StackOverflowError but got org.testng.TestException: 
Method CalculatorTest.testMultOverflowLong(long, long)[pri:0, instance:businessObject.CalculatorTest@47d384ee] should have thrown an exception of class java.lang.StackOverflowError
	at org.testng.internal.Invoker.handleInvocationResults(Invoker.java:1497)
	at org.testng.internal.Invoker.invokeTestMethods(Invoker.java:1245)
	at org.testng.internal.TestMethodWorker.invokeTestMethods(TestMethodWorker.java:127)
	at org.testng.internal.TestMethodWorker.run(TestMethodWorker.java:111)
	at org.testng.TestRunner.privateRun(TestRunner.java:767)
	at org.testng.TestRunner.run(TestRunner.java:617)
	at org.testng.SuiteRunner.runTest(SuiteRunner.java:348)
	at org.testng.SuiteRunner.runSequentially(SuiteRunner.java:343)
	at org.testng.SuiteRunner.privateRun(SuiteRunner.java:305)
	at org.testng.SuiteRunner.run(SuiteRunner.java:254)
	at org.testng.SuiteRunnerWorker.runSuite(SuiteRunnerWorker.java:52)
	at org.testng.SuiteRunnerWorker.run(SuiteRunnerWorker.java:86)
	at org.testng.TestNG.runSuitesSequentially(TestNG.java:1224)
	at org.testng.TestNG.runSuitesLocally(TestNG.java:1149)
	at org.testng.TestNG.run(TestNG.java:1057)
	at org.testng.IDEARemoteTestNG.run(IDEARemoteTestNG.java:72)
	at org.testng.RemoteTestNGStarter.main(RemoteTestNGStarter.java:124)
	at sun.reflect.NativeMethodAccessorImpl.invoke0(Native Method)
	at sun.reflect.NativeMethodAccessorImpl.invoke(NativeMethodAccessorImpl.java:62)
	at sun.reflect.DelegatingMethodAccessorImpl.invoke(DelegatingMethodAccessorImpl.java:43)
	at java.lang.reflect.Method.invoke(Method.java:498)
	at com.intellij.rt.execution.application.AppMain.main(AppMain.java:147)
Caused by: org.testng.TestException: 
Method CalculatorTest.testMultOverflowLong(long, long)[pri:0, instance:businessObject.CalculatorTest@47d384ee] should have thrown an exception of class java.lang.StackOverflowError
	at org.testng.internal.Invoker.handleInvocationResults(Invoker.java:1512)
	at org.testng.internal.Invoker.invokeMethod(Invoker.java:754)
	at org.testng.internal.Invoker.invokeTestMethod(Invoker.java:901)
	at org.testng.internal.Invoker.invokeTestMethods(Invoker.java:1231)
	... 20 more
]]>
    </failure>
  </testcase> <!-- testMultOverflowLong -->
  <testcase name="testPow" time="0.001" classname="businessObject.CalculatorTest"/>
  <testcase name="testMultLong" time="0.000" classname="businessObject.CalculatorTest"/>
  <testcase name="testSumDouble" time="2.003" classname="businessObject.CalculatorTest"/>
  <testcase name="testSubLong" time="0.000" classname="businessObject.CalculatorTest"/>
  <testcase name="testSubDouble" time="0.000" classname="businessObject.CalculatorTest"/>
  <testcase name="testDivOnZeroDouble" time="0.006" classname="businessObject.CalculatorTest">
    <failure type="org.testng.TestException" message="
Expected exception java.lang.ArithmeticException but got org.testng.TestException: 
Method CalculatorTest.testDivOnZeroDouble(double, double)[pri:0, instance:businessObject.CalculatorTest@47d384ee] should have thrown an exception of class java.lang.ArithmeticException">
      <![CDATA[org.testng.TestException: 
Expected exception java.lang.ArithmeticException but got org.testng.TestException: 
Method CalculatorTest.testDivOnZeroDouble(double, double)[pri:0, instance:businessObject.CalculatorTest@47d384ee] should have thrown an exception of class java.lang.ArithmeticException
	at org.testng.internal.Invoker.handleInvocationResults(Invoker.java:1497)
	at org.testng.internal.Invoker.invokeTestMethods(Invoker.java:1245)
	at org.testng.internal.TestMethodWorker.invokeTestMethods(TestMethodWorker.java:127)
	at org.testng.internal.TestMethodWorker.run(TestMethodWorker.java:111)
	at org.testng.TestRunner.privateRun(TestRunner.java:767)
	at org.testng.TestRunner.run(TestRunner.java:617)
	at org.testng.SuiteRunner.runTest(SuiteRunner.java:348)
	at org.testng.SuiteRunner.runSequentially(SuiteRunner.java:343)
	at org.testng.SuiteRunner.privateRun(SuiteRunner.java:305)
	at org.testng.SuiteRunner.run(SuiteRunner.java:254)
	at org.testng.SuiteRunnerWorker.runSuite(SuiteRunnerWorker.java:52)
	at org.testng.SuiteRunnerWorker.run(SuiteRunnerWorker.java:86)
	at org.testng.TestNG.runSuitesSequentially(TestNG.java:1224)
	at org.testng.TestNG.runSuitesLocally(TestNG.java:1149)
	at org.testng.TestNG.run(TestNG.java:1057)
	at org.testng.IDEARemoteTestNG.run(IDEARemoteTestNG.java:72)
	at org.testng.RemoteTestNGStarter.main(RemoteTestNGStarter.java:124)
	at sun.reflect.NativeMethodAccessorImpl.invoke0(Native Method)
	at sun.reflect.NativeMethodAccessorImpl.invoke(NativeMethodAccessorImpl.java:62)
	at sun.reflect.DelegatingMethodAccessorImpl.invoke(DelegatingMethodAccessorImpl.java:43)
	at java.lang.reflect.Method.invoke(Method.java:498)
	at com.intellij.rt.execution.application.AppMain.main(AppMain.java:147)
Caused by: org.testng.TestException: 
Method CalculatorTest.testDivOnZeroDouble(double, double)[pri:0, instance:businessObject.CalculatorTest@47d384ee] should have thrown an exception of class java.lang.ArithmeticException
	at org.testng.internal.Invoker.handleInvocationResults(Invoker.java:1512)
	at org.testng.internal.Invoker.invokeMethod(Invoker.java:754)
	at org.testng.internal.Invoker.invokeTestMethod(Invoker.java:901)
	at org.testng.internal.Invoker.invokeTestMethods(Invoker.java:1231)
	... 20 more
]]>
    </failure>
  </testcase> <!-- testDivOnZeroDouble -->
</testsuite> <!-- businessObject.CalculatorTest -->
