<?xml version="1.0" encoding="UTF-8"?>
<!-- Generated by org.testng.reporters.JUnitXMLReporter -->
<testsuite hostname="EPUAKYIW0675" name="Test for different type of numbers" tests="86" failures="29" timestamp="1 Nov 2016 17:34:15 GMT" time="7.436" errors="0">
  <testcase name="testCos" time="0.0" classname="businessObject.CalculatorTest">
    <failure type="java.lang.AssertionError" message="expected [0.9480811024049992] but found [0.3180286516377352]">
      <![CDATA[java.lang.AssertionError: expected [0.9480811024049992] but found [0.3180286516377352]
	at org.testng.Assert.fail(Assert.java:94)
	at org.testng.Assert.failNotEquals(Assert.java:494)
	at org.testng.Assert.assertEquals(Assert.java:123)
	at org.testng.Assert.assertEquals(Assert.java:165)
	at businessObject.CalculatorTest.testCos(CalculatorTest.java:81)
	at sun.reflect.NativeMethodAccessorImpl.invoke0(Native Method)
	at sun.reflect.NativeMethodAccessorImpl.invoke(NativeMethodAccessorImpl.java:62)
	at sun.reflect.DelegatingMethodAccessorImpl.invoke(DelegatingMethodAccessorImpl.java:43)
	at java.lang.reflect.Method.invoke(Method.java:498)
	at org.testng.internal.MethodInvocationHelper.invokeMethod(MethodInvocationHelper.java:84)
	at org.testng.internal.Invoker.invokeMethod(Invoker.java:714)
	at org.testng.internal.Invoker.invokeTestMethod(Invoker.java:901)
	at org.testng.internal.Invoker.invokeTestMethods(Invoker.java:1231)
	at org.testng.internal.TestMethodWorker.invokeTestMethods(TestMethodWorker.java:127)
	at org.testng.internal.TestMethodWorker.run(TestMethodWorker.java:111)
	at java.util.concurrent.ThreadPoolExecutor.runWorker(ThreadPoolExecutor.java:1142)
	at java.util.concurrent.ThreadPoolExecutor$Worker.run(ThreadPoolExecutor.java:617)
	at java.lang.Thread.run(Thread.java:745)
]]>
    </failure>
  </testcase> <!-- testCos -->
  <testcase name="testCtg" time="0.0" classname="businessObject.CalculatorTest">
    <failure type="java.lang.AssertionError" message="expected [2.981118517223813] but found [-1.0]">
      <![CDATA[java.lang.AssertionError: expected [2.981118517223813] but found [-1.0]
	at org.testng.Assert.fail(Assert.java:94)
	at org.testng.Assert.failNotEquals(Assert.java:494)
	at org.testng.Assert.assertEquals(Assert.java:123)
	at org.testng.Assert.assertEquals(Assert.java:165)
	at businessObject.CalculatorTest.testCtg(CalculatorTest.java:76)
	at sun.reflect.NativeMethodAccessorImpl.invoke0(Native Method)
	at sun.reflect.NativeMethodAccessorImpl.invoke(NativeMethodAccessorImpl.java:62)
	at sun.reflect.DelegatingMethodAccessorImpl.invoke(DelegatingMethodAccessorImpl.java:43)
	at java.lang.reflect.Method.invoke(Method.java:498)
	at org.testng.internal.MethodInvocationHelper.invokeMethod(MethodInvocationHelper.java:84)
	at org.testng.internal.Invoker.invokeMethod(Invoker.java:714)
	at org.testng.internal.Invoker.invokeTestMethod(Invoker.java:901)
	at org.testng.internal.Invoker.invokeTestMethods(Invoker.java:1231)
	at org.testng.internal.TestMethodWorker.invokeTestMethods(TestMethodWorker.java:127)
	at org.testng.internal.TestMethodWorker.run(TestMethodWorker.java:111)
	at java.util.concurrent.ThreadPoolExecutor.runWorker(ThreadPoolExecutor.java:1142)
	at java.util.concurrent.ThreadPoolExecutor$Worker.run(ThreadPoolExecutor.java:617)
	at java.lang.Thread.run(Thread.java:745)
]]>
    </failure>
  </testcase> <!-- testCtg -->
  <testcase name="testCtg" time="0.0" classname="businessObject.CalculatorTest">
    <failure type="java.lang.AssertionError" message="expected [-0.1405626691891154] but found [1.0]">
      <![CDATA[java.lang.AssertionError: expected [-0.1405626691891154] but found [1.0]
	at org.testng.Assert.fail(Assert.java:94)
	at org.testng.Assert.failNotEquals(Assert.java:494)
	at org.testng.Assert.assertEquals(Assert.java:123)
	at org.testng.Assert.assertEquals(Assert.java:165)
	at businessObject.CalculatorTest.testCtg(CalculatorTest.java:76)
	at sun.reflect.NativeMethodAccessorImpl.invoke0(Native Method)
	at sun.reflect.NativeMethodAccessorImpl.invoke(NativeMethodAccessorImpl.java:62)
	at sun.reflect.DelegatingMethodAccessorImpl.invoke(DelegatingMethodAccessorImpl.java:43)
	at java.lang.reflect.Method.invoke(Method.java:498)
	at org.testng.internal.MethodInvocationHelper.invokeMethod(MethodInvocationHelper.java:84)
	at org.testng.internal.Invoker.invokeMethod(Invoker.java:714)
	at org.testng.internal.Invoker.invokeTestMethod(Invoker.java:901)
	at org.testng.internal.Invoker.invokeTestMethods(Invoker.java:1231)
	at org.testng.internal.TestMethodWorker.invokeTestMethods(TestMethodWorker.java:127)
	at org.testng.internal.TestMethodWorker.run(TestMethodWorker.java:111)
	at java.util.concurrent.ThreadPoolExecutor.runWorker(ThreadPoolExecutor.java:1142)
	at java.util.concurrent.ThreadPoolExecutor$Worker.run(ThreadPoolExecutor.java:617)
	at java.lang.Thread.run(Thread.java:745)
]]>
    </failure>
  </testcase> <!-- testCtg -->
  <testcase name="testCos" time="0.0" classname="businessObject.CalculatorTest">
    <failure type="java.lang.AssertionError" message="expected [1.0] but found [0.0]">
      <![CDATA[java.lang.AssertionError: expected [1.0] but found [0.0]
	at org.testng.Assert.fail(Assert.java:94)
	at org.testng.Assert.failNotEquals(Assert.java:494)
	at org.testng.Assert.assertEquals(Assert.java:123)
	at org.testng.Assert.assertEquals(Assert.java:165)
	at businessObject.CalculatorTest.testCos(CalculatorTest.java:81)
	at sun.reflect.NativeMethodAccessorImpl.invoke0(Native Method)
	at sun.reflect.NativeMethodAccessorImpl.invoke(NativeMethodAccessorImpl.java:62)
	at sun.reflect.DelegatingMethodAccessorImpl.invoke(DelegatingMethodAccessorImpl.java:43)
	at java.lang.reflect.Method.invoke(Method.java:498)
	at org.testng.internal.MethodInvocationHelper.invokeMethod(MethodInvocationHelper.java:84)
	at org.testng.internal.Invoker.invokeMethod(Invoker.java:714)
	at org.testng.internal.Invoker.invokeTestMethod(Invoker.java:901)
	at org.testng.internal.Invoker.invokeTestMethods(Invoker.java:1231)
	at org.testng.internal.TestMethodWorker.invokeTestMethods(TestMethodWorker.java:127)
	at org.testng.internal.TestMethodWorker.run(TestMethodWorker.java:111)
	at java.util.concurrent.ThreadPoolExecutor.runWorker(ThreadPoolExecutor.java:1142)
	at java.util.concurrent.ThreadPoolExecutor$Worker.run(ThreadPoolExecutor.java:617)
	at java.lang.Thread.run(Thread.java:745)
]]>
    </failure>
  </testcase> <!-- testCos -->
  <testcase name="testCos" time="0.001" classname="businessObject.CalculatorTest">
    <failure type="java.lang.AssertionError" message="expected [-0.13919430405964572] but found [0.9902650886087779]">
      <![CDATA[java.lang.AssertionError: expected [-0.13919430405964572] but found [0.9902650886087779]
	at org.testng.Assert.fail(Assert.java:94)
	at org.testng.Assert.failNotEquals(Assert.java:494)
	at org.testng.Assert.assertEquals(Assert.java:123)
	at org.testng.Assert.assertEquals(Assert.java:165)
	at businessObject.CalculatorTest.testCos(CalculatorTest.java:81)
	at sun.reflect.NativeMethodAccessorImpl.invoke0(Native Method)
	at sun.reflect.NativeMethodAccessorImpl.invoke(NativeMethodAccessorImpl.java:62)
	at sun.reflect.DelegatingMethodAccessorImpl.invoke(DelegatingMethodAccessorImpl.java:43)
	at java.lang.reflect.Method.invoke(Method.java:498)
	at org.testng.internal.MethodInvocationHelper.invokeMethod(MethodInvocationHelper.java:84)
	at org.testng.internal.Invoker.invokeMethod(Invoker.java:714)
	at org.testng.internal.Invoker.invokeTestMethod(Invoker.java:901)
	at org.testng.internal.Invoker.invokeTestMethods(Invoker.java:1231)
	at org.testng.internal.TestMethodWorker.invokeTestMethods(TestMethodWorker.java:127)
	at org.testng.internal.TestMethodWorker.run(TestMethodWorker.java:111)
	at java.util.concurrent.ThreadPoolExecutor.runWorker(ThreadPoolExecutor.java:1142)
	at java.util.concurrent.ThreadPoolExecutor$Worker.run(ThreadPoolExecutor.java:617)
	at java.lang.Thread.run(Thread.java:745)
]]>
    </failure>
  </testcase> <!-- testCos -->
  <testcase name="testCos" time="0.0" classname="businessObject.CalculatorTest">
    <failure type="java.lang.AssertionError" message="expected [0.5403023058681398] but found [0.8414709848078965]">
      <![CDATA[java.lang.AssertionError: expected [0.5403023058681398] but found [0.8414709848078965]
	at org.testng.Assert.fail(Assert.java:94)
	at org.testng.Assert.failNotEquals(Assert.java:494)
	at org.testng.Assert.assertEquals(Assert.java:123)
	at org.testng.Assert.assertEquals(Assert.java:165)
	at businessObject.CalculatorTest.testCos(CalculatorTest.java:81)
	at sun.reflect.NativeMethodAccessorImpl.invoke0(Native Method)
	at sun.reflect.NativeMethodAccessorImpl.invoke(NativeMethodAccessorImpl.java:62)
	at sun.reflect.DelegatingMethodAccessorImpl.invoke(DelegatingMethodAccessorImpl.java:43)
	at java.lang.reflect.Method.invoke(Method.java:498)
	at org.testng.internal.MethodInvocationHelper.invokeMethod(MethodInvocationHelper.java:84)
	at org.testng.internal.Invoker.invokeMethod(Invoker.java:714)
	at org.testng.internal.Invoker.invokeTestMethod(Invoker.java:901)
	at org.testng.internal.Invoker.invokeTestMethods(Invoker.java:1231)
	at org.testng.internal.TestMethodWorker.invokeTestMethods(TestMethodWorker.java:127)
	at org.testng.internal.TestMethodWorker.run(TestMethodWorker.java:111)
	at java.util.concurrent.ThreadPoolExecutor.runWorker(ThreadPoolExecutor.java:1142)
	at java.util.concurrent.ThreadPoolExecutor$Worker.run(ThreadPoolExecutor.java:617)
	at java.lang.Thread.run(Thread.java:745)
]]>
    </failure>
  </testcase> <!-- testCos -->
  <testcase name="testCtgFromZero" time="0.001" classname="businessObject.CalculatorTest">
    <failure type="org.testng.TestException" message="
Expected exception java.lang.IllegalArgumentException but got org.testng.TestException: 
Method CalculatorTest.testCtgFromZero(double)[pri:0, instance:businessObject.CalculatorTest@22a71081] should have thrown an exception of class java.lang.IllegalArgumentException">
      <![CDATA[org.testng.TestException: 
Expected exception java.lang.IllegalArgumentException but got org.testng.TestException: 
Method CalculatorTest.testCtgFromZero(double)[pri:0, instance:businessObject.CalculatorTest@22a71081] should have thrown an exception of class java.lang.IllegalArgumentException
	at org.testng.internal.Invoker.handleInvocationResults(Invoker.java:1497)
	at org.testng.internal.Invoker.invokeTestMethods(Invoker.java:1245)
	at org.testng.internal.TestMethodWorker.invokeTestMethods(TestMethodWorker.java:127)
	at org.testng.internal.TestMethodWorker.run(TestMethodWorker.java:111)
	at java.util.concurrent.ThreadPoolExecutor.runWorker(ThreadPoolExecutor.java:1142)
	at java.util.concurrent.ThreadPoolExecutor$Worker.run(ThreadPoolExecutor.java:617)
	at java.lang.Thread.run(Thread.java:745)
Caused by: org.testng.TestException: 
Method CalculatorTest.testCtgFromZero(double)[pri:0, instance:businessObject.CalculatorTest@22a71081] should have thrown an exception of class java.lang.IllegalArgumentException
	at org.testng.internal.Invoker.handleInvocationResults(Invoker.java:1512)
	at org.testng.internal.Invoker.invokeMethod(Invoker.java:754)
	at org.testng.internal.Invoker.invokeTestMethod(Invoker.java:901)
	at org.testng.internal.Invoker.invokeTestMethods(Invoker.java:1231)
	... 5 more
]]>
    </failure>
  </testcase> <!-- testCtgFromZero -->
  <testcase name="testDivLong" time="0.0" classname="businessObject.CalculatorTest"/>
  <testcase name="testDivLong" time="0.0" classname="businessObject.CalculatorTest"/>
  <testcase name="testDivLong" time="0.002" classname="businessObject.CalculatorTest"/>
  <testcase name="testDivLong" time="0.0" classname="businessObject.CalculatorTest"/>
  <testcase name="testDivDouble" time="0.0" classname="businessObject.CalculatorTest"/>
  <testcase name="testDivDouble" time="0.002" classname="businessObject.CalculatorTest"/>
  <testcase name="testDivDouble" time="0.0" classname="businessObject.CalculatorTest"/>
  <testcase name="testDivDouble" time="0.0" classname="businessObject.CalculatorTest"/>
  <testcase name="testDivDouble" time="0.0" classname="businessObject.CalculatorTest"/>
  <testcase name="testDivOnZeroLong" time="0.0" classname="businessObject.CalculatorTest">
    <failure type="org.testng.TestException" message="
Expected exception java.lang.ArithmeticException but got org.testng.TestException: 
Expected exception java.lang.ArithmeticException but got java.lang.NumberFormatException: Attempt to divide by zero">
      <![CDATA[org.testng.TestException: 
Expected exception java.lang.ArithmeticException but got org.testng.TestException: 
Expected exception java.lang.ArithmeticException but got java.lang.NumberFormatException: Attempt to divide by zero
	at org.testng.internal.Invoker.handleInvocationResults(Invoker.java:1497)
	at org.testng.internal.Invoker.invokeTestMethods(Invoker.java:1245)
	at org.testng.internal.TestMethodWorker.invokeTestMethods(TestMethodWorker.java:127)
	at org.testng.internal.TestMethodWorker.run(TestMethodWorker.java:111)
	at java.util.concurrent.ThreadPoolExecutor.runWorker(ThreadPoolExecutor.java:1142)
	at java.util.concurrent.ThreadPoolExecutor$Worker.run(ThreadPoolExecutor.java:617)
	at java.lang.Thread.run(Thread.java:745)
Caused by: org.testng.TestException: 
Expected exception java.lang.ArithmeticException but got java.lang.NumberFormatException: Attempt to divide by zero
	at org.testng.internal.Invoker.handleInvocationResults(Invoker.java:1497)
	at org.testng.internal.Invoker.invokeMethod(Invoker.java:754)
	at org.testng.internal.Invoker.invokeTestMethod(Invoker.java:901)
	at org.testng.internal.Invoker.invokeTestMethods(Invoker.java:1231)
	... 5 more
Caused by: java.lang.NumberFormatException: Attempt to divide by zero
	at businessObject.Calculator.div(Calculator.java:36)
	at businessObject.CalculatorTest.testDivOnZeroLong(CalculatorTest.java:101)
	at sun.reflect.NativeMethodAccessorImpl.invoke0(Native Method)
	at sun.reflect.NativeMethodAccessorImpl.invoke(NativeMethodAccessorImpl.java:62)
	at sun.reflect.DelegatingMethodAccessorImpl.invoke(DelegatingMethodAccessorImpl.java:43)
	at java.lang.reflect.Method.invoke(Method.java:498)
	at org.testng.internal.MethodInvocationHelper.invokeMethod(MethodInvocationHelper.java:84)
	at org.testng.internal.Invoker.invokeMethod(Invoker.java:714)
	... 7 more
]]>
    </failure>
  </testcase> <!-- testDivOnZeroLong -->
  <testcase name="testDivOnZeroDouble" time="0.0" classname="businessObject.CalculatorTest">
    <failure type="org.testng.TestException" message="
Expected exception java.lang.ArithmeticException but got org.testng.TestException: 
Method CalculatorTest.testDivOnZeroDouble(double, double)[pri:0, instance:businessObject.CalculatorTest@22a71081] should have thrown an exception of class java.lang.ArithmeticException">
      <![CDATA[org.testng.TestException: 
Expected exception java.lang.ArithmeticException but got org.testng.TestException: 
Method CalculatorTest.testDivOnZeroDouble(double, double)[pri:0, instance:businessObject.CalculatorTest@22a71081] should have thrown an exception of class java.lang.ArithmeticException
	at org.testng.internal.Invoker.handleInvocationResults(Invoker.java:1497)
	at org.testng.internal.Invoker.invokeTestMethods(Invoker.java:1245)
	at org.testng.internal.TestMethodWorker.invokeTestMethods(TestMethodWorker.java:127)
	at org.testng.internal.TestMethodWorker.run(TestMethodWorker.java:111)
	at java.util.concurrent.ThreadPoolExecutor.runWorker(ThreadPoolExecutor.java:1142)
	at java.util.concurrent.ThreadPoolExecutor$Worker.run(ThreadPoolExecutor.java:617)
	at java.lang.Thread.run(Thread.java:745)
Caused by: org.testng.TestException: 
Method CalculatorTest.testDivOnZeroDouble(double, double)[pri:0, instance:businessObject.CalculatorTest@22a71081] should have thrown an exception of class java.lang.ArithmeticException
	at org.testng.internal.Invoker.handleInvocationResults(Invoker.java:1512)
	at org.testng.internal.Invoker.invokeMethod(Invoker.java:754)
	at org.testng.internal.Invoker.invokeTestMethod(Invoker.java:901)
	at org.testng.internal.Invoker.invokeTestMethods(Invoker.java:1231)
	... 5 more
]]>
    </failure>
  </testcase> <!-- testDivOnZeroDouble -->
  <testcase name="testDivOnZeroLong" time="0.0" classname="businessObject.CalculatorTest">
    <failure type="org.testng.TestException" message="
Expected exception java.lang.ArithmeticException but got org.testng.TestException: 
Expected exception java.lang.ArithmeticException but got java.lang.NumberFormatException: Attempt to divide by zero">
      <![CDATA[org.testng.TestException: 
Expected exception java.lang.ArithmeticException but got org.testng.TestException: 
Expected exception java.lang.ArithmeticException but got java.lang.NumberFormatException: Attempt to divide by zero
	at org.testng.internal.Invoker.handleInvocationResults(Invoker.java:1497)
	at org.testng.internal.Invoker.invokeTestMethods(Invoker.java:1245)
	at org.testng.internal.TestMethodWorker.invokeTestMethods(TestMethodWorker.java:127)
	at org.testng.internal.TestMethodWorker.run(TestMethodWorker.java:111)
	at java.util.concurrent.ThreadPoolExecutor.runWorker(ThreadPoolExecutor.java:1142)
	at java.util.concurrent.ThreadPoolExecutor$Worker.run(ThreadPoolExecutor.java:617)
	at java.lang.Thread.run(Thread.java:745)
Caused by: org.testng.TestException: 
Expected exception java.lang.ArithmeticException but got java.lang.NumberFormatException: Attempt to divide by zero
	at org.testng.internal.Invoker.handleInvocationResults(Invoker.java:1497)
	at org.testng.internal.Invoker.invokeMethod(Invoker.java:754)
	at org.testng.internal.Invoker.invokeTestMethod(Invoker.java:901)
	at org.testng.internal.Invoker.invokeTestMethods(Invoker.java:1231)
	... 5 more
Caused by: java.lang.NumberFormatException: Attempt to divide by zero
	at businessObject.Calculator.div(Calculator.java:36)
	at businessObject.CalculatorTest.testDivOnZeroLong(CalculatorTest.java:101)
	at sun.reflect.NativeMethodAccessorImpl.invoke0(Native Method)
	at sun.reflect.NativeMethodAccessorImpl.invoke(NativeMethodAccessorImpl.java:62)
	at sun.reflect.DelegatingMethodAccessorImpl.invoke(DelegatingMethodAccessorImpl.java:43)
	at java.lang.reflect.Method.invoke(Method.java:498)
	at org.testng.internal.MethodInvocationHelper.invokeMethod(MethodInvocationHelper.java:84)
	at org.testng.internal.Invoker.invokeMethod(Invoker.java:714)
	... 7 more
]]>
    </failure>
  </testcase> <!-- testDivOnZeroLong -->
  <testcase name="testDivOnZeroDouble" time="0.0" classname="businessObject.CalculatorTest">
    <failure type="org.testng.TestException" message="
Expected exception java.lang.ArithmeticException but got org.testng.TestException: 
Method CalculatorTest.testDivOnZeroDouble(double, double)[pri:0, instance:businessObject.CalculatorTest@22a71081] should have thrown an exception of class java.lang.ArithmeticException">
      <![CDATA[org.testng.TestException: 
Expected exception java.lang.ArithmeticException but got org.testng.TestException: 
Method CalculatorTest.testDivOnZeroDouble(double, double)[pri:0, instance:businessObject.CalculatorTest@22a71081] should have thrown an exception of class java.lang.ArithmeticException
	at org.testng.internal.Invoker.handleInvocationResults(Invoker.java:1497)
	at org.testng.internal.Invoker.invokeTestMethods(Invoker.java:1245)
	at org.testng.internal.TestMethodWorker.invokeTestMethods(TestMethodWorker.java:127)
	at org.testng.internal.TestMethodWorker.run(TestMethodWorker.java:111)
	at java.util.concurrent.ThreadPoolExecutor.runWorker(ThreadPoolExecutor.java:1142)
	at java.util.concurrent.ThreadPoolExecutor$Worker.run(ThreadPoolExecutor.java:617)
	at java.lang.Thread.run(Thread.java:745)
Caused by: org.testng.TestException: 
Method CalculatorTest.testDivOnZeroDouble(double, double)[pri:0, instance:businessObject.CalculatorTest@22a71081] should have thrown an exception of class java.lang.ArithmeticException
	at org.testng.internal.Invoker.handleInvocationResults(Invoker.java:1512)
	at org.testng.internal.Invoker.invokeMethod(Invoker.java:754)
	at org.testng.internal.Invoker.invokeTestMethod(Invoker.java:901)
	at org.testng.internal.Invoker.invokeTestMethods(Invoker.java:1231)
	... 5 more
]]>
    </failure>
  </testcase> <!-- testDivOnZeroDouble -->
  <testcase name="testDivOnZeroDouble" time="0.0" classname="businessObject.CalculatorTest">
    <failure type="org.testng.TestException" message="
Expected exception java.lang.ArithmeticException but got org.testng.TestException: 
Method CalculatorTest.testDivOnZeroDouble(double, double)[pri:0, instance:businessObject.CalculatorTest@22a71081] should have thrown an exception of class java.lang.ArithmeticException">
      <![CDATA[org.testng.TestException: 
Expected exception java.lang.ArithmeticException but got org.testng.TestException: 
Method CalculatorTest.testDivOnZeroDouble(double, double)[pri:0, instance:businessObject.CalculatorTest@22a71081] should have thrown an exception of class java.lang.ArithmeticException
	at org.testng.internal.Invoker.handleInvocationResults(Invoker.java:1497)
	at org.testng.internal.Invoker.invokeTestMethods(Invoker.java:1245)
	at org.testng.internal.TestMethodWorker.invokeTestMethods(TestMethodWorker.java:127)
	at org.testng.internal.TestMethodWorker.run(TestMethodWorker.java:111)
	at java.util.concurrent.ThreadPoolExecutor.runWorker(ThreadPoolExecutor.java:1142)
	at java.util.concurrent.ThreadPoolExecutor$Worker.run(ThreadPoolExecutor.java:617)
	at java.lang.Thread.run(Thread.java:745)
Caused by: org.testng.TestException: 
Method CalculatorTest.testDivOnZeroDouble(double, double)[pri:0, instance:businessObject.CalculatorTest@22a71081] should have thrown an exception of class java.lang.ArithmeticException
	at org.testng.internal.Invoker.handleInvocationResults(Invoker.java:1512)
	at org.testng.internal.Invoker.invokeMethod(Invoker.java:754)
	at org.testng.internal.Invoker.invokeTestMethod(Invoker.java:901)
	at org.testng.internal.Invoker.invokeTestMethods(Invoker.java:1231)
	... 5 more
]]>
    </failure>
  </testcase> <!-- testDivOnZeroDouble -->
  <testcase name="testDivOnZeroLong" time="0.016" classname="businessObject.CalculatorTest">
    <failure type="org.testng.TestException" message="
Expected exception java.lang.ArithmeticException but got org.testng.TestException: 
Expected exception java.lang.ArithmeticException but got java.lang.NumberFormatException: Attempt to divide by zero">
      <![CDATA[org.testng.TestException: 
Expected exception java.lang.ArithmeticException but got org.testng.TestException: 
Expected exception java.lang.ArithmeticException but got java.lang.NumberFormatException: Attempt to divide by zero
	at org.testng.internal.Invoker.handleInvocationResults(Invoker.java:1497)
	at org.testng.internal.Invoker.invokeTestMethods(Invoker.java:1245)
	at org.testng.internal.TestMethodWorker.invokeTestMethods(TestMethodWorker.java:127)
	at org.testng.internal.TestMethodWorker.run(TestMethodWorker.java:111)
	at java.util.concurrent.ThreadPoolExecutor.runWorker(ThreadPoolExecutor.java:1142)
	at java.util.concurrent.ThreadPoolExecutor$Worker.run(ThreadPoolExecutor.java:617)
	at java.lang.Thread.run(Thread.java:745)
Caused by: org.testng.TestException: 
Expected exception java.lang.ArithmeticException but got java.lang.NumberFormatException: Attempt to divide by zero
	at org.testng.internal.Invoker.handleInvocationResults(Invoker.java:1497)
	at org.testng.internal.Invoker.invokeMethod(Invoker.java:754)
	at org.testng.internal.Invoker.invokeTestMethod(Invoker.java:901)
	at org.testng.internal.Invoker.invokeTestMethods(Invoker.java:1231)
	... 5 more
Caused by: java.lang.NumberFormatException: Attempt to divide by zero
	at businessObject.Calculator.div(Calculator.java:36)
	at businessObject.CalculatorTest.testDivOnZeroLong(CalculatorTest.java:101)
	at sun.reflect.NativeMethodAccessorImpl.invoke0(Native Method)
	at sun.reflect.NativeMethodAccessorImpl.invoke(NativeMethodAccessorImpl.java:62)
	at sun.reflect.DelegatingMethodAccessorImpl.invoke(DelegatingMethodAccessorImpl.java:43)
	at java.lang.reflect.Method.invoke(Method.java:498)
	at org.testng.internal.MethodInvocationHelper.invokeMethod(MethodInvocationHelper.java:84)
	at org.testng.internal.Invoker.invokeMethod(Invoker.java:714)
	... 7 more
]]>
    </failure>
  </testcase> <!-- testDivOnZeroLong -->
  <testcase name="testIsNegWithPositiveNumber" time="0.0" classname="businessObject.CalculatorTest">
    <failure type="java.lang.IllegalArgumentException" message="argument type mismatch">
      <![CDATA[java.lang.IllegalArgumentException: argument type mismatch
	at sun.reflect.NativeMethodAccessorImpl.invoke0(Native Method)
	at sun.reflect.NativeMethodAccessorImpl.invoke(NativeMethodAccessorImpl.java:62)
	at sun.reflect.DelegatingMethodAccessorImpl.invoke(DelegatingMethodAccessorImpl.java:43)
	at java.lang.reflect.Method.invoke(Method.java:498)
	at org.testng.internal.MethodInvocationHelper.invokeMethod(MethodInvocationHelper.java:84)
	at org.testng.internal.Invoker.invokeMethod(Invoker.java:714)
	at org.testng.internal.Invoker.invokeTestMethod(Invoker.java:901)
	at org.testng.internal.Invoker.invokeTestMethods(Invoker.java:1231)
	at org.testng.internal.TestMethodWorker.invokeTestMethods(TestMethodWorker.java:127)
	at org.testng.internal.TestMethodWorker.run(TestMethodWorker.java:111)
	at java.util.concurrent.ThreadPoolExecutor.runWorker(ThreadPoolExecutor.java:1142)
	at java.util.concurrent.ThreadPoolExecutor$Worker.run(ThreadPoolExecutor.java:617)
	at java.lang.Thread.run(Thread.java:745)
]]>
    </failure>
  </testcase> <!-- testIsNegWithPositiveNumber -->
  <testcase name="testIsPosWithNegativeNumber" time="0.0" classname="businessObject.CalculatorTest"/>
  <testcase name="testIsPositive" time="0.0" classname="businessObject.CalculatorTest"/>
  <testcase name="testIsPositive" time="0.0" classname="businessObject.CalculatorTest">
    <failure type="java.lang.AssertionError" message="expected [true] but found [false]">
      <![CDATA[java.lang.AssertionError: expected [true] but found [false]
	at org.testng.Assert.fail(Assert.java:94)
	at org.testng.Assert.failNotEquals(Assert.java:494)
	at org.testng.Assert.assertTrue(Assert.java:42)
	at org.testng.Assert.assertTrue(Assert.java:52)
	at businessObject.CalculatorTest.testIsPositive(CalculatorTest.java:91)
	at sun.reflect.NativeMethodAccessorImpl.invoke0(Native Method)
	at sun.reflect.NativeMethodAccessorImpl.invoke(NativeMethodAccessorImpl.java:62)
	at sun.reflect.DelegatingMethodAccessorImpl.invoke(DelegatingMethodAccessorImpl.java:43)
	at java.lang.reflect.Method.invoke(Method.java:498)
	at org.testng.internal.MethodInvocationHelper.invokeMethod(MethodInvocationHelper.java:84)
	at org.testng.internal.Invoker.invokeMethod(Invoker.java:714)
	at org.testng.internal.Invoker.invokeTestMethod(Invoker.java:901)
	at org.testng.internal.Invoker.invokeTestMethods(Invoker.java:1231)
	at org.testng.internal.TestMethodWorker.invokeTestMethods(TestMethodWorker.java:127)
	at org.testng.internal.TestMethodWorker.run(TestMethodWorker.java:111)
	at java.util.concurrent.ThreadPoolExecutor.runWorker(ThreadPoolExecutor.java:1142)
	at java.util.concurrent.ThreadPoolExecutor$Worker.run(ThreadPoolExecutor.java:617)
	at java.lang.Thread.run(Thread.java:745)
]]>
    </failure>
  </testcase> <!-- testIsPositive -->
  <testcase name="testMultDouble" time="0.0" classname="businessObject.CalculatorTest"/>
  <testcase name="testIsNegative" time="0.0" classname="businessObject.CalculatorTest"/>
  <testcase name="testMultDouble" time="0.0" classname="businessObject.CalculatorTest"/>
  <testcase name="testMultDouble" time="0.0" classname="businessObject.CalculatorTest"/>
  <testcase name="testMultDouble" time="0.0" classname="businessObject.CalculatorTest">
    <failure type="java.lang.AssertionError" message="expected [2740734.0] but found [2858587.0]">
      <![CDATA[java.lang.AssertionError: expected [2740734.0] but found [2858587.0]
	at org.testng.Assert.fail(Assert.java:94)
	at org.testng.Assert.failNotEquals(Assert.java:494)
	at org.testng.Assert.assertEquals(Assert.java:207)
	at org.testng.Assert.assertEquals(Assert.java:220)
	at businessObject.CalculatorTest.testMultDouble(CalculatorTest.java:46)
	at sun.reflect.NativeMethodAccessorImpl.invoke0(Native Method)
	at sun.reflect.NativeMethodAccessorImpl.invoke(NativeMethodAccessorImpl.java:62)
	at sun.reflect.DelegatingMethodAccessorImpl.invoke(DelegatingMethodAccessorImpl.java:43)
	at java.lang.reflect.Method.invoke(Method.java:498)
	at org.testng.internal.MethodInvocationHelper.invokeMethod(MethodInvocationHelper.java:84)
	at org.testng.internal.Invoker.invokeMethod(Invoker.java:714)
	at org.testng.internal.Invoker.invokeTestMethod(Invoker.java:901)
	at org.testng.internal.Invoker.invokeTestMethods(Invoker.java:1231)
	at org.testng.internal.TestMethodWorker.invokeTestMethods(TestMethodWorker.java:127)
	at org.testng.internal.TestMethodWorker.run(TestMethodWorker.java:111)
	at java.util.concurrent.ThreadPoolExecutor.runWorker(ThreadPoolExecutor.java:1142)
	at java.util.concurrent.ThreadPoolExecutor$Worker.run(ThreadPoolExecutor.java:617)
	at java.lang.Thread.run(Thread.java:745)
]]>
    </failure>
  </testcase> <!-- testMultDouble -->
  <testcase name="testMultLong" time="0.016" classname="businessObject.CalculatorTest"/>
  <testcase name="testMultDouble" time="0.0" classname="businessObject.CalculatorTest">
    <failure type="java.lang.AssertionError" message="expected [25.0] but found [27.0]">
      <![CDATA[java.lang.AssertionError: expected [25.0] but found [27.0]
	at org.testng.Assert.fail(Assert.java:94)
	at org.testng.Assert.failNotEquals(Assert.java:494)
	at org.testng.Assert.assertEquals(Assert.java:207)
	at org.testng.Assert.assertEquals(Assert.java:220)
	at businessObject.CalculatorTest.testMultDouble(CalculatorTest.java:46)
	at sun.reflect.NativeMethodAccessorImpl.invoke0(Native Method)
	at sun.reflect.NativeMethodAccessorImpl.invoke(NativeMethodAccessorImpl.java:62)
	at sun.reflect.DelegatingMethodAccessorImpl.invoke(DelegatingMethodAccessorImpl.java:43)
	at java.lang.reflect.Method.invoke(Method.java:498)
	at org.testng.internal.MethodInvocationHelper.invokeMethod(MethodInvocationHelper.java:84)
	at org.testng.internal.Invoker.invokeMethod(Invoker.java:714)
	at org.testng.internal.Invoker.invokeTestMethod(Invoker.java:901)
	at org.testng.internal.Invoker.invokeTestMethods(Invoker.java:1231)
	at org.testng.internal.TestMethodWorker.invokeTestMethods(TestMethodWorker.java:127)
	at org.testng.internal.TestMethodWorker.run(TestMethodWorker.java:111)
	at java.util.concurrent.ThreadPoolExecutor.runWorker(ThreadPoolExecutor.java:1142)
	at java.util.concurrent.ThreadPoolExecutor$Worker.run(ThreadPoolExecutor.java:617)
	at java.lang.Thread.run(Thread.java:745)
]]>
    </failure>
  </testcase> <!-- testMultDouble -->
  <testcase name="testMultDouble" time="0.0" classname="businessObject.CalculatorTest">
    <failure type="java.lang.AssertionError" message="expected [-150.0] but found [-159.0]">
      <![CDATA[java.lang.AssertionError: expected [-150.0] but found [-159.0]
	at org.testng.Assert.fail(Assert.java:94)
	at org.testng.Assert.failNotEquals(Assert.java:494)
	at org.testng.Assert.assertEquals(Assert.java:207)
	at org.testng.Assert.assertEquals(Assert.java:220)
	at businessObject.CalculatorTest.testMultDouble(CalculatorTest.java:46)
	at sun.reflect.NativeMethodAccessorImpl.invoke0(Native Method)
	at sun.reflect.NativeMethodAccessorImpl.invoke(NativeMethodAccessorImpl.java:62)
	at sun.reflect.DelegatingMethodAccessorImpl.invoke(DelegatingMethodAccessorImpl.java:43)
	at java.lang.reflect.Method.invoke(Method.java:498)
	at org.testng.internal.MethodInvocationHelper.invokeMethod(MethodInvocationHelper.java:84)
	at org.testng.internal.Invoker.invokeMethod(Invoker.java:714)
	at org.testng.internal.Invoker.invokeTestMethod(Invoker.java:901)
	at org.testng.internal.Invoker.invokeTestMethods(Invoker.java:1231)
	at org.testng.internal.TestMethodWorker.invokeTestMethods(TestMethodWorker.java:127)
	at org.testng.internal.TestMethodWorker.run(TestMethodWorker.java:111)
	at java.util.concurrent.ThreadPoolExecutor.runWorker(ThreadPoolExecutor.java:1142)
	at java.util.concurrent.ThreadPoolExecutor$Worker.run(ThreadPoolExecutor.java:617)
	at java.lang.Thread.run(Thread.java:745)
]]>
    </failure>
  </testcase> <!-- testMultDouble -->
  <testcase name="testMultLong" time="0.0" classname="businessObject.CalculatorTest"/>
  <testcase name="testMultDouble" time="0.015" classname="businessObject.CalculatorTest">
    <failure type="java.lang.AssertionError" message="expected [-160.0] but found [-167.0]">
      <![CDATA[java.lang.AssertionError: expected [-160.0] but found [-167.0]
	at org.testng.Assert.fail(Assert.java:94)
	at org.testng.Assert.failNotEquals(Assert.java:494)
	at org.testng.Assert.assertEquals(Assert.java:207)
	at org.testng.Assert.assertEquals(Assert.java:220)
	at businessObject.CalculatorTest.testMultDouble(CalculatorTest.java:46)
	at sun.reflect.NativeMethodAccessorImpl.invoke0(Native Method)
	at sun.reflect.NativeMethodAccessorImpl.invoke(NativeMethodAccessorImpl.java:62)
	at sun.reflect.DelegatingMethodAccessorImpl.invoke(DelegatingMethodAccessorImpl.java:43)
	at java.lang.reflect.Method.invoke(Method.java:498)
	at org.testng.internal.MethodInvocationHelper.invokeMethod(MethodInvocationHelper.java:84)
	at org.testng.internal.Invoker.invokeMethod(Invoker.java:714)
	at org.testng.internal.Invoker.invokeTestMethod(Invoker.java:901)
	at org.testng.internal.Invoker.invokeTestMethods(Invoker.java:1231)
	at org.testng.internal.TestMethodWorker.invokeTestMethods(TestMethodWorker.java:127)
	at org.testng.internal.TestMethodWorker.run(TestMethodWorker.java:111)
	at java.util.concurrent.ThreadPoolExecutor.runWorker(ThreadPoolExecutor.java:1142)
	at java.util.concurrent.ThreadPoolExecutor$Worker.run(ThreadPoolExecutor.java:617)
	at java.lang.Thread.run(Thread.java:745)
]]>
    </failure>
  </testcase> <!-- testMultDouble -->
  <testcase name="testMultLong" time="0.0" classname="businessObject.CalculatorTest"/>
  <testcase name="testMultLong" time="0.0" classname="businessObject.CalculatorTest"/>
  <testcase name="testMultLong" time="0.0" classname="businessObject.CalculatorTest"/>
  <testcase name="testMultLong" time="0.0" classname="businessObject.CalculatorTest"/>
  <testcase name="testMultLong" time="0.0" classname="businessObject.CalculatorTest"/>
  <testcase name="testPow" time="0.0" classname="businessObject.CalculatorTest"/>
  <testcase name="testPow" time="0.017" classname="businessObject.CalculatorTest"/>
  <testcase name="testPowNumZeroAndPowLessZero" time="0.0" classname="businessObject.CalculatorTest">
    <failure type="org.testng.TestException" message="
Expected exception java.lang.IllegalArgumentException but got org.testng.TestException: 
Method CalculatorTest.testPowNumZeroAndPowLessZero(double, double)[pri:0, instance:businessObject.CalculatorTest@22a71081] should have thrown an exception of class java.lang.IllegalArgumentException">
      <![CDATA[org.testng.TestException: 
Expected exception java.lang.IllegalArgumentException but got org.testng.TestException: 
Method CalculatorTest.testPowNumZeroAndPowLessZero(double, double)[pri:0, instance:businessObject.CalculatorTest@22a71081] should have thrown an exception of class java.lang.IllegalArgumentException
	at org.testng.internal.Invoker.handleInvocationResults(Invoker.java:1497)
	at org.testng.internal.Invoker.invokeTestMethods(Invoker.java:1245)
	at org.testng.internal.TestMethodWorker.invokeTestMethods(TestMethodWorker.java:127)
	at org.testng.internal.TestMethodWorker.run(TestMethodWorker.java:111)
	at java.util.concurrent.ThreadPoolExecutor.runWorker(ThreadPoolExecutor.java:1142)
	at java.util.concurrent.ThreadPoolExecutor$Worker.run(ThreadPoolExecutor.java:617)
	at java.lang.Thread.run(Thread.java:745)
Caused by: org.testng.TestException: 
Method CalculatorTest.testPowNumZeroAndPowLessZero(double, double)[pri:0, instance:businessObject.CalculatorTest@22a71081] should have thrown an exception of class java.lang.IllegalArgumentException
	at org.testng.internal.Invoker.handleInvocationResults(Invoker.java:1512)
	at org.testng.internal.Invoker.invokeMethod(Invoker.java:754)
	at org.testng.internal.Invoker.invokeTestMethod(Invoker.java:901)
	at org.testng.internal.Invoker.invokeTestMethods(Invoker.java:1231)
	... 5 more
]]>
    </failure>
  </testcase> <!-- testPowNumZeroAndPowLessZero -->
  <testcase name="testPow" time="0.001" classname="businessObject.CalculatorTest"/>
  <testcase name="testPow" time="0.0" classname="businessObject.CalculatorTest"/>
  <testcase name="testPow" time="0.0" classname="businessObject.CalculatorTest"/>
  <testcase name="testSqrt" time="0.0" classname="businessObject.CalculatorTest"/>
  <testcase name="testSin" time="0.0" classname="businessObject.CalculatorTest"/>
  <testcase name="testSqrt" time="0.0" classname="businessObject.CalculatorTest"/>
  <testcase name="testSin" time="0.0" classname="businessObject.CalculatorTest"/>
  <testcase name="testSqrt" time="0.0" classname="businessObject.CalculatorTest"/>
  <testcase name="testSin" time="0.0" classname="businessObject.CalculatorTest"/>
  <testcase name="testSin" time="0.0" classname="businessObject.CalculatorTest"/>
  <testcase name="testSqrtWhenNumLessZero" time="0.0" classname="businessObject.CalculatorTest">
    <failure type="org.testng.TestException" message="
Expected exception java.lang.IllegalArgumentException but got org.testng.TestException: 
Method CalculatorTest.testSqrtWhenNumLessZero(double)[pri:0, instance:businessObject.CalculatorTest@22a71081] should have thrown an exception of class java.lang.IllegalArgumentException">
      <![CDATA[org.testng.TestException: 
Expected exception java.lang.IllegalArgumentException but got org.testng.TestException: 
Method CalculatorTest.testSqrtWhenNumLessZero(double)[pri:0, instance:businessObject.CalculatorTest@22a71081] should have thrown an exception of class java.lang.IllegalArgumentException
	at org.testng.internal.Invoker.handleInvocationResults(Invoker.java:1497)
	at org.testng.internal.Invoker.invokeTestMethods(Invoker.java:1245)
	at org.testng.internal.TestMethodWorker.invokeTestMethods(TestMethodWorker.java:127)
	at org.testng.internal.TestMethodWorker.run(TestMethodWorker.java:111)
	at java.util.concurrent.ThreadPoolExecutor.runWorker(ThreadPoolExecutor.java:1142)
	at java.util.concurrent.ThreadPoolExecutor$Worker.run(ThreadPoolExecutor.java:617)
	at java.lang.Thread.run(Thread.java:745)
Caused by: org.testng.TestException: 
Method CalculatorTest.testSqrtWhenNumLessZero(double)[pri:0, instance:businessObject.CalculatorTest@22a71081] should have thrown an exception of class java.lang.IllegalArgumentException
	at org.testng.internal.Invoker.handleInvocationResults(Invoker.java:1512)
	at org.testng.internal.Invoker.invokeMethod(Invoker.java:754)
	at org.testng.internal.Invoker.invokeTestMethod(Invoker.java:901)
	at org.testng.internal.Invoker.invokeTestMethods(Invoker.java:1231)
	... 5 more
]]>
    </failure>
  </testcase> <!-- testSqrtWhenNumLessZero -->
  <testcase name="testSubLong" time="0.0" classname="businessObject.CalculatorTest"/>
  <testcase name="testSubLong" time="0.0" classname="businessObject.CalculatorTest"/>
  <testcase name="testSubLong" time="0.0" classname="businessObject.CalculatorTest"/>
  <testcase name="testSubLong" time="0.0" classname="businessObject.CalculatorTest">
    <failure type="java.lang.AssertionError" message="expected [9223372036854775807] but found [9223372036854775709]">
      <![CDATA[java.lang.AssertionError: expected [9223372036854775807] but found [9223372036854775709]
	at org.testng.Assert.fail(Assert.java:94)
	at org.testng.Assert.failNotEquals(Assert.java:494)
	at org.testng.Assert.assertEquals(Assert.java:123)
	at org.testng.Assert.assertEquals(Assert.java:265)
	at org.testng.Assert.assertEquals(Assert.java:275)
	at businessObject.CalculatorTest.testSubLong(CalculatorTest.java:30)
	at sun.reflect.NativeMethodAccessorImpl.invoke0(Native Method)
	at sun.reflect.NativeMethodAccessorImpl.invoke(NativeMethodAccessorImpl.java:62)
	at sun.reflect.DelegatingMethodAccessorImpl.invoke(DelegatingMethodAccessorImpl.java:43)
	at java.lang.reflect.Method.invoke(Method.java:498)
	at org.testng.internal.MethodInvocationHelper.invokeMethod(MethodInvocationHelper.java:84)
	at org.testng.internal.Invoker.invokeMethod(Invoker.java:714)
	at org.testng.internal.Invoker.invokeTestMethod(Invoker.java:901)
	at org.testng.internal.Invoker.invokeTestMethods(Invoker.java:1231)
	at org.testng.internal.TestMethodWorker.invokeTestMethods(TestMethodWorker.java:127)
	at org.testng.internal.TestMethodWorker.run(TestMethodWorker.java:111)
	at java.util.concurrent.ThreadPoolExecutor.runWorker(ThreadPoolExecutor.java:1142)
	at java.util.concurrent.ThreadPoolExecutor$Worker.run(ThreadPoolExecutor.java:617)
	at java.lang.Thread.run(Thread.java:745)
]]>
    </failure>
  </testcase> <!-- testSubLong -->
  <testcase name="testSubDouble" time="0.015" classname="businessObject.CalculatorTest"/>
  <testcase name="testSubLong" time="0.0" classname="businessObject.CalculatorTest">
    <failure type="java.lang.AssertionError" message="expected [56562979] but found [-56562067]">
      <![CDATA[java.lang.AssertionError: expected [56562979] but found [-56562067]
	at org.testng.Assert.fail(Assert.java:94)
	at org.testng.Assert.failNotEquals(Assert.java:494)
	at org.testng.Assert.assertEquals(Assert.java:123)
	at org.testng.Assert.assertEquals(Assert.java:265)
	at org.testng.Assert.assertEquals(Assert.java:275)
	at businessObject.CalculatorTest.testSubLong(CalculatorTest.java:30)
	at sun.reflect.NativeMethodAccessorImpl.invoke0(Native Method)
	at sun.reflect.NativeMethodAccessorImpl.invoke(NativeMethodAccessorImpl.java:62)
	at sun.reflect.DelegatingMethodAccessorImpl.invoke(DelegatingMethodAccessorImpl.java:43)
	at java.lang.reflect.Method.invoke(Method.java:498)
	at org.testng.internal.MethodInvocationHelper.invokeMethod(MethodInvocationHelper.java:84)
	at org.testng.internal.Invoker.invokeMethod(Invoker.java:714)
	at org.testng.internal.Invoker.invokeTestMethod(Invoker.java:901)
	at org.testng.internal.Invoker.invokeTestMethods(Invoker.java:1231)
	at org.testng.internal.TestMethodWorker.invokeTestMethods(TestMethodWorker.java:127)
	at org.testng.internal.TestMethodWorker.run(TestMethodWorker.java:111)
	at java.util.concurrent.ThreadPoolExecutor.runWorker(ThreadPoolExecutor.java:1142)
	at java.util.concurrent.ThreadPoolExecutor$Worker.run(ThreadPoolExecutor.java:617)
	at java.lang.Thread.run(Thread.java:745)
]]>
    </failure>
  </testcase> <!-- testSubLong -->
  <testcase name="testSubLong" time="0.0" classname="businessObject.CalculatorTest">
    <failure type="java.lang.AssertionError" message="expected [0] but found [824682468246]">
      <![CDATA[java.lang.AssertionError: expected [0] but found [824682468246]
	at org.testng.Assert.fail(Assert.java:94)
	at org.testng.Assert.failNotEquals(Assert.java:494)
	at org.testng.Assert.assertEquals(Assert.java:123)
	at org.testng.Assert.assertEquals(Assert.java:265)
	at org.testng.Assert.assertEquals(Assert.java:275)
	at businessObject.CalculatorTest.testSubLong(CalculatorTest.java:30)
	at sun.reflect.NativeMethodAccessorImpl.invoke0(Native Method)
	at sun.reflect.NativeMethodAccessorImpl.invoke(NativeMethodAccessorImpl.java:62)
	at sun.reflect.DelegatingMethodAccessorImpl.invoke(DelegatingMethodAccessorImpl.java:43)
	at java.lang.reflect.Method.invoke(Method.java:498)
	at org.testng.internal.MethodInvocationHelper.invokeMethod(MethodInvocationHelper.java:84)
	at org.testng.internal.Invoker.invokeMethod(Invoker.java:714)
	at org.testng.internal.Invoker.invokeTestMethod(Invoker.java:901)
	at org.testng.internal.Invoker.invokeTestMethods(Invoker.java:1231)
	at org.testng.internal.TestMethodWorker.invokeTestMethods(TestMethodWorker.java:127)
	at org.testng.internal.TestMethodWorker.run(TestMethodWorker.java:111)
	at java.util.concurrent.ThreadPoolExecutor.runWorker(ThreadPoolExecutor.java:1142)
	at java.util.concurrent.ThreadPoolExecutor$Worker.run(ThreadPoolExecutor.java:617)
	at java.lang.Thread.run(Thread.java:745)
]]>
    </failure>
  </testcase> <!-- testSubLong -->
  <testcase name="testSubLong" time="0.0" classname="businessObject.CalculatorTest">
    <failure type="java.lang.AssertionError" message="expected [555555555555550] but found [-555555555555560]">
      <![CDATA[java.lang.AssertionError: expected [555555555555550] but found [-555555555555560]
	at org.testng.Assert.fail(Assert.java:94)
	at org.testng.Assert.failNotEquals(Assert.java:494)
	at org.testng.Assert.assertEquals(Assert.java:123)
	at org.testng.Assert.assertEquals(Assert.java:265)
	at org.testng.Assert.assertEquals(Assert.java:275)
	at businessObject.CalculatorTest.testSubLong(CalculatorTest.java:30)
	at sun.reflect.NativeMethodAccessorImpl.invoke0(Native Method)
	at sun.reflect.NativeMethodAccessorImpl.invoke(NativeMethodAccessorImpl.java:62)
	at sun.reflect.DelegatingMethodAccessorImpl.invoke(DelegatingMethodAccessorImpl.java:43)
	at java.lang.reflect.Method.invoke(Method.java:498)
	at org.testng.internal.MethodInvocationHelper.invokeMethod(MethodInvocationHelper.java:84)
	at org.testng.internal.Invoker.invokeMethod(Invoker.java:714)
	at org.testng.internal.Invoker.invokeTestMethod(Invoker.java:901)
	at org.testng.internal.Invoker.invokeTestMethods(Invoker.java:1231)
	at org.testng.internal.TestMethodWorker.invokeTestMethods(TestMethodWorker.java:127)
	at org.testng.internal.TestMethodWorker.run(TestMethodWorker.java:111)
	at java.util.concurrent.ThreadPoolExecutor.runWorker(ThreadPoolExecutor.java:1142)
	at java.util.concurrent.ThreadPoolExecutor$Worker.run(ThreadPoolExecutor.java:617)
	at java.lang.Thread.run(Thread.java:745)
]]>
    </failure>
  </testcase> <!-- testSubLong -->
  <testcase name="testSubDouble" time="0.016" classname="businessObject.CalculatorTest"/>
  <testcase name="testSubDouble" time="0.015" classname="businessObject.CalculatorTest"/>
  <testcase name="testSumDouble" time="0.015" classname="businessObject.CalculatorTest"/>
  <testcase name="testSubDouble" time="0.0" classname="businessObject.CalculatorTest"/>
  <testcase name="testSumDouble" time="0.0" classname="businessObject.CalculatorTest"/>
  <testcase name="testSubDouble" time="0.0" classname="businessObject.CalculatorTest">
    <failure type="java.lang.AssertionError" message="expected [-5.6562979E7] but found [-5.6562067E7]">
      <![CDATA[java.lang.AssertionError: expected [-5.6562979E7] but found [-5.6562067E7]
	at org.testng.Assert.fail(Assert.java:94)
	at org.testng.Assert.failNotEquals(Assert.java:494)
	at org.testng.Assert.assertEquals(Assert.java:207)
	at org.testng.Assert.assertEquals(Assert.java:220)
	at businessObject.CalculatorTest.testSubDouble(CalculatorTest.java:36)
	at sun.reflect.NativeMethodAccessorImpl.invoke0(Native Method)
	at sun.reflect.NativeMethodAccessorImpl.invoke(NativeMethodAccessorImpl.java:62)
	at sun.reflect.DelegatingMethodAccessorImpl.invoke(DelegatingMethodAccessorImpl.java:43)
	at java.lang.reflect.Method.invoke(Method.java:498)
	at org.testng.internal.MethodInvocationHelper.invokeMethod(MethodInvocationHelper.java:84)
	at org.testng.internal.Invoker.invokeMethod(Invoker.java:714)
	at org.testng.internal.Invoker.invokeTestMethod(Invoker.java:901)
	at org.testng.internal.Invoker.invokeTestMethods(Invoker.java:1231)
	at org.testng.internal.TestMethodWorker.invokeTestMethods(TestMethodWorker.java:127)
	at org.testng.internal.TestMethodWorker.run(TestMethodWorker.java:111)
	at java.util.concurrent.ThreadPoolExecutor.runWorker(ThreadPoolExecutor.java:1142)
	at java.util.concurrent.ThreadPoolExecutor$Worker.run(ThreadPoolExecutor.java:617)
	at java.lang.Thread.run(Thread.java:745)
]]>
    </failure>
  </testcase> <!-- testSubDouble -->
  <testcase name="testSumDouble" time="0.0" classname="businessObject.CalculatorTest"/>
  <testcase name="testSubDouble" time="0.0" classname="businessObject.CalculatorTest"/>
  <testcase name="testSumDouble" time="0.0" classname="businessObject.CalculatorTest"/>
  <testcase name="testSubDouble" time="0.0" classname="businessObject.CalculatorTest"/>
  <testcase name="testSumDouble" time="0.0" classname="businessObject.CalculatorTest"/>
  <testcase name="testSumDouble" time="0.0" classname="businessObject.CalculatorTest"/>
  <testcase name="testSumDouble" time="0.0" classname="businessObject.CalculatorTest"/>
  <testcase name="testTg" time="0.0" classname="businessObject.CalculatorTest">
    <failure type="java.lang.AssertionError" message="expected [0.3354445635832207] but found [1.0]">
      <![CDATA[java.lang.AssertionError: expected [0.3354445635832207] but found [1.0]
	at org.testng.Assert.fail(Assert.java:94)
	at org.testng.Assert.failNotEquals(Assert.java:494)
	at org.testng.Assert.assertEquals(Assert.java:123)
	at org.testng.Assert.assertEquals(Assert.java:165)
	at businessObject.CalculatorTest.testTg(CalculatorTest.java:71)
	at sun.reflect.NativeMethodAccessorImpl.invoke0(Native Method)
	at sun.reflect.NativeMethodAccessorImpl.invoke(NativeMethodAccessorImpl.java:62)
	at sun.reflect.DelegatingMethodAccessorImpl.invoke(DelegatingMethodAccessorImpl.java:43)
	at java.lang.reflect.Method.invoke(Method.java:498)
	at org.testng.internal.MethodInvocationHelper.invokeMethod(MethodInvocationHelper.java:84)
	at org.testng.internal.Invoker.invokeMethod(Invoker.java:714)
	at org.testng.internal.Invoker.invokeTestMethod(Invoker.java:901)
	at org.testng.internal.Invoker.invokeTestMethods(Invoker.java:1231)
	at org.testng.internal.TestMethodWorker.invokeTestMethods(TestMethodWorker.java:127)
	at org.testng.internal.TestMethodWorker.run(TestMethodWorker.java:111)
	at java.util.concurrent.ThreadPoolExecutor.runWorker(ThreadPoolExecutor.java:1142)
	at java.util.concurrent.ThreadPoolExecutor$Worker.run(ThreadPoolExecutor.java:617)
	at java.lang.Thread.run(Thread.java:745)
]]>
    </failure>
  </testcase> <!-- testTg -->
  <testcase name="testTg" time="0.0" classname="businessObject.CalculatorTest">
    <failure type="java.lang.AssertionError" message="expected [0.0] but found [NaN]">
      <![CDATA[java.lang.AssertionError: expected [0.0] but found [NaN]
	at org.testng.Assert.fail(Assert.java:94)
	at org.testng.Assert.failNotEquals(Assert.java:494)
	at org.testng.Assert.assertEquals(Assert.java:123)
	at org.testng.Assert.assertEquals(Assert.java:165)
	at businessObject.CalculatorTest.testTg(CalculatorTest.java:71)
	at sun.reflect.NativeMethodAccessorImpl.invoke0(Native Method)
	at sun.reflect.NativeMethodAccessorImpl.invoke(NativeMethodAccessorImpl.java:62)
	at sun.reflect.DelegatingMethodAccessorImpl.invoke(DelegatingMethodAccessorImpl.java:43)
	at java.lang.reflect.Method.invoke(Method.java:498)
	at org.testng.internal.MethodInvocationHelper.invokeMethod(MethodInvocationHelper.java:84)
	at org.testng.internal.Invoker.invokeMethod(Invoker.java:714)
	at org.testng.internal.Invoker.invokeTestMethod(Invoker.java:901)
	at org.testng.internal.Invoker.invokeTestMethods(Invoker.java:1231)
	at org.testng.internal.TestMethodWorker.invokeTestMethods(TestMethodWorker.java:127)
	at org.testng.internal.TestMethodWorker.run(TestMethodWorker.java:111)
	at java.util.concurrent.ThreadPoolExecutor.runWorker(ThreadPoolExecutor.java:1142)
	at java.util.concurrent.ThreadPoolExecutor$Worker.run(ThreadPoolExecutor.java:617)
	at java.lang.Thread.run(Thread.java:745)
]]>
    </failure>
  </testcase> <!-- testTg -->
  <testcase name="testTg" time="0.0" classname="businessObject.CalculatorTest">
    <failure type="java.lang.AssertionError" message="expected [-7.114264447088601] but found [1.0]">
      <![CDATA[java.lang.AssertionError: expected [-7.114264447088601] but found [1.0]
	at org.testng.Assert.fail(Assert.java:94)
	at org.testng.Assert.failNotEquals(Assert.java:494)
	at org.testng.Assert.assertEquals(Assert.java:123)
	at org.testng.Assert.assertEquals(Assert.java:165)
	at businessObject.CalculatorTest.testTg(CalculatorTest.java:71)
	at sun.reflect.NativeMethodAccessorImpl.invoke0(Native Method)
	at sun.reflect.NativeMethodAccessorImpl.invoke(NativeMethodAccessorImpl.java:62)
	at sun.reflect.DelegatingMethodAccessorImpl.invoke(DelegatingMethodAccessorImpl.java:43)
	at java.lang.reflect.Method.invoke(Method.java:498)
	at org.testng.internal.MethodInvocationHelper.invokeMethod(MethodInvocationHelper.java:84)
	at org.testng.internal.Invoker.invokeMethod(Invoker.java:714)
	at org.testng.internal.Invoker.invokeTestMethod(Invoker.java:901)
	at org.testng.internal.Invoker.invokeTestMethods(Invoker.java:1231)
	at org.testng.internal.TestMethodWorker.invokeTestMethods(TestMethodWorker.java:127)
	at org.testng.internal.TestMethodWorker.run(TestMethodWorker.java:111)
	at java.util.concurrent.ThreadPoolExecutor.runWorker(ThreadPoolExecutor.java:1142)
	at java.util.concurrent.ThreadPoolExecutor$Worker.run(ThreadPoolExecutor.java:617)
	at java.lang.Thread.run(Thread.java:745)
]]>
    </failure>
  </testcase> <!-- testTg -->
  <testcase name="testSumLong" time="1.0" classname="businessObject.CalculatorTest"/>
  <testcase name="testSumLong" time="1.002" classname="businessObject.CalculatorTest"/>
  <testcase name="testSumLong" time="1.002" classname="businessObject.CalculatorTest"/>
  <testcase name="testSumLong" time="1.0" classname="businessObject.CalculatorTest"/>
  <testcase name="testSumLong" time="1.007" classname="businessObject.CalculatorTest"/>
  <testcase name="testSumLong" time="1.004" classname="businessObject.CalculatorTest"/>
  <testcase name="testSumLong" time="1.005" classname="businessObject.CalculatorTest"/>
</testsuite> <!-- Test for different type of numbers -->
